Workbook
Name Нет: Коэффициенты!$C$2:$C$7
Name Подтягивания: Коэффициенты!$C$2:$C$7

Sheet Программа тренировок 
B6: ВИДЕО-ИНСТРУКЦИЯ К ДАННОЙ ПРОГРАММЕ ТРЕНИРОВОК
B7: Если у вас возникнут вопросы, то у меня есть постоянная поддержка к программам тренировок для всех подписчиков Boosty
B10: ПРАВИЛА СИЛОВОЙ ТРЕНИРОВКИ:
B11: Разминка:
B12: Каждая тренировка начинается с суставной гимнастики - необходимо в течение 5-10 минут разогреть все суставы (выполнить вращательные, сгибательные и разгибательные движения всеми доступными частями тела) - уделить особое внимание плечевому суставу, позвоночнику, коленям
B14: Разминочные подходы:
B15: В каждом упражнении делаем от 1 до 4,5 или даже 6 разминочных подходов перед рабочим весом (чем больше рабочий вес - тем больше подходов необходимо чтобы подготовить тело).
B16: В упражнениях с маленьким весом в качестве разминки достаточно взять 50% от рабочего веса и медленно поработать на 8-10 повторений в одном подходе (не закисляясь)
B17: Чем больше рабочий вес, тем больше требуется разминочных подходов перед рабочим весом, при этом во время разминки не делать большого кол-ва повторений, чтобы не закисляться (1х8, 1х6, 1х4, 1х2, 1х1)
B18: Например если приседания 120 кг, то понадобится сделать 20*8, 50*6, 70*4, 90*2, 110*1, а только затем рабочий вес (делать большие шаги в увеличении веса после 50%ПМ травмоопасно - 10-20 кг оптимальный шаг)
B20: Отдых между подходами:
B21: Во время силовой тренировки на 3-6 повторений с субмаксимальными весами используются большие интервалы времени отдыха 5-10 минут
... B35: Для этого нажмите на название упражнения в списке подготовительного периода и программа выдаст доступные варианты на замену каждого упражнения
E37: ВНИМАНИЕ!
E38: Если вы хотите добавить в программу тренировок отжимания на брусьях с дополнительным весом
E39: или подтягивания с дополнительным весом, то в ней обязательно должны присутствовать подтягивания
E40: и/или отжимания с обственным весом
E42: В остальным набор упражнений может быть абсолютно любым
E43: Если нажать на "+", то в программу добавится ещё одно упражнение на выбор
B48: 2. Подберите рабочие веса, которые соответствуют "ПМ" указанным в таблице и проведите с ними тренировку
B53: ПМ - это обозначение повторного максимума (например если вы можете пожать 100 кг только на 1 повторение, а 80 кг на 8 повторений, то 100 кг = 1ПМ, а 80 кг = 8ПМ)
B54: В таблице подготовительного периода указаны ПМ, с которыми вам необходимо выполнять упражнения
B56: Колонка Подх - это количество подходов с данным рабочим весом
B58: Колонка RIR - это количество повторений в запасе перед тем как наступит отказ.
B59: В данном случае 10ПМ 1 ПОДХ 2RIR означает что вам нужно выполнить 1 подход с весом, который вы можете пожать максимум на 10 повторений
B60: и остановиться за 2 повторения до отказа (то есть выполнить всего 8 повторений)
C63: ПОДГОТОВИТЕЛЬНЫЙ ПЕРИОД
C65: Неделя 1 | F65: Неделя 2 | I65: Неделя 3
B66: День 1: | C66: ПМ | D66: Подх | E66: RIR (повт в запасе) | F66: ПМ | G66: Подх | H66: RIR (повт в запасе) | I66: ПМ | J66: Подх | K66: RIR (повт в запасе)
B67: Жим штанги лёжа | C67: 10ПМ | D67: 1 | E67: 2 | F67: 8ПМ | G67: 2 | H67: 2 | I67: 6ПМ | J67: 3 | K67: 2
B68: Подтягивания (с отягощением) | C68: =IF(B68=Формулы!L14, "собственный", "10ПМ") -> 10ПМ | D68: 1 | E68: 2 | F68: =IF(B68=Формулы!L14, "собственный", "8ПМ") -> 8ПМ | G68: 2 | H68: 2 | I68: =IF(B68=Формулы!L14, "собственный", "6ПМ") -> 6ПМ | J68: 3 | K68: 2
B69: Приседания со штангой | C69: 10ПМ | D69: 1 | E69: 2 | F69: 8ПМ | G69: 2 | H69: 2 | I69: 6ПМ | J69: 3 | K69: 2
B70: Махи с гантелями в стороны | C70: 12ПМ | D70: 1 | E70: 2 | F70: 10ПМ | G70: 2 | H70: 2 | I70: 8ПМ | J70: 3 | K70: 2
B71: + | C71: =IF(B71=Формулы!L39, "", "собственный") | D71: =IF(B71=Формулы!L39, "", "1") | E71: =IF(B71=Формулы!L39,"",IF(B71=Формулы!L68,"2","30 сек")) | F71: =IF(B71=Формулы!L39, "", "собственный") | G71: =IF(B71=Формулы!L39, "", "2") | H71: =IF(B71=Формулы!L39,"",IF(B71=Формулы!L68,"2","30 сек")) | I71: =IF(B71=Формулы!L39, "", "собственный") | J71: =IF(E71=Формулы!O39, "", "3") | K71: =IF(B71=Формулы!L39,"",IF(B71=Формулы!L68,"2","30 сек"))
B74: День 2: | C74: ПМ | D74: Подх | E74: RIR (повт в запасе) | F74: ПМ | G74: Подх | H74: RIR (повт в запасе) | I74: ПМ | J74: Подх | K74: RIR (повт в запасе)
B75: Становая тяга | C75: 10ПМ | D75: 1 | E75: 2 | F75: 8ПМ | G75: 2 | H75: 2 | I75: 6ПМ | J75: 3 | K75: 2
B76: Жим штанги лёжа | C76: 10ПМ | D76: 1 | E76: 2 | F76: 8ПМ | G76: 2 | H76: 2 | I76: 6ПМ | J76: 3 | K76: 2
B77: Подъём штанги на бицепс | C77: 10ПМ | D77: 1 | E77: 2 | F77: 8ПМ | G77: 2 | H77: 2 | I77: 6ПМ | J77: 3 | K77: 2
B78: Жим лёжа узким хватом | C78: =IF(B78=Формулы!L37, "собственный", "12ПМ") -> 12ПМ | D78: 1 | E78: 2 | F78: =IF(B78=Формулы!L37, "собственный", "10ПМ") -> 10ПМ | G78: 2 | H78: 2 | I78: =IF(B78=Формулы!L37, "собственный", "8ПМ") -> 8ПМ | J78: 3 | K78: 2
B79: + | C79: =IF(B79=Формулы!L39, "", "12ПМ") | D79: 1 | E79: 2 | F79: =IF(B79=Формулы!L39, "", "10ПМ") | G79: =IF(B79=Формулы!L39, "", "2") | H79: =IF(B79=Формулы!L39, "", "2") | I79: =IF(B79=Формулы!L39, "", "8ПМ") | J79: =IF(B79=Формулы!L39, "", "3") | K79: =IF(B79=Формулы!L39, "", "2")
...

Sheet Формулы
M3: 100
N7: Введите свой 4-7ПМ в ячейки: | Q7: Неделя 1 | S7: Неделя 2 | U7: Неделя 3 | W7: Неделя 4 | Y7: Неделя 5 | AA7: Неделя 6 | AE7: Неделя 1 | AG7: Неделя 2 | AI7: Неделя 3 | AK7: Неделя 4 | AM7: Неделя 5 | AO7: Неделя 6
N8: вес (кг) ↓ | O8: ПМ (повт до отказа)↓ | P8: Прогрессия (кг) ↓ | Q8: Вес | R8: Подх x повт | S8: Вес | T8: Подх x повт | U8: Вес | V8: Подх x повт | W8: Вес | X8: Подх x повт | Y8: Вес | Z8: Подх x повт | AA8: Вес | AB8: Подх x повт | AC8: НЕДЕЛЯ ОТДЫХА | AE8: Вес | AF8: Подх x повт | AG8: Вес | AH8: Подх x повт | AI8: Вес | AJ8: Подх x повт | AK8: Вес | AL8: Подх x повт | AM8: Вес | AN8: Подх x повт | AO8: Вес | AP8: Подх x повт
L9: Жим штанги лёжа | N9: ='Программа тренировок '!C116 -> 117.5 | O9: ='Программа тренировок '!D116 -> 4 | P9: ='Программа тренировок '!E116 -> 5 | Q9: =CEILING(N9*VLOOKUP(O9, Коэффициенты!H3:I6, 2,FALSE)*0.7,2.5)&" кг" -> 90 кг | R9: 5х5 | S9: =CEILING(N9*VLOOKUP(O9, Коэффициенты!H3:I6, 2,FALSE)*0.75,2.5)&" кг" -> 97,5 кг | T9: 4х5 | U9: =CEILING(N9*VLOOKUP(O9, Коэффициенты!H3:I6, 2,FALSE)*0.8,2.5)&" кг" -> 102,5 кг | V9: 4х4 | W9: =CEILING(N9*VLOOKUP(O9, Коэффициенты!H3:I6, 2,FALSE)*0.85,2.5)&" кг" -> 110 кг | X9: 3х4 | Y9: =CEILING(N9*VLOOKUP(O9, Коэффициенты!H3:I6, 2,FALSE)*0.9,2.5)&" кг" -> 115 кг | Z9: 3х3 | AA9: =CEILING((N9*VLOOKUP(O9, Коэффициенты!H3:I6, 2,FALSE)+P9)*0.9,2.5)&" кг" -> 120 кг | AB9: 2х3 | AE9: =CEILING((N9*VLOOKUP(O9, Коэффициенты!H3:I6, 2,FALSE)+P9)*0.7,2.5)&" кг" -> 95 кг | AF9: 5х5 | AG9: =CEILING((N9*VLOOKUP(O9, Коэффициенты!H3:I6, 2,FALSE)+P9)*0.75,2.5)&" кг" -> 100 кг | AH9: 4х5 | AI9: =CEILING((N9*VLOOKUP(O9, Коэффициенты!H3:I6, 2,FALSE)+P9)*0.8,2.5)&" кг" -> 107,5 кг | AJ9: 4х4 | AK9: =CEILING((N9*VLOOKUP(O9, Коэффициенты!H3:I6, 2,FALSE)+P9)*0.85,2.5)&" кг" -> 115 кг | AL9: 3х4 | AM9: =CEILING((N9*VLOOKUP(O9, Коэффициенты!H3:I6, 2,FALSE)+P9)*0.9,2.5)&" кг" -> 120 кг | AN9: 3х3 | AO9: =FLOOR((N9*VLOOKUP(O9, Коэффициенты!H3:I6, 2,FALSE)+P9+P9)*0.9,2.5)&" кг" -> 122,5 кг | AP9: 2х3
L10: Отжимания на брусьях (с доп весом) | N10: ='Программа тренировок '!C116 -> 117.5 | O10: 4 | P10: ='Программа тренировок '!E116 -> 5 | Q10: 6 подходов | R10: =FLOOR(0.4*O37,1)&" повт" -> 2 повт | S10: 5 подходов | T10: =FLOOR(0.5*O37,1)&" повт" -> 3 повт | U10: 4 подхода | V10: =CEILING(0.6*O37,1)&" повт" -> 4 повт | W10: =N10/2&" кг" -> 58,75 кг | X10: 3x4 | Y10: =N10*0.8&" кг" -> 94 кг | Z10: 3х3 | AA10: =IF(O10<6,N10+P10, N10+P10+2.5)&" кг" -> 122,5 кг | AB10: 2x3 | AE10: 5 подходов | AF10: =FLOOR(0.4*O10+P10,1)&" повт" -> 6 повт | AG10: 4 подхода | AH10: =FLOOR(0.5*O10+P10,1)&" повт" -> 7 повт | AI10: =W10 -> 58,75 кг | AJ10: 4х4 | AK10: =Y10 -> 94 кг | AL10: 3х4 | AM10: =AA10 -> 122,5 кг | AN10: 3х3 | AO10: =IF(O10<6,N10+P10, N10+P10+2.5)+P10&" кг" -> 127,5 кг | AP10: 2х3
L11: Жим штанги лёжа на наклонной скамье | N11: ='Программа тренировок '!C116 -> 117.5 | O11: ='Программа тренировок '!D116 -> 4 | P11: ='Программа тренировок '!E116 -> 5 | Q11: =CEILING(N11*VLOOKUP(O11, Коэффициенты!N3:O11, 2,FALSE)*0.7,2.5)&" кг" -> 85 кг | R11: 5х5 | S11: =CEILING(N11*VLOOKUP(O11, Коэффициенты!N3:O11, 2,FALSE)*0.75,2.5)&" кг" -> 92,5 кг | T11: 4х5 | U11: =CEILING(N11*VLOOKUP(O11, Коэффициенты!N3:O11, 2,FALSE)*0.8,2.5)&" кг" -> 97,5 кг | V11: 4х4 | W11: =CEILING(N11*VLOOKUP(O11, Коэффициенты!N3:O11, 2,FALSE)*0.85,2.5)&" кг" -> 105 кг | X11: 3х4 | Y11: =CEILING(N11*VLOOKUP(O11, Коэффициенты!N3:O11, 2,FALSE)*0.9,2.5)&" кг" -> 110 кг | Z11: 3х3 | AA11: =CEILING((N11*VLOOKUP(O11, Коэффициенты!N3:O11, 2,FALSE)+P11)*0.9,2.5)&" кг" -> 115 кг | AB11: 2х3 | AE11: =CEILING((N11*VLOOKUP(O11, Коэффициенты!N3:O11, 2,FALSE)+P11)*0.7,2.5)&" кг" -> 90 кг | AF11: 5х5 | AG11: =CEILING((N11*VLOOKUP(O11, Коэффициенты!N3:O11, 2,FALSE)+P11)*0.75,2.5)&" кг" -> 95 кг | AH11: 4х5 | AI11: =CEILING((N11*VLOOKUP(O11, Коэффициенты!N3:O11, 2,FALSE)+P11)*0.8,2.5)&" кг" -> 102,5 кг | AJ11: 4х4 | AK11: =CEILING((N11*VLOOKUP(O11, Коэффициенты!N3:O11, 2,FALSE)+P11)*0.85,2.5)&" кг" -> 107,5 кг | AL11: 3х4 | AM11: =CEILING((N11*VLOOKUP(O11, Коэффициенты!N3:O11, 2,FALSE)+P11)*0.9,2.5)&" кг" -> 115 кг | AN11: 3х3 | AO11: =FLOOR((N11*VLOOKUP(O11, Коэффициенты!N3:O11, 2,FALSE)+P11+P11)*0.9,2.5)&" кг" -> 117,5 кг | AP11: 2х3
L13: Подтягивания (с отягощением) | N13: ='Программа тренировок '!C117 -> 15 | O13: ='Программа тренировок '!D117 -> 4 | P13: ='Программа тренировок '!E117 -> 2.5 | Q13: 6 подходов | R13: =FLOOR(0.4*O59,1)&" повт" -> 3 повт | S13: 5 подходов | T13: =FLOOR(0.5*O59,1)&" повт" -> 4 повт | U13: 4 подхода | V13: =CEILING(0.6*O59,1)&" повт" -> 5 повт | W13: =N13/2&" кг" -> 7,5 кг | X13: 3x4 | Y13: =N13&" кг" -> 15 кг | Z13: 3х3 | AA13: =IF(O13<6,N13+P13, N13+P13+2.5)&" кг" -> 17,5 кг | AB13: 2x3 | AE13: 5 подходов | AF13: =FLOOR(0.4*O59+P59,1)&" повт" -> 5 повт | AG13: 4 подхода | AH13: =FLOOR(0.5*O59+P59,1)&" повт" -> 6 повт | AI13: =W13 -> 7,5 кг | AJ13: 4х4 | AK13: =Y13 -> 15 кг | AL13: 3х4 | AM13: =AA13 -> 17,5 кг | AN13: 3х3 | AO13: =IF(O13<6,N13+P13, N13+P13+2.5)+P13&" кг" -> 20 кг | AP13: 2х3
L14: Подтягивания (собственный вес) | N14: ='Программа тренировок '!C117 -> 15 | O14: ='Программа тренировок '!D117 -> 4 | P14: ='Программа тренировок '!E117 -> 2.5 | Q14: 6 подходов | R14: =FLOOR(0.4*O14,1)&" повт" -> 1 повт | S14: 5 подходов | T14: =FLOOR(0.5*O14,1)&" повт" -> 2 повт | U14: 4 подхода | V14: =IF('Программа тренировок '!D206="boosty.to/yetiblog", FLOOR(0.6*O14,1), "")&" повт" -> 2 повт | W14: 3 подхода | X14: =CEILING(0.7*O14,1)&" повт" -> 3 повт | Y14: 2 подхода | Z14: =FLOOR(IF(0.8*O14-0.7*O14<1,0.8*O14+1,0.8*O14),1)&" повт" -> 4 повт | AA14: 1 подход | AB14: =O14+P14&" повт" -> 6,5 повт | AE14: 6 подходов | AF14: =FLOOR(0.4*O14+P14,1)&" повт" -> 4 повт | AG14: 5 подходов | AH14: =FLOOR(0.5*O14+P14,1)&" повт" -> 4 повт | AI14: 4 подхода | AJ14: =FLOOR(0.6*O14+P14,1)&" повт" -> 4 повт | AK14: 3 подхода | AL14: =FLOOR(0.8*O14+P14,1)&" повт" -> 5 повт | AM14: 2 подхода | AN14: =CEILING(0.8*O14+P14,1)&" повт" -> 6 повт | AO14: 1 подход | AP14: =O14+P14+P14&" повт" -> 9 повт
L15: Тяга вертикального блока | N15: ='Программа тренировок '!C117 -> 15 | O15: ='Программа тренировок '!D117 -> 4 | P15: ='Программа тренировок '!E117 -> 2.5 | Q15: =CEILING(N15*VLOOKUP(O15, Коэффициенты!N3:O11, 2,FALSE)*0.6,3)&" кг" -> 12 кг | R15: 5х10 | S15: =CEILING(N15*VLOOKUP(O15, Коэффициенты!N3:O11, 2,FALSE)*0.65,3)&" кг" -> 12 кг | T15: 4x10 | U15: =CEILING(N15*VLOOKUP(O15, Коэффициенты!N3:O11, 2,FALSE)*0.7,3)&" кг" -> 12 кг | V15: 4х8 | W15: =CEILING(N15*VLOOKUP(O15, Коэффициенты!N3:O11, 2,FALSE)*0.75,3)&" кг" -> 12 кг | X15: 3х8 | Y15: =CEILING(N15*VLOOKUP(O15, Коэффициенты!N3:O11, 2,FALSE)*0.85,3)&" кг" -> 15 кг | Z15: 3х6 | AA15: =CEILING((N15*VLOOKUP(O15, Коэффициенты!N3:O11, 2,FALSE)+P15)*0.9,3)&" кг" -> 18 кг | AB15: 2х6 | AE15: =CEILING((N15*VLOOKUP(O15, Коэффициенты!N3:O11, 2,FALSE)+P15)*0.6,3)&" кг" -> 12 кг | AF15: 5х10 | AG15: =CEILING((N15*VLOOKUP(O15, Коэффициенты!N3:O11, 2,FALSE)+P15)*0.65,3)&" кг" -> 12 кг | AH15: 4x10 | AI15: =CEILING((N15*VLOOKUP(O15, Коэффициенты!N3:O11, 2,FALSE)+P15)*0.7,3)&" кг" -> 15 кг | AJ15: 4х8 | AK15: =CEILING((N15*VLOOKUP(O15, Коэффициенты!N3:O11, 2,FALSE)+P15)*0.75,3)&" кг" -> 15 кг | AL15: 3х8 | AM15: =CEILING((N15*VLOOKUP(O15, Коэффициенты!N3:O11, 2,FALSE)+P15)*0.85,3)&" кг" -> 18 кг | AN15: 3х6 | AO15: =CEILING((N15*VLOOKUP(O15,Коэффициенты!N3:O11,2,FALSE)+2*P15)*0.9,3)&" кг" -> 21 кг | AP15: 2х6
L17: Приседания со штангой | N17: ='Программа тренировок '!C118 -> 150 | O17: ='Программа тренировок '!D118 -> 4 | P17: ='Программа тренировок '!E118 -> 5 | Q17: =CEILING(N17*VLOOKUP(O17, Коэффициенты!H3:I6, 2,FALSE)*0.675,2.5)&" кг" -> 112,5 кг | R17: 3х5 | S17: =CEILING(N17*VLOOKUP(O17, Коэффициенты!H3:I6, 2,FALSE)*0.725,2.5)&" кг" -> 120 кг | T17: 3х5 | U17: =CEILING(N17*VLOOKUP(O17, Коэффициенты!H3:I6, 2,FALSE)*0.775,2.5)&" кг" -> 127,5 кг | V17: 2х5 | W17: =CEILING(N17*VLOOKUP(O17, Коэффициенты!H3:I6, 2,FALSE)*0.825,2.5)&" кг" -> 135 кг | X17: 2х5 | Y17: =CEILING(N17*VLOOKUP(O17, Коэффициенты!H3:I6, 2,FALSE)*0.865,2.5)&" кг" -> 142,5 кг | Z17: 1х5 | AA17: =CEILING((N17*VLOOKUP(O17, Коэффициенты!H3:I6, 2,FALSE)+P54)*0.885,2.5)&" кг" -> 150 кг | AB17: 1х5 | AE17: =CEILING((N17*VLOOKUP(O17, Коэффициенты!H3:I6, 2,FALSE)+P54)*0.675,2.5)&" кг" -> 115 кг | AF17: 3х5 | AG17: =CEILING((N17*VLOOKUP(O17, Коэффициенты!H3:I6, 2,FALSE)+P54)*0.725,2.5)&" кг" -> 122,5 кг | AH17: 3х5 | AI17: =CEILING((N17*VLOOKUP(O17, Коэффициенты!H3:I6, 2,FALSE)+P54)*0.775,2.5)&" кг" -> 132,5 кг | AJ17: 2х5 | AK17: =CEILING((N17*VLOOKUP(O17, Коэффициенты!H3:I6, 2,FALSE)+P54)*0.825,2.5)&" кг" -> 140 кг | AL17: 2х5 | AM17: =CEILING((N17*VLOOKUP(O17, Коэффициенты!H3:I6, 2,FALSE)+P54)*0.865,2.5)&" кг" -> 147,5 кг | AN17: 1х5 | AO17: =CEILING((N17*VLOOKUP(O17, Коэффициенты!H3:I6, 2,FALSE)+P54+P54)*0.885,2.5)&" кг" -> 155 кг | AP17: 1х5
L18: Приседания в колодец | N18: ='Программа тренировок '!C118 -> 150 | O18: ='Программа тренировок '!D118 -> 4 | P18: ='Программа тренировок '!E118 -> 5 | Q18: =CEILING(N18*VLOOKUP(O18, Коэффициенты!H3:I6, 2,FALSE)*0.5,2.5)&" кг" -> 82,5 кг | R18: 5х5 | S18: =CEILING(N18*VLOOKUP(O18, Коэффициенты!H3:I6, 2,FALSE)*0.55,2.5)&" кг" -> 90 кг | T18: 4х5 | U18: =CEILING(N18*VLOOKUP(O18, Коэффициенты!H3:I6, 2,FALSE)*0.6,2.5)&" кг" -> 100 кг | V18: 4х4 | W18: =CEILING(N18*VLOOKUP(O18, Коэффициенты!H3:I6, 2,FALSE)*0.65,2.5)&" кг" -> 107,5 кг | X18: 3х4 | Y18: =CEILING(N18*VLOOKUP(O18, Коэффициенты!H3:I6, 2,FALSE)*0.7,2.5)&" кг" -> 115 кг | Z18: 3х3 | AA18: =CEILING(N18*VLOOKUP(O18, Коэффициенты!H3:I6, 2,FALSE)*0.75,2.5)&" кг" -> 122,5 кг | AB18: 2х3 | AE18: =CEILING((N18*VLOOKUP(O18, Коэффициенты!H3:I6, 2,FALSE)+P18)*0.5,2.5)&" кг" -> 85 кг | AF18: 5х5 | AG18: =CEILING((N18*VLOOKUP(O18, Коэффициенты!H3:I6, 2,FALSE)+P18)*0.55,2.5)&" кг" -> 92,5 кг | AH18: 4х5 | AI18: =CEILING((N18*VLOOKUP(O18, Коэффициенты!H3:I6, 2,FALSE)+P18)*0.6,2.5)&" кг" -> 102,5 кг | AJ18: 4х4 | AK18: =CEILING((N18*VLOOKUP(O18, Коэффициенты!H3:I6, 2,FALSE)+P18)*0.65,2.5)&" кг" -> 110 кг | AL18: 3х4 | AM18: =CEILING((N18*VLOOKUP(O18, Коэффициенты!H3:I6, 2,FALSE)+P18)*0.7,2.5)&" кг" -> 120 кг | AN18: 3х3 | AO18: =CEILING((N18*VLOOKUP(O18, Коэффициенты!H3:I6, 2,FALSE)+P18)*0.75,2.5)&" кг" -> 127,5 кг | AP18: 2х3
L19: Ягодичный мост | N19: ='Программа тренировок '!C118 -> 150 | O19: ='Программа тренировок '!D118 -> 4 | P19: ='Программа тренировок '!E118 -> 5 | Q19: =CEILING(N19*VLOOKUP(O19, Коэффициенты!H3:I6, 2,FALSE)*0.675,2.5)&" кг" -> 112,5 кг | R19: 5х5 | S19: =CEILING(N19*VLOOKUP(O19, Коэффициенты!H3:I6, 2,FALSE)*0.725,2.5)&" кг" -> 120 кг | T19: 4х5 | U19: =CEILING(N19*VLOOKUP(O19, Коэффициенты!H3:I6, 2,FALSE)*0.775,2.5)&" кг" -> 127,5 кг | V19: 3х5 | W19: =CEILING(N19*VLOOKUP(O19, Коэффициенты!H3:I6, 2,FALSE)*0.825,2.5)&" кг" -> 135 кг | X19: 2х5 | Y19: =CEILING(N19*VLOOKUP(O19, Коэффициенты!H3:I6, 2,FALSE)*0.865,2.5)&" кг" -> 142,5 кг | Z19: 1х5 | AA19: =CEILING((N19*VLOOKUP(O19, Коэффициенты!H3:I6, 2,FALSE)+P19)*0.885,2.5)&" кг" -> 150 кг | AB19: 1х5 | AE19: =CEILING((N19*VLOOKUP(O19, Коэффициенты!H3:I6, 2,FALSE)+P19)*0.675,2.5)&" кг" -> 115 кг | AF19: 5х5 | AG19: =CEILING((N19*VLOOKUP(O19, Коэффициенты!H3:I6, 2,FALSE)+P19)*0.725,2.5)&" кг" -> 122,5 кг | AH19: 4х5 | AI19: =CEILING((N19*VLOOKUP(O19, Коэффициенты!H3:I6, 2,FALSE)+P19)*0.775,2.5)&" кг" -> 132,5 кг | AJ19: 3х5 | AK19: =CEILING((N19*VLOOKUP(O19, Коэффициенты!H3:I6, 2,FALSE)+P19)*0.825,2.5)&" кг" -> 140 кг | AL19: 2х5 | AM19: =CEILING((N19*VLOOKUP(O19, Коэффициенты!H3:I6, 2,FALSE)+P19)*0.865,2.5)&" кг" -> 147,5 кг | AN19: 1х5 | AO19: =CEILING((N19*VLOOKUP(O19, Коэффициенты!H3:I6, 2,FALSE)+P19+P19)*0.885,2.5)&" кг" -> 155 кг | AP19: 1х5
L21: Махи с гантелями в стороны | N21: ='Программа тренировок '!C119 -> 20 | O21: ='Программа тренировок '!D119 -> 8 | P21: ='Программа тренировок '!E119 -> 2 | Q21: =CEILING(N21*VLOOKUP(O21, Коэффициенты!N5:O11, 2,FALSE)*0.4,2)&" кг" -> 10 кг | R21: 5х12 | S21: =CEILING(N21*VLOOKUP(O21, Коэффициенты!N5:O11, 2,FALSE)*0.5,2)&" кг" -> 12 кг | T21: 5х12 | U21: =CEILING(N21*VLOOKUP(O21, Коэффициенты!N5:O11, 2,FALSE)*0.6,2)&" кг" -> 14 кг | V21: 4х10 | W21: =CEILING(N21*VLOOKUP(O21, Коэффициенты!N5:O11, 2,FALSE)*0.7,2)&" кг" -> 18 кг | X21: 4х10 | Y21: =CEILING(N21*VLOOKUP(O21, Коэффициенты!N5:O11, 2,FALSE)*0.8,2)&" кг" -> 20 кг | Z21: 3х8 | AA21: =CEILING((N21*VLOOKUP(O21, Коэффициенты!N5:O11, 2,FALSE)+P21)*0.85,2)&" кг" -> 22 кг | AB21: 3х8 | AE21: =CEILING((N21*VLOOKUP(O21, Коэффициенты!N5:O11, 2,FALSE)+P21)*0.4,2)&" кг" -> 10 кг | AF21: 5х12 | AG21: =CEILING((N21*VLOOKUP(O21, Коэффициенты!N5:O11, 2,FALSE)+P21)*0.5,2)&" кг" -> 14 кг | AH21: 5х12 | AI21: =CEILING((N21*VLOOKUP(O21, Коэффициенты!N5:O11, 2,FALSE)+P21)*0.6,2)&" кг" -> 16 кг | AJ21: 4х10 | AK21: =CEILING((N21*VLOOKUP(O21, Коэффициенты!N5:O11, 2,FALSE)+P21)*0.7,2)&" кг" -> 18 кг | AL21: 4х10 | AM21: =CEILING((N21*VLOOKUP(O21, Коэффициенты!N5:O11, 2,FALSE)+P21)*0.8,2)&" кг" -> 20 кг | AN21: 3х8 | AO21: =CEILING((N21*VLOOKUP(O21, Коэффициенты!N5:O11, 2,FALSE)+P21+P21)*0.9,2)&" кг" -> 26 кг | AP21: 3х8
L22: Тяга к подбородку | N22: ='Программа тренировок '!C119 -> 20 | O22: ='Программа тренировок '!D119 -> 8 | P22: ='Программа тренировок '!E119 -> 2 | Q22: =CEILING(N22*VLOOKUP(O22, Коэффициенты!H3:I6, 2,FALSE)*0.675,2.5)&" кг" -> #N/A | R22: 5х5 | S22: =CEILING(N22*VLOOKUP(O22, Коэффициенты!H3:I6, 2,FALSE)*0.725,2.5)&" кг" -> #N/A | T22: 4х5 | U22: =CEILING(N22*VLOOKUP(O22, Коэффициенты!H3:I6, 2,FALSE)*0.775,2.5)&" кг" -> #N/A | V22: 3х5 | W22: =CEILING(N22*VLOOKUP(O22, Коэффициенты!H3:I6, 2,FALSE)*0.825,2.5)&" кг" -> #N/A | X22: 2х5 | Y22: =CEILING(N22*VLOOKUP(O22, Коэффициенты!H3:I6, 2,FALSE)*0.865,2.5)&" кг" -> #N/A | Z22: 1х5 | AA22: =CEILING((N22*VLOOKUP(O22, Коэффициенты!H3:I6, 2,FALSE)+P22)*0.885,2.5)&" кг" -> #N/A | AB22: 1х5 | AE22: =CEILING((N22*VLOOKUP(O22, Коэффициенты!H3:I6, 2,FALSE)+P22)*0.675,2.5)&" кг" -> #N/A | AF22: 5х5 | AG22: =CEILING((N22*VLOOKUP(O22, Коэффициенты!H3:I6, 2,FALSE)+P22)*0.725,2.5)&" кг" -> #N/A | AH22: 4х5 | AI22: =CEILING((N22*VLOOKUP(O22, Коэффициенты!H3:I6, 2,FALSE)+P22)*0.775,2.5)&" кг" -> #N/A | AJ22: 3х5 | AK22: =CEILING((N22*VLOOKUP(O22, Коэффициенты!H3:I6, 2,FALSE)+P22)*0.825,2.5)&" кг" -> #N/A | AL22: 2х5 | AM22: =CEILING((N22*VLOOKUP(O22, Коэффициенты!H3:I6, 2,FALSE)+P22)*0.865,2.5)&" кг" -> #N/A | AN22: 1х5 | AO22: =CEILING((N22*VLOOKUP(O22, Коэффициенты!H3:I6, 2,FALSE)+P22+P22)*0.885,2.5)&" кг" -> #N/A | AP22: 1х5
L24: Становая тяга | N24: ='Программа тренировок '!C124 -> 195 | O24: ='Программа тренировок '!D124 -> 5 | P24: ='Программа тренировок '!E124 -> 5 | Q24: =CEILING(N24*VLOOKUP(O24, Коэффициенты!H3:I6, 2,FALSE)*0.675,2.5)&" кг" -> 150 кг | R24: 3х5 | S24: =CEILING(N24*VLOOKUP(O24, Коэффициенты!H3:I6, 2,FALSE)*0.725,2.5)&" кг" -> 160 кг | T24: 3х5 | U24: =CEILING(N24*VLOOKUP(O24, Коэффициенты!H3:I6, 2,FALSE)*0.775,2.5)&" кг" -> 170 кг | V24: 2х5 | W24: =CEILING(N24*VLOOKUP(O24, Коэффициенты!H3:I6, 2,FALSE)*0.825,2.5)&" кг" -> 182,5 кг | X24: 2х5 | Y24: =CEILING(N24*VLOOKUP(O24, Коэффициенты!H3:I6, 2,FALSE)*0.865,2.5)&" кг" -> 190 кг | Z24: 1х5 | AA24: =CEILING((N24*VLOOKUP(O24, Коэффициенты!H3:I6, 2,FALSE)+P24)*0.885,2.5)&" кг" -> 200 кг | AB24: 1х5 | AE24: =CEILING((N24*VLOOKUP(O24, Коэффициенты!H3:I6, 2,FALSE)+P24)*0.675,2.5)&" кг" -> 152,5 кг | AF24: 1х5 | AG24: =CEILING((N24*VLOOKUP(O24, Коэффициенты!H3:I6, 2,FALSE)+P24)*0.725,2.5)&" кг" -> 162,5 кг | AH24: 1х5 | AI24: =CEILING((N24*VLOOKUP(O24, Коэффициенты!H3:I6, 2,FALSE)+P24)*0.775,2.5)&" кг" -> 175 кг | AJ24: 1х5 | AK24: =CEILING((N24*VLOOKUP(O24, Коэффициенты!H3:I6, 2,FALSE)+P24)*0.825,2.5)&" кг" -> 185 кг | AL24: 1х5 | AM24: =CEILING((N24*VLOOKUP(O24, Коэффициенты!H3:I6, 2,FALSE)+P24)*0.865,2.5)&" кг" -> 195 кг | AN24: 1х5 | AO24: =CEILING((N24*VLOOKUP(O24, Коэффициенты!H3:I6, 2,FALSE)+P24+P24)*0.885,2.5)&" кг" -> 205 кг | AP24: 1х5
L25: Приседания со штангой | N25: =IF('Программа тренировок '!B69=Формулы!L17, Формулы!N17, 'Программа тренировок '!C124) -> 150 | O25: =IF('Программа тренировок '!B69=Формулы!L17, O17, 'Программа тренировок '!D124) -> 4 | P25: =IF('Программа тренировок '!B69=Формулы!L17, P17, 'Программа тренировок '!E124) -> 5 | Q25: =CEILING(N25*VLOOKUP(O25, Коэффициенты!H3:I6, 2,FALSE)*0.675,2.5)&" кг" -> 112,5 кг | R25: 1х5 | S25: =CEILING(N25*VLOOKUP(O25, Коэффициенты!H3:I6, 2,FALSE)*0.725,2.5)&" кг" -> 120 кг | T25: 1х5 | U25: =CEILING(N25*VLOOKUP(O25, Коэффициенты!H3:I6, 2,FALSE)*0.775,2.5)&" кг" -> 127,5 кг | V25: 1х5 | W25: =CEILING(N25*VLOOKUP(O25, Коэффициенты!H3:I6, 2,FALSE)*0.825,2.5)&" кг" -> 135 кг | X25: 1х5 | Y25: =CEILING(N25*VLOOKUP(O25, Коэффициенты!H3:I6, 2,FALSE)*0.865,2.5)&" кг" -> 142,5 кг | Z25: 1х5 | AA25: =IF('Программа тренировок '!B69=Формулы!L25, "отдых", CEILING((N25*VLOOKUP(O25, Коэффициенты!H3:I6, 2,FALSE)+P25)*0.885,2.5)&" кг") -> отдых | AB25: =IF('Программа тренировок '!B69=Формулы!L25, "отдых", "1х5") -> отдых | AE25: =CEILING((N25*VLOOKUP(O25, Коэффициенты!H3:I6, 2,FALSE)+P25)*0.675,2.5)&" кг" -> 115 кг | AF25: 1х5 | AG25: =CEILING((N25*VLOOKUP(O25, Коэффициенты!H3:I6, 2,FALSE)+P25)*0.725,2.5)&" кг" -> 122,5 кг | AH25: 1х5 | AI25: =CEILING((N25*VLOOKUP(O25, Коэффициенты!H3:I6, 2,FALSE)+P25)*0.775,2.5)&" кг" -> 132,5 кг | AJ25: 1х5 | AK25: =CEILING((N25*VLOOKUP(O25, Коэффициенты!H3:I6, 2,FALSE)+P25)*0.825,2.5)&" кг" -> 140 кг | AL25: 1х5 | AM25: =CEILING((N25*VLOOKUP(O25, Коэффициенты!H3:I6, 2,FALSE)+P25)*0.865,2.5)&" кг" -> 147,5 кг | AN25: 1х5 | AO25: =IF('Программа тренировок '!B69=Формулы!L25, "отдых", CEILING((N25*VLOOKUP(O25, Коэффициенты!H3:I6, 2,FALSE)+P25+P25)*0.885,2.5)&" кг") -> отдых | AP25: =IF('Программа тренировок '!B69=Формулы!L25, "отдых", "1х5") -> отдых
L26: Ягодичный мост | N26: ='Программа тренировок '!C124 -> 195 | O26: ='Программа тренировок '!D124 -> 5 | P26: ='Программа тренировок '!E124 -> 5 | Q26: =CEILING(N26*VLOOKUP(O26, Коэффициенты!H3:I6, 2,FALSE)*0.675,2.5)&" кг" -> 150 кг | R26: 3х5 | S26: =CEILING(N26*VLOOKUP(O26, Коэффициенты!H3:I6, 2,FALSE)*0.725,2.5)&" кг" -> 160 кг | T26: 3х5 | U26: =CEILING(N26*VLOOKUP(O26, Коэффициенты!H3:I6, 2,FALSE)*0.775,2.5)&" кг" -> 170 кг | V26: 2х5 | W26: =CEILING(N26*VLOOKUP(O26, Коэффициенты!H3:I6, 2,FALSE)*0.825,2.5)&" кг" -> 182,5 кг | X26: 2х5 | Y26: =CEILING(N26*VLOOKUP(O26, Коэффициенты!H3:I6, 2,FALSE)*0.865,2.5)&" кг" -> 190 кг | Z26: 1х5 | AA26: =CEILING((N26*VLOOKUP(O26, Коэффициенты!H3:I6, 2,FALSE)+P26)*0.885,2.5)&" кг" -> 200 кг | AB26: 1х5 | AE26: =CEILING((N26*VLOOKUP(O26, Коэффициенты!H3:I6, 2,FALSE)+P26)*0.675,2.5)&" кг" -> 152,5 кг | AF26: 1х5 | AG26: =CEILING((N26*VLOOKUP(O26, Коэффициенты!H3:I6, 2,FALSE)+P26)*0.725,2.5)&" кг" -> 162,5 кг | AH26: 1х5 | AI26: =CEILING((N26*VLOOKUP(O26, Коэффициенты!H3:I6, 2,FALSE)+P26)*0.775,2.5)&" кг" -> 175 кг | AJ26: 1х5 | AK26: =CEILING((N26*VLOOKUP(O26, Коэффициенты!H3:I6, 2,FALSE)+P26)*0.825,2.5)&" кг" -> 185 кг | AL26: 1х5 | AM26: =CEILING((N26*VLOOKUP(O26, Коэффициенты!H3:I6, 2,FALSE)+P26)*0.865,2.5)&" кг" -> 195 кг | AN26: 1х5 | AO26: =CEILING((N26*VLOOKUP(O26, Коэффициенты!H3:I6, 2,FALSE)+P26+P26)*0.885,2.5)&" кг" -> 205 кг | AP26: 1х5
L28: Жим штанги лёжа | N28: =IF('Программа тренировок '!B67='Программа тренировок '!B76, Формулы!N9, 'Программа тренировок '!C125) -> 117.5 | O28: =IF('Программа тренировок '!B67='Программа тренировок '!B76, Формулы!O9, 'Программа тренировок '!D125) -> 4 | P28: =IF('Программа тренировок '!B67='Программа тренировок '!B76, Формулы!P9, 'Программа тренировок '!E125) -> 5 | Q28: =CEILING(N28*VLOOKUP(O28, Коэффициенты!H3:I6, 2,FALSE)*0.7,2.5)&" кг" -> 90 кг | R28: 5х5 | S28: =CEILING(N28*VLOOKUP(O28, Коэффициенты!H3:I6, 2,FALSE)*0.75,2.5)&" кг" -> 97,5 кг | T28: 4х5 | U28: =CEILING(N28*VLOOKUP(O28, Коэффициенты!H3:I6, 2,FALSE)*0.8,2.5)&" кг" -> 102,5 кг | V28: 4х4 | W28: =CEILING(N28*VLOOKUP(O28, Коэффициенты!H3:I6, 2,FALSE)*0.85,2.5)&" кг" -> 110 кг | X28: 3х4 | Y28: =CEILING(N28*VLOOKUP(O28, Коэффициенты!H3:I6, 2,FALSE)*0.9,2.5)&" кг" -> 115 кг | Z28: 3х3 | AA28: =IF('Программа тренировок '!B67=Формулы!L9, "отдых",CEILING((N28*VLOOKUP(O28, Коэффициенты!H3:I6, 2,FALSE)+P28)*0.9,2.5)&" кг") -> отдых | AB28: =IF('Программа тренировок '!B67=Формулы!L9, "отдых","2х3") -> отдых | AE28: =CEILING((N28*VLOOKUP(O28, Коэффициенты!H3:I6, 2,FALSE)+P28)*0.7,2.5)&" кг" -> 95 кг | AF28: 5х5 | AG28: =CEILING((N28*VLOOKUP(O28, Коэффициенты!H3:I6, 2,FALSE)+P28)*0.75,2.5)&" кг" -> 100 кг | AH28: 4х5 | AI28: =CEILING((N28*VLOOKUP(O28, Коэффициенты!H3:I6, 2,FALSE)+P28)*0.8,2.5)&" кг" -> 107,5 кг | AJ28: 4х4 | AK28: =CEILING((N28*VLOOKUP(O28, Коэффициенты!H3:I6, 2,FALSE)+P28)*0.85,2.5)&" кг" -> 115 кг | AL28: 3х4 | AM28: =CEILING((N28*VLOOKUP(O28, Коэффициенты!H3:I6, 2,FALSE)+P28)*0.9,2.5)&" кг" -> 120 кг | AN28: 3х3 | AO28: =IF('Программа тренировок '!B67=Формулы!L9, "отдых",CEILING((N28*VLOOKUP(O28, Коэффициенты!H3:I6, 2,FALSE)+P28+P28)*0.9,2.5)&" кг") -> отдых | AP28: =IF('Программа тренировок '!B67=Формулы!L9, "отдых","2х3") -> отдых
L29: Жим гантелей лёжа | N29: ='Программа тренировок '!C125 -> 0 | O29: ='Программа тренировок '!D125 -> 0 | P29: ='Программа тренировок '!E125 -> 0 | Q29: =CEILING(N29*VLOOKUP(O29, Коэффициенты!N3:O11, 2,FALSE)*0.65,2)&" кг" -> #N/A | R29: 5х8 | S29: =CEILING(N29*VLOOKUP(O29, Коэффициенты!N3:O11, 2,FALSE)*0.7,2)&" кг" -> #N/A | T29: 4х8 | U29: =CEILING(N29*VLOOKUP(O29, Коэффициенты!N3:O11, 2,FALSE)*0.75,2)&" кг" -> #N/A | V29: 4х6 | W29: =CEILING(N29*VLOOKUP(O29, Коэффициенты!N3:O11, 2,FALSE)*0.8,2)&" кг" -> #N/A | X29: 3х6 | Y29: =CEILING(N29*VLOOKUP(O29, Коэффициенты!N3:O11, 2,FALSE)*0.875,2)&" кг" -> #N/A | Z29: 3х4 | AA29: =CEILING((N29*VLOOKUP(O29, Коэффициенты!N3:O11, 2,FALSE)+P29)*0.9,2)&" кг" -> #N/A | AB29: 2х4 | AE29: =CEILING((N29*VLOOKUP(O29, Коэффициенты!N3:O11, 2,FALSE)+P29)*0.7,2)&" кг" -> #N/A | AF29: 5х8 | AG29: =CEILING((N29*VLOOKUP(O29, Коэффициенты!N3:O11, 2,FALSE)+P29)*0.75,2)&" кг" -> #N/A | AH29: 4х8 | AI29: =CEILING((N29*VLOOKUP(O29, Коэффициенты!N3:O11, 2,FALSE)+P29)*0.8,2)&" кг" -> #N/A | AJ29: 4х6 | AK29: =CEILING((N29*VLOOKUP(O29, Коэффициенты!N3:O11, 2,FALSE)+P29)*0.85,2)&" кг" -> #N/A | AL29: 3х6 | AM29: =CEILING((N29*VLOOKUP(O29, Коэффициенты!N3:O11, 2,FALSE)+P29)*0.9,2)&" кг" -> #N/A | AN29: 3х4 | AO29: =FLOOR((N29*VLOOKUP(O29, Коэффициенты!N3:O11, 2,FALSE)+P29+P29)*0.9,2)&" кг" -> #N/A | AP29: 2х4
L30: Жим штанги лёжа на наклонной скамье | N30: ='Программа тренировок '!C125 -> 0 | O30: ='Программа тренировок '!D125 -> 0 | P30: ='Программа тренировок '!E125 -> 0 | Q30: =CEILING(N30*VLOOKUP(O30, Коэффициенты!H3:I6, 2,FALSE)*0.7,2.5)&" кг" -> #N/A | R30: 5х5 | S30: =CEILING(N30*VLOOKUP(O30, Коэффициенты!H3:I6, 2,FALSE)*0.75,2.5)&" кг" -> #N/A | T30: 4х5 | U30: =CEILING(N30*VLOOKUP(O30, Коэффициенты!H3:I6, 2,FALSE)*0.8,2.5)&" кг" -> #N/A | V30: 4х4 | W30: =CEILING(N30*VLOOKUP(O30, Коэффициенты!H3:I6, 2,FALSE)*0.85,2.5)&" кг" -> #N/A | X30: 3х4 | Y30: =CEILING(N30*VLOOKUP(O30, Коэффициенты!H3:I6, 2,FALSE)*0.9,2.5)&" кг" -> #N/A | Z30: 3х3 | AA30: =CEILING((N30*VLOOKUP(O30, Коэффициенты!H3:I6, 2,FALSE)+P30)*0.9,2.5)&" кг" -> #N/A | AB30: 2х3 | AE30: =CEILING((N30*VLOOKUP(O30, Коэффициенты!H3:I6, 2,FALSE)+P30)*0.7,2.5)&" кг" -> #N/A | AF30: 5х5 | AG30: =CEILING((N30*VLOOKUP(O30, Коэффициенты!H3:I6, 2,FALSE)+P30)*0.75,2.5)&" кг" -> #N/A | AH30: 4х5 | AI30: =CEILING((N30*VLOOKUP(O30, Коэффициенты!H3:I6, 2,FALSE)+P30)*0.8,2.5)&" кг" -> #N/A | AJ30: 4х4 | AK30: =CEILING((N30*VLOOKUP(O30, Коэффициенты!H3:I6, 2,FALSE)+P30)*0.85,2.5)&" кг" -> #N/A | AL30: 3х4 | AM30: =CEILING((N30*VLOOKUP(O30, Коэффициенты!H3:I6, 2,FALSE)+P30)*0.9,2.5)&" кг" -> #N/A | AN30: 3х3 | AO30: =CEILING((N30*VLOOKUP(O30, Коэффициенты!H3:I6, 2,FALSE)+P30+P30)*0.9,2.5)&" кг" -> #N/A | AP30: 2х3
L33: Подъём штанги на бицепс | N33: ='Программа тренировок '!C126 -> 57.5 | O33: ='Программа тренировок '!D126 -> 4 | P33: ='Программа тренировок '!E126 -> 2.5 | Q33: =CEILING(N33*VLOOKUP(O33, Коэффициенты!K3:L6, 2,FALSE)*0.55,2.5)&" кг" -> 37,5 кг | R33: 5x5 | S33: =CEILING(N33*VLOOKUP(O33, Коэффициенты!K3:L6, 2,FALSE)*0.625,2.5)&" кг" -> 42,5 кг | T33: 4x5 | U33: =CEILING(N33*VLOOKUP(O33, Коэффициенты!K3:L6, 2,FALSE)*0.7,2.5)&" кг" -> 47,5 кг | V33: 4x4 | W33: =CEILING(N33*VLOOKUP(O33, Коэффициенты!K3:L6, 2,FALSE)*0.75,2.5)&" кг" -> 52,5 кг | X33: 3x4 | Y33: =CEILING(N33*VLOOKUP(O33, Коэффициенты!K3:L6, 2,FALSE)*0.8,2.5)&" кг" -> 55 кг | Z33: 3х3 | AA33: =CEILING((N33*VLOOKUP(O33, Коэффициенты!K3:L6, 2,FALSE)+P33)*0.825,2.5)&" кг" -> 60 кг | AB33: 2x3 | AE33: =CEILING((N33*VLOOKUP(O33, Коэффициенты!K3:L6, 2,FALSE)+P33)*0.55,2.5)&" кг" -> 40 кг | AF33: 5х5 | AG33: =CEILING((N33*VLOOKUP(O33, Коэффициенты!K3:L6, 2,FALSE)+P33)*0.625,2.5)&" кг" -> 45 кг | AH33: 4х5 | AI33: =CEILING((N33*VLOOKUP(O33, Коэффициенты!K3:L6, 2,FALSE)+P33)*0.7,2.5)&" кг" -> 50 кг | AJ33: 4х4 | AK33: =CEILING((N33*VLOOKUP(O33, Коэффициенты!K3:L6, 2,FALSE)+P33)*0.75,2.5)&" кг" -> 55 кг | AL33: 3х4 | AM33: =CEILING((N33*VLOOKUP(O33, Коэффициенты!K3:L6, 2,FALSE)+P33)*0.8,2.5)&" кг" -> 57,5 кг | AN33: 3х3 | AO33: =CEILING((N33*VLOOKUP(O33, Коэффициенты!K3:L6, 2,FALSE)+2*P33)*0.835,2.5)&" кг" -> 62,5 кг | AP33: 2х3
L34: Молот | N34: ='Программа тренировок '!C126 -> 57.5 | O34: ='Программа тренировок '!D126 -> 4 | P34: ='Программа тренировок '!E126 -> 2.5 | Q34: =CEILING(N34*VLOOKUP(O34, Коэффициенты!N3:O11, 2,FALSE)*0.65,2)&" кг" -> 40 кг | R34: 5х8 | S34: =CEILING(N34*VLOOKUP(O34, Коэффициенты!N3:O11, 2,FALSE)*0.7,2)&" кг" -> 42 кг | T34: 4х8 | U34: =CEILING(N34*VLOOKUP(O34, Коэффициенты!N3:O11, 2,FALSE)*0.75,2)&" кг" -> 46 кг | V34: 4х6 | W34: =CEILING(N34*VLOOKUP(O34, Коэффициенты!N3:O11, 2,FALSE)*0.8,2)&" кг" -> 48 кг | X34: 3х6 | Y34: =CEILING(N34*VLOOKUP(O34, Коэффициенты!N3:O11, 2,FALSE)*0.875,2)&" кг" -> 52 кг | Z34: 3х4 | AA34: =CEILING((N34*VLOOKUP(O34, Коэффициенты!N3:O11, 2,FALSE)+P34)*0.9,2)&" кг" -> 56 кг | AB34: 2х4 | AE34: =CEILING((N34*VLOOKUP(O34, Коэффициенты!N3:O11, 2,FALSE)+P34)*0.7,2)&" кг" -> 44 кг | AF34: 5х8 | AG34: =CEILING((N34*VLOOKUP(O34, Коэффициенты!N3:O11, 2,FALSE)+P34)*0.75,2)&" кг" -> 48 кг | AH34: 4х8 | AI34: =CEILING((N34*VLOOKUP(O34, Коэффициенты!N3:O11, 2,FALSE)+P34)*0.8,2)&" кг" -> 50 кг | AJ34: 4х6 | AK34: =CEILING((N34*VLOOKUP(O34, Коэффициенты!N3:O11, 2,FALSE)+P34)*0.85,2)&" кг" -> 54 кг | AL34: 3х6 | AM34: =CEILING((N34*VLOOKUP(O34, Коэффициенты!N3:O11, 2,FALSE)+P34)*0.9,2)&" кг" -> 56 кг | AN34: 3х4 | AO34: =CEILING((N34*VLOOKUP(O34, Коэффициенты!N3:O11, 2,FALSE)+P34+P34)*0.9,2)&" кг" -> 58 кг | AP34: 2х4
L36: Жим лёжа узким хватом | N36: ='Программа тренировок '!C127 -> 80 | O36: ='Программа тренировок '!D127 -> 6 | P36: ='Программа тренировок '!E127 -> 5 | Q36: =CEILING(N36*VLOOKUP(O36, Коэффициенты!H3:I6, 2,FALSE)*0.65,2.5)&" кг" -> 60 кг | R36: 4х5 | S36: =CEILING(N36*VLOOKUP(O36, Коэффициенты!H3:I6, 2,FALSE)*0.7,2.5)&" кг" -> 65 кг | T36: 4х5 | U36: =CEILING(N36*VLOOKUP(O36, Коэффициенты!H3:I6, 2,FALSE)*0.75,2.5)&" кг" -> 70 кг | V36: 3х5 | W36: =CEILING(N36*VLOOKUP(O36, Коэффициенты!H3:I6, 2,FALSE)*0.8,2.5)&" кг" -> 75 кг | X36: 3х5 | Y36: =CEILING(N36*VLOOKUP(O36, Коэффициенты!H3:I6, 2,FALSE)*0.85,2.5)&" кг" -> 80 кг | Z36: 2х5 | AA36: =CEILING((N36*VLOOKUP(O36, Коэффициенты!H3:I6, 2,FALSE)+P36)*0.865,2.5)&" кг" -> 85 кг | AB36: 1х5 | AE36: =CEILING((N36*VLOOKUP(O36, Коэффициенты!H3:I6, 2,FALSE)+P36)*0.65,2.5)&" кг" -> 65 кг | AF36: 3х5 | AG36: =CEILING((N36*VLOOKUP(O36, Коэффициенты!H3:I6, 2,FALSE)+P36)*0.7,2.5)&" кг" -> 70 кг | AH36: 3х5 | AI36: =CEILING((N36*VLOOKUP(O36, Коэффициенты!H3:I6, 2,FALSE)+P36)*0.75,2.5)&" кг" -> 75 кг | AJ36: 2х5 | AK36: =CEILING((N36*VLOOKUP(O36, Коэффициенты!H3:I6, 2,FALSE)+P36)*0.8,2.5)&" кг" -> 80 кг | AL36: 2х5 | AM36: =CEILING((N36*VLOOKUP(O36, Коэффициенты!H3:I6, 2,FALSE)+P36)*0.85,2.5)&" кг" -> 82,5 кг | AN36: 1х5 | AO36: =CEILING((N36*VLOOKUP(O36, Коэффициенты!H3:I6, 2,FALSE)+P36+P36)*0.865,2.5)&" кг" -> 90 кг | AP36: 1х5
L37: Отжимания на брусьях (собственный вес) | N37: ='Программа тренировок '!C127 -> 80 | O37: ='Программа тренировок '!D127 -> 6 | P37: 2 | Q37: 6 подходов | R37: =FLOOR(0.4*O37,1)&" повт" -> 2 повт | S37: 5 подходов | T37: =FLOOR(0.5*O37,1)&" повт" -> 3 повт | U37: 4 подхода | V37: =FLOOR(0.6*O37,1)&" повт" -> 3 повт | W37: 3 подхода | X37: =CEILING(0.7*O37,1)&" повт" -> 5 повт | Y37: 2 подхода | Z37: =FLOOR(IF(0.8*O37-0.7*O37<1,0.8*O37+1,0.8*O37),1)&" повт" -> 5 повт | AA37: 1 подход | AB37: =O37+P37&" повт" -> 8 повт | AE37: 6 подходов | AF37: =FLOOR(0.4*O37+P37,1)&" повт" -> 4 повт | AG37: 5 подходов | AH37: =FLOOR(0.5*O37+P37,1)&" повт" -> 5 повт | AI37: 4 подхода | AJ37: =FLOOR(0.6*O37+P37,1)&" повт" -> 5 повт | AK37: 3 подхода | AL37: =FLOOR(0.8*O37+P37,1)&" повт" -> 6 повт | AM37: 2 подхода | AN37: =CEILING(0.8*O37+P37,1)&" повт" -> 7 повт | AO37: 1 подход | AP37: =O37+P37+P37&" повт" -> 10 повт
L38: Разгибания рук на блоке | N38: ='Программа тренировок '!C127 -> 80 | O38: ='Программа тренировок '!D127 -> 6 | P38: ='Программа тренировок '!E127 -> 5 | Q38: =CEILING(N38*VLOOKUP(O38, Коэффициенты!N3:O11, 2,FALSE)*0.6,3)&" кг" -> 54 кг | R38: 5х10 | S38: =CEILING(N38*VLOOKUP(O38, Коэффициенты!N3:O11, 2,FALSE)*0.65,3)&" кг" -> 57 кг | T38: 4x10 | U38: =CEILING(N38*VLOOKUP(O38, Коэффициенты!N3:O11, 2,FALSE)*0.7,3)&" кг" -> 63 кг | V38: 4х8 | W38: =CEILING(N38*VLOOKUP(O38, Коэффициенты!N3:O11, 2,FALSE)*0.75,3)&" кг" -> 66 кг | X38: 3х8 | Y38: =CEILING(N38*VLOOKUP(O38, Коэффициенты!N3:O11, 2,FALSE)*0.85,3)&" кг" -> 75 кг | Z38: 3х6 | AA38: =CEILING((N38*VLOOKUP(O38, Коэффициенты!N3:O11, 2,FALSE)+P38)*0.9,3)&" кг" -> 84 кг | AB38: 2х6 | AE38: =CEILING((N38*VLOOKUP(O38, Коэффициенты!N3:O11, 2,FALSE)+P38)*0.6,3)&" кг" -> 57 кг | AF38: 5х10 | AG38: =CEILING((N38*VLOOKUP(O38, Коэффициенты!N3:O11, 2,FALSE)+P38)*0.65,3)&" кг" -> 60 кг | AH38: 4x10 | AI38: =CEILING((N38*VLOOKUP(O38, Коэффициенты!N3:O11, 2,FALSE)+P38)*0.7,3)&" кг" -> 66 кг | AJ38: 4х8 | AK38: =CEILING((N38*VLOOKUP(O38, Коэффициенты!N3:O11, 2,FALSE)+P38)*0.75,3)&" кг" -> 69 кг | AL38: 3х8 | AM38: =CEILING((N38*VLOOKUP(O38, Коэффициенты!N3:O11, 2,FALSE)+P38)*0.85,3)&" кг" -> 81 кг | AN38: 3х6 | AO38: =CEILING((N38*VLOOKUP(O38,Коэффициенты!N3:O11,2,FALSE)+2*P38)*0.9,3)&" кг" -> 90 кг | AP38: 2х6
L39: +
L40: Шраги | N40: ='Программа тренировок '!C128 -> 0 | O40: ='Программа тренировок '!D128 -> 0 | P40: ='Программа тренировок '!E128 -> 0 | Q40: =CEILING(N40*VLOOKUP(O40, Коэффициенты!N3:O11, 2,FALSE)*0.65,2.5)&" кг" -> #N/A | R40: 5х8 | S40: =CEILING(N40*VLOOKUP(O40, Коэффициенты!N3:O11, 2,FALSE)*0.7,2.5)&" кг" -> #N/A | T40: 4х8 | U40: =CEILING(N40*VLOOKUP(O40, Коэффициенты!N3:O11, 2,FALSE)*0.75,2.5)&" кг" -> #N/A | V40: 4х6 | W40: =CEILING(N40*VLOOKUP(O40, Коэффициенты!N3:O11, 2,FALSE)*0.8,2.5)&" кг" -> #N/A | X40: 3х6 | Y40: =CEILING(N40*VLOOKUP(O40, Коэффициенты!N3:O11, 2,FALSE)*0.875,2.5)&" кг" -> #N/A | Z40: 3х4 | AA40: =CEILING((N40*VLOOKUP(O40, Коэффициенты!N3:O11, 2,FALSE)+P40)*0.9,2.5)&" кг" -> #N/A | AB40: 2х4 | AE40: =CEILING((N40*VLOOKUP(O40, Коэффициенты!N3:O11, 2,FALSE)+P40)*0.7,2.5)&" кг" -> #N/A | AF40: 5х8 | AG40: =CEILING((N40*VLOOKUP(O40, Коэффициенты!N3:O11, 2,FALSE)+P40)*0.75,2.5)&" кг" -> #N/A | AH40: 4х8 | AI40: =CEILING((N40*VLOOKUP(O40, Коэффициенты!N3:O11, 2,FALSE)+P40)*0.8,2.5)&" кг" -> #N/A | AJ40: 4х6 | AK40: =CEILING((N40*VLOOKUP(O40, Коэффициенты!N3:O11, 2,FALSE)+P40)*0.85,2.5)&" кг" -> #N/A | AL40: 3х6 | AM40: =CEILING((N40*VLOOKUP(O40, Коэффициенты!N3:O11, 2,FALSE)+P40)*0.9,2.5)&" кг" -> #N/A | AN40: 3х4 | AO40: =CEILING((N40*VLOOKUP(O40, Коэффициенты!N3:O11, 2,FALSE)+P40+P40)*0.9,2.5)&" кг" -> #N/A | AP40: 2х4
L41: Подъёмы на носки | N41: ='Программа тренировок '!C128 -> 0 | O41: ='Программа тренировок '!D128 -> 0 | P41: ='Программа тренировок '!E128 -> 0 | Q41: =CEILING(N41*VLOOKUP(O41, Коэффициенты!N3:O11, 2,FALSE)*0.7,2.5)&" кг" -> #N/A | R41: 5х10 | S41: =CEILING(N41*VLOOKUP(O41, Коэффициенты!N3:O11, 2,FALSE)*0.75,2.5)&" кг" -> #N/A | T41: 4x10 | U41: =CEILING(N41*VLOOKUP(O41, Коэффициенты!N3:O11, 2,FALSE)*0.8,2.5)&" кг" -> #N/A | V41: 4х8 | W41: =CEILING(N41*VLOOKUP(O41, Коэффициенты!N3:O11, 2,FALSE)*0.85,2.5)&" кг" -> #N/A | X41: 3х8 | Y41: =CEILING(N41*VLOOKUP(O41, Коэффициенты!N3:O11, 2,FALSE)*0.9,2.5)&" кг" -> #N/A | Z41: 3х6 | AA41: =CEILING((N41*VLOOKUP(O41, Коэффициенты!N3:O11, 2,FALSE)+P41)*0.9,2.5)&" кг" -> #N/A | AB41: 2х6 | AE41: =CEILING((N41*VLOOKUP(O41, Коэффициенты!N3:O11, 2,FALSE)+P41)*0.7,2.5)&" кг" -> #N/A | AF41: 5х10 | AG41: =CEILING((N41*VLOOKUP(O41, Коэффициенты!N3:O11, 2,FALSE)+P41)*0.75,2.5)&" кг" -> #N/A | AH41: 4x10 | AI41: =CEILING((N41*VLOOKUP(O41, Коэффициенты!N3:O11, 2,FALSE)+P41)*0.8,2.5)&" кг" -> #N/A | AJ41: 4х8 | AK41: =CEILING((N41*VLOOKUP(O41, Коэффициенты!N3:O11, 2,FALSE)+P41)*0.85,2.5)&" кг" -> #N/A | AL41: 3х8 | AM41: =CEILING((N41*VLOOKUP(O41, Коэффициенты!N3:O11, 2,FALSE)+P41)*0.9,2.5)&" кг" -> #N/A | AN41: 3х6 | AO41: =CEILING((N41*VLOOKUP(O41,Коэффициенты!N3:O11,2,FALSE)+P227)*0.9,2.5)&" кг" -> #N/A | AP41: 2х6
L44: Армейский жим | N44: ='Программа тренировок '!C132 -> 72.5 | O44: ='Программа тренировок '!D132 -> 4 | P44: ='Программа тренировок '!E132 -> 2.5 | Q44: =CEILING(N44*VLOOKUP(O44, Коэффициенты!K3:L6, 2,FALSE)*0.55,2.5)&" кг" -> 47,5 кг | R44: 5x5 | S44: =CEILING(N44*VLOOKUP(O44, Коэффициенты!K3:L6, 2,FALSE)*0.625,2.5)&" кг" -> 55 кг | T44: 4x5 | U44: =CEILING(N44*VLOOKUP(O44, Коэффициенты!K3:L6, 2,FALSE)*0.7,2.5)&" кг" -> 60 кг | V44: 4x4 | W44: =CEILING(N44*VLOOKUP(O44, Коэффициенты!K3:L6, 2,FALSE)*0.75,2.5)&" кг" -> 65 кг | X44: 3x4 | Y44: =CEILING(N44*VLOOKUP(O44, Коэффициенты!K3:L6, 2,FALSE)*0.8,2.5)&" кг" -> 70 кг | Z44: 3х3 | AA44: =CEILING((N44*VLOOKUP(O44, Коэффициенты!K3:L6, 2,FALSE)+P44)*0.825,2.5)&" кг" -> 72,5 кг | AB44: 2x3 | AE44: =CEILING((N44*VLOOKUP(O44, Коэффициенты!K3:L6, 2,FALSE)+P44)*0.55,2.5)&" кг" -> 50 кг | AF44: 5х5 | AG44: =CEILING((N44*VLOOKUP(O44, Коэффициенты!K3:L6, 2,FALSE)+P44)*0.65,2.5)&" кг" -> 57,5 кг | AH44: 4х5 | AI44: =CEILING((N44*VLOOKUP(O44, Коэффициенты!K3:L6, 2,FALSE)+P44)*0.7,2.5)&" кг" -> 62,5 кг | AJ44: 4х4 | AK44: =CEILING((N44*VLOOKUP(O44, Коэффициенты!K3:L6, 2,FALSE)+P44)*0.75,2.5)&" кг" -> 67,5 кг | AL44: 3х4 | AM44: =CEILING((N44*VLOOKUP(O44, Коэффициенты!K3:L6, 2,FALSE)+P44)*0.8,2.5)&" кг" -> 72,5 кг | AN44: 3х3 | AO44: =FLOOR((N44*VLOOKUP(O44, Коэффициенты!K3:L6, 2,FALSE)+2*P44)*0.835,2.5)&" кг" -> 75 кг | AP44: 2х3
L45: Жим гантелей сидя | N45: ='Программа тренировок '!C132 -> 72.5 | O45: ='Программа тренировок '!D132 -> 4 | P45: ='Программа тренировок '!E132 -> 2.5 | Q45: =CEILING(N45*VLOOKUP(O45, Коэффициенты!N3:O11, 2,FALSE)*0.4,2)&" кг" -> 30 кг | R45: 5х12 | S45: =CEILING(N45*VLOOKUP(O45, Коэффициенты!N3:O11, 2,FALSE)*0.5,2)&" кг" -> 38 кг | T45: 5х12 | U45: =CEILING(N45*VLOOKUP(O45, Коэффициенты!N3:O11, 2,FALSE)*0.6,2)&" кг" -> 46 кг | V45: 4х10 | W45: =CEILING(N45*VLOOKUP(O45, Коэффициенты!N3:O11, 2,FALSE)*0.7,2)&" кг" -> 54 кг | X45: 4х10 | Y45: =CEILING(N45*VLOOKUP(O45, Коэффициенты!N3:O11, 2,FALSE)*0.8,2)&" кг" -> 60 кг | Z45: 3х8 | AA45: =CEILING((N45*VLOOKUP(O45, Коэффициенты!N3:O11, 2,FALSE)+P45)*0.85,2)&" кг" -> 66 кг | AB45: 3х8 | AE45: =CEILING((N45*VLOOKUP(O45, Коэффициенты!N3:O11, 2,FALSE)+P45)*0.4,2)&" кг" -> 32 кг | AF45: 5х12 | AG45: =CEILING((N45*VLOOKUP(O45, Коэффициенты!N3:O11, 2,FALSE)+P45)*0.5,2)&" кг" -> 40 кг | AH45: 5х12 | AI45: =CEILING((N45*VLOOKUP(O45, Коэффициенты!N3:O11, 2,FALSE)+P45)*0.6,2)&" кг" -> 48 кг | AJ45: 4х10 | AK45: =CEILING((N45*VLOOKUP(O45, Коэффициенты!N3:O11, 2,FALSE)+P45)*0.7,2)&" кг" -> 56 кг | AL45: 4х10 | AM45: =CEILING((N45*VLOOKUP(O45, Коэффициенты!N3:O11, 2,FALSE)+P45)*0.8,2)&" кг" -> 62 кг | AN45: 3х8 | AO45: =CEILING((N45*VLOOKUP(O45, Коэффициенты!N3:O11, 2,FALSE)+P45+P45)*0.9,2)&" кг" -> 72 кг | AP45: 3х8
L48: Тяга штанги в наклоне | N48: ='Программа тренировок '!C133 -> 150 | O48: ='Программа тренировок '!D133 -> 4 | P48: ='Программа тренировок '!E133 -> 5 | Q48: =CEILING(N48*VLOOKUP(O48, Коэффициенты!H3:I6, 2,FALSE)*0.7,2.5)&" кг" -> 115 кг | R48: 5х5 | S48: =CEILING(N48*VLOOKUP(O48, Коэффициенты!H3:I6, 2,FALSE)*0.75,2.5)&" кг" -> 122,5 кг | T48: 4х5 | U48: =CEILING(N48*VLOOKUP(O48, Коэффициенты!H3:I6, 2,FALSE)*0.8,2.5)&" кг" -> 132,5 кг | V48: 4х4 | W48: =CEILING(N48*VLOOKUP(O48, Коэффициенты!H3:I6, 2,FALSE)*0.85,2.5)&" кг" -> 140 кг | X48: 3х4 | Y48: =CEILING(N48*VLOOKUP(O48, Коэффициенты!H3:I6, 2,FALSE)*0.9,2.5)&" кг" -> 147,5 кг | Z48: 3х3 | AA48: =CEILING((N48*VLOOKUP(O48, Коэффициенты!H3:I6, 2,FALSE)+P48)*0.9,2.5)&" кг" -> 152,5 кг | AB48: 2х3 | AE48: =CEILING((N48*VLOOKUP(O48, Коэффициенты!H3:I6, 2,FALSE)+P48)*0.7,2.5)&" кг" -> 120 кг | AF48: 5х5 | AG48: =CEILING((N48*VLOOKUP(O48, Коэффициенты!H3:I6, 2,FALSE)+P48)*0.75,2.5)&" кг" -> 127,5 кг | AH48: 4х5 | AI48: =CEILING((N48*VLOOKUP(O48, Коэффициенты!H3:I6, 2,FALSE)+P48)*0.8,2.5)&" кг" -> 135 кг | AJ48: 4х4 | AK48: =CEILING((N48*VLOOKUP(O48, Коэффициенты!H3:I6, 2,FALSE)+P48)*0.85,2.5)&" кг" -> 145 кг | AL48: 3х4 | AM48: =CEILING((N48*VLOOKUP(O48, Коэффициенты!H3:I6, 2,FALSE)+P48)*0.9,2.5)&" кг" -> 152,5 кг | AN48: 3х3 | AO48: =CEILING((N48*VLOOKUP(O48, Коэффициенты!H3:I6, 2,FALSE)+P48+P48)*0.9,2.5)&" кг" -> 157,5 кг | AP48: 2х3
L49: Тяга гантели в наклоне | N49: ='Программа тренировок '!C133 -> 150 | O49: ='Программа тренировок '!D133 -> 4 | P49: ='Программа тренировок '!E133 -> 5 | Q49: =CEILING(N49*VLOOKUP(O49, Коэффициенты!N3:O11, 2,FALSE)*0.65,2)&" кг" -> 102 кг | R49: 5х8 | S49: =CEILING(N49*VLOOKUP(O49, Коэффициенты!N3:O11, 2,FALSE)*0.7,2)&" кг" -> 110 кг | T49: 4х8 | U49: =CEILING(N49*VLOOKUP(O49, Коэффициенты!N3:O11, 2,FALSE)*0.75,2)&" кг" -> 116 кг | V49: 4х6 | W49: =CEILING(N49*VLOOKUP(O49, Коэффициенты!N3:O11, 2,FALSE)*0.8,2)&" кг" -> 124 кг | X49: 3х6 | Y49: =CEILING(N49*VLOOKUP(O49, Коэффициенты!N3:O11, 2,FALSE)*0.875,2)&" кг" -> 136 кг | Z49: 3х4 | AA49: =CEILING((N49*VLOOKUP(O49, Коэффициенты!N3:O11, 2,FALSE)+P49)*0.9,2)&" кг" -> 144 кг | AB49: 2х4 | AE49: =CEILING((N49*VLOOKUP(O49, Коэффициенты!N3:O11, 2,FALSE)+P49)*0.7,2)&" кг" -> 112 кг | AF49: 5х8 | AG49: =CEILING((N49*VLOOKUP(O49, Коэффициенты!N3:O11, 2,FALSE)+P49)*0.75,2)&" кг" -> 120 кг | AH49: 4х8 | AI49: =CEILING((N49*VLOOKUP(O49, Коэффициенты!N3:O11, 2,FALSE)+P49)*0.8,2)&" кг" -> 128 кг | AJ49: 4х6 | AK49: =CEILING((N49*VLOOKUP(O49, Коэффициенты!N3:O11, 2,FALSE)+P49)*0.85,2)&" кг" -> 136 кг | AL49: 3х6 | AM49: =CEILING((N49*VLOOKUP(O49, Коэффициенты!N3:O11, 2,FALSE)+P49)*0.9,2)&" кг" -> 144 кг | AN49: 3х4 | AO49: =CEILING((N49*VLOOKUP(O49, Коэффициенты!N3:O11, 2,FALSE)+P49+P49)*0.9,2)&" кг" -> 150 кг | AP49: 2х4
L50: Тяга в хаммере | N50: ='Программа тренировок '!C133 -> 150 | O50: ='Программа тренировок '!D133 -> 4 | P50: ='Программа тренировок '!E133 -> 5 | Q50: =CEILING(N50*VLOOKUP(O50, Коэффициенты!N3:O11, 2,FALSE)*0.65,2.5)&" кг" -> 102,5 кг | R50: 5х8 | S50: =CEILING(N50*VLOOKUP(O50, Коэффициенты!N3:O11, 2,FALSE)*0.7,2.5)&" кг" -> 110 кг | T50: 4х8 | U50: =CEILING(N50*VLOOKUP(O50, Коэффициенты!N3:O11, 2,FALSE)*0.75,2.5)&" кг" -> 117,5 кг | V50: 4х6 | W50: =CEILING(N50*VLOOKUP(O50, Коэффициенты!N3:O11, 2,FALSE)*0.8,2.5)&" кг" -> 125 кг | X50: 3х6 | Y50: =CEILING(N50*VLOOKUP(O50, Коэффициенты!N3:O11, 2,FALSE)*0.875,2.5)&" кг" -> 137,5 кг | Z50: 3х4 | AA50: =CEILING((N50*VLOOKUP(O50, Коэффициенты!N3:O11, 2,FALSE)+P50)*0.9,2.5)&" кг" -> 145 кг | AB50: 2х4 | AE50: =CEILING((N50*VLOOKUP(O50, Коэффициенты!N3:O11, 2,FALSE)+P50)*0.7,2.5)&" кг" -> 112,5 кг | AF50: 5х8 | AG50: =CEILING((N50*VLOOKUP(O50, Коэффициенты!N3:O11, 2,FALSE)+P50)*0.75,2.5)&" кг" -> 120 кг | AH50: 4х8 | AI50: =CEILING((N50*VLOOKUP(O50, Коэффициенты!N3:O11, 2,FALSE)+P50)*0.8,2.5)&" кг" -> 130 кг | AJ50: 4х6 | AK50: =CEILING((N50*VLOOKUP(O50, Коэффициенты!N3:O11, 2,FALSE)+P50)*0.85,2.5)&" кг" -> 137,5 кг | AL50: 3х6 | AM50: =CEILING((N50*VLOOKUP(O50, Коэффициенты!N3:O11, 2,FALSE)+P50)*0.9,2.5)&" кг" -> 145 кг | AN50: 3х4 | AO50: =CEILING((N50*VLOOKUP(O50, Коэффициенты!N3:O11, 2,FALSE)+P50+P50)*0.9,2.5)&" кг" -> 150 кг | AP50: 2х4
L54: Приседания со штангой | N54: =IF('Программа тренировок '!B69=Формулы!L17, Формулы!N17, 'Программа тренировок '!C134) -> 150 | O54: =IF('Программа тренировок '!B69=Формулы!L17, Формулы!O17, 'Программа тренировок '!D134) -> 4 | P54: =IF('Программа тренировок '!B69=Формулы!L17, Формулы!P17, 'Программа тренировок '!E134) -> 5 | Q54: =CEILING(N54*VLOOKUP(O54, Коэффициенты!H3:I6, 2,FALSE)*0.5,2.5)&" кг" -> 82,5 кг | R54: 5х5 | S54: =CEILING(N54*VLOOKUP(O54, Коэффициенты!H3:I6, 2,FALSE)*0.55,2.5)&" кг" -> 90 кг | T54: 4х5 | U54: =CEILING(N54*VLOOKUP(O54, Коэффициенты!H3:I6, 2,FALSE)*0.6,2.5)&" кг" -> 100 кг | V54: 4х4 | W54: =CEILING(N54*VLOOKUP(O54, Коэффициенты!H3:I6, 2,FALSE)*0.65,2.5)&" кг" -> 107,5 кг | X54: 3х4 | Y54: =CEILING(N54*VLOOKUP(O54, Коэффициенты!H3:I6, 2,FALSE)*0.7,2.5)&" кг" -> 115 кг | Z54: 3х3 | AA54: =CEILING(N54*VLOOKUP(O54, Коэффициенты!H3:I6, 2,FALSE)*0.75,2.5)&" кг" -> 122,5 кг | AB54: 2х3 | AE54: =CEILING((N54*VLOOKUP(O54, Коэффициенты!H3:I6, 2,FALSE)+P17)*0.5,2.5)&" кг" -> 85 кг | AF54: 5х5 | AG54: =CEILING((N54*VLOOKUP(O54, Коэффициенты!H3:I6, 2,FALSE)+P17)*0.55,2.5)&" кг" -> 92,5 кг | AH54: 4х5 | AI54: =CEILING((N54*VLOOKUP(O54, Коэффициенты!H3:I6, 2,FALSE)+P17)*0.6,2.5)&" кг" -> 102,5 кг | AJ54: 4х4 | AK54: =CEILING((N54*VLOOKUP(O54, Коэффициенты!H3:I6, 2,FALSE)+P17)*0.65,2.5)&" кг" -> 110 кг | AL54: 3х4 | AM54: =CEILING((N54*VLOOKUP(O54, Коэффициенты!H3:I6, 2,FALSE)+P17)*0.7,2.5)&" кг" -> 120 кг | AN54: 3х3 | AO54: =CEILING((N54*VLOOKUP(O54, Коэффициенты!H3:I6, 2,FALSE)+P17)*0.75,2.5)&" кг" -> 127,5 кг | AP54: 2х3
L55: Жим платформы ногами | N55: ='Программа тренировок '!C134 -> 0 | O55: ='Программа тренировок '!D134 -> 0 | P55: ='Программа тренировок '!E134 -> 0 | Q55: =CEILING(N55*VLOOKUP(O55, Коэффициенты!N3:O11, 2,FALSE)*0.7,2.5)&" кг" -> #N/A | R55: 5х10 | S55: =CEILING(N55*VLOOKUP(O55, Коэффициенты!N3:O11, 2,FALSE)*0.75,2.5)&" кг" -> #N/A | T55: 4x10 | U55: =CEILING(N55*VLOOKUP(O55, Коэффициенты!N3:O11, 2,FALSE)*0.8,2.5)&" кг" -> #N/A | V55: 4х8 | W55: =CEILING(N55*VLOOKUP(O55, Коэффициенты!N3:O11, 2,FALSE)*0.85,2.5)&" кг" -> #N/A | X55: 3х8 | Y55: =CEILING(N55*VLOOKUP(O55, Коэффициенты!N3:O11, 2,FALSE)*0.9,2.5)&" кг" -> #N/A | Z55: 3х6 | AA55: =CEILING((N55*VLOOKUP(O55, Коэффициенты!N3:O11, 2,FALSE)+P55)*0.9,2.5)&" кг" -> #N/A | AB55: 2х6 | AE55: =CEILING((N55*VLOOKUP(O55, Коэффициенты!N3:O11, 2,FALSE)+P55)*0.7,2.5)&" кг" -> #N/A | AF55: 5х10 | AG55: =CEILING((N55*VLOOKUP(O55, Коэффициенты!N3:O11, 2,FALSE)+P55)*0.75,2.5)&" кг" -> #N/A | AH55: 4x10 | AI55: =CEILING((N55*VLOOKUP(O55, Коэффициенты!N3:O11, 2,FALSE)+P55)*0.8,2.5)&" кг" -> #N/A | AJ55: 4х8 | AK55: =CEILING((N55*VLOOKUP(O55, Коэффициенты!N3:O11, 2,FALSE)+P55)*0.85,2.5)&" кг" -> #N/A | AL55: 3х8 | AM55: =CEILING((N55*VLOOKUP(O55, Коэффициенты!N3:O11, 2,FALSE)+P55)*0.9,2.5)&" кг" -> #N/A | AN55: 3х6 | AO55: =CEILING((N55*VLOOKUP(O55,Коэффициенты!N3:O11,2,FALSE)+P240)*0.9,2.5)&" кг" -> #N/A | AP55: 2х6
L56: Фронтальные приседания | N56: ='Программа тренировок '!C134 -> 0 | O56: ='Программа тренировок '!D134 -> 0 | P56: ='Программа тренировок '!E134 -> 0 | Q56: =CEILING(N56*VLOOKUP(O56, Коэффициенты!H3:I6, 2,FALSE)*0.5,2.5)&" кг" -> #N/A | R56: 5х5 | S56: =CEILING(N56*VLOOKUP(O56, Коэффициенты!H3:I6, 2,FALSE)*0.55,2.5)&" кг" -> #N/A | T56: 4х5 | U56: =CEILING(N56*VLOOKUP(O56, Коэффициенты!H3:I6, 2,FALSE)*0.6,2.5)&" кг" -> #N/A | V56: 4х4 | W56: =CEILING(N56*VLOOKUP(O56, Коэффициенты!H3:I6, 2,FALSE)*0.65,2.5)&" кг" -> #N/A | X56: 3х4 | Y56: =CEILING(N56*VLOOKUP(O56, Коэффициенты!H3:I6, 2,FALSE)*0.7,2.5)&" кг" -> #N/A | Z56: 3х3 | AA56: =CEILING(N56*VLOOKUP(O56, Коэффициенты!H3:I6, 2,FALSE)*0.75,2.5)&" кг" -> #N/A | AB56: 2х3 | AE56: =CEILING((N56*VLOOKUP(O56, Коэффициенты!H3:I6, 2,FALSE)+P56)*0.5,2.5)&" кг" -> #N/A | AF56: 5х5 | AG56: =CEILING((N56*VLOOKUP(O56, Коэффициенты!H3:I6, 2,FALSE)+P56)*0.55,2.5)&" кг" -> #N/A | AH56: 4х5 | AI56: =CEILING((N56*VLOOKUP(O56, Коэффициенты!H3:I6, 2,FALSE)+P56)*0.6,2.5)&" кг" -> #N/A | AJ56: 4х4 | AK56: =CEILING((N56*VLOOKUP(O56, Коэффициенты!H3:I6, 2,FALSE)+P56)*0.65,2.5)&" кг" -> #N/A | AL56: 3х4 | AM56: =CEILING((N56*VLOOKUP(O56, Коэффициенты!H3:I6, 2,FALSE)+P56)*0.7,2.5)&" кг" -> #N/A | AN56: 3х3 | AO56: =CEILING((N56*VLOOKUP(O56, Коэффициенты!H3:I6, 2,FALSE)+P56)*0.75,2.5)&" кг" -> #N/A | AP56: 2х3
L59: Подтягивания (собственный вес) | N59: =IF('Программа тренировок '!B68=Формулы!L59, Формулы!N14, 'Программа тренировок '!C135) -> 120 | O59: =IF('Программа тренировок '!B68=Формулы!L59, Формулы!O14, 'Программа тренировок '!D135) -> 8 | P59: =IF('Программа тренировок '!B68=Формулы!L59, Формулы!P14, 'Программа тренировок '!E135) -> 2 | Q59: 6 подходов | R59: =FLOOR(0.4*O59,1)&" повт" -> 3 повт | S59: 5 подходов | T59: =FLOOR(0.5*O59,1)&" повт" -> 4 повт | U59: 4 подхода | V59: =FLOOR(0.6*O59,1)&" повт" -> 4 повт | W59: 3 подхода | X59: =CEILING(0.7*O59,1)&" повт" -> 6 повт | Y59: 2 подхода | Z59: =FLOOR(IF(0.8*O59-0.7*O59<1,0.8*O59+1,0.8*O59),1)&" повт" -> 7 повт | AA59: 1 подход | AB59: =O59+P59&" повт" -> 10 повт | AE59: 6 подходов | AF59: =FLOOR(0.4*O59+P59,1)&" повт" -> 5 повт | AG59: 5 подходов | AH59: =FLOOR(0.5*O59+P59,1)&" повт" -> 6 повт | AI59: 4 подхода | AJ59: =FLOOR(0.6*O59+P59,1)&" повт" -> 6 повт | AK59: 3 подхода | AL59: =FLOOR(0.8*O59+P59,1)&" повт" -> 8 повт | AM59: 2 подхода | AN59: =CEILING(0.8*O59+P59,1)&" повт" -> 9 повт | AO59: 1 подход | AP59: =O59+P59+P59&" повт" -> 12 повт
L60: Пуловер | N60: ='Программа тренировок '!C135 -> 120 | O60: ='Программа тренировок '!D135 -> 8 | P60: ='Программа тренировок '!E135 -> 2 | Q60: =CEILING(N60*VLOOKUP(O60, Коэффициенты!N3:O11, 2,FALSE)*0.6,3)&" кг" -> #N/A | R60: 5х10 | S60: =CEILING(N60*VLOOKUP(O60, Коэффициенты!N3:O11, 2,FALSE)*0.65,3)&" кг" -> #N/A | T60: 4x10 | U60: =CEILING(N60*VLOOKUP(O60, Коэффициенты!N3:O11, 2,FALSE)*0.7,3)&" кг" -> #N/A | V60: 4х8 | W60: =CEILING(N60*VLOOKUP(O60, Коэффициенты!N3:O11, 2,FALSE)*0.75,3)&" кг" -> #N/A | X60: 3х8 | Y60: =CEILING(N60*VLOOKUP(O60, Коэффициенты!N3:O11, 2,FALSE)*0.85,3)&" кг" -> #N/A | Z60: 3х6 | AA60: =CEILING((N60*VLOOKUP(O60, Коэффициенты!N3:O11, 2,FALSE)+P60)*0.9,3)&" кг" -> #N/A | AB60: 2х6 | AE60: =CEILING((N60*VLOOKUP(O60, Коэффициенты!N3:O11, 2,FALSE)+P60)*0.6,3)&" кг" -> #N/A | AF60: 5х10 | AG60: =CEILING((N60*VLOOKUP(O60, Коэффициенты!N3:O11, 2,FALSE)+P60)*0.65,3)&" кг" -> #N/A | AH60: 4x10 | AI60: =CEILING((N60*VLOOKUP(O60, Коэффициенты!N3:O11, 2,FALSE)+P60)*0.7,3)&" кг" -> #N/A | AJ60: 4х8 | AK60: =CEILING((N60*VLOOKUP(O60, Коэффициенты!N3:O11, 2,FALSE)+P60)*0.75,3)&" кг" -> #N/A | AL60: 3х8 | AM60: =CEILING((N60*VLOOKUP(O60, Коэффициенты!N3:O11, 2,FALSE)+P60)*0.85,3)&" кг" -> #N/A | AN60: 3х6 | AO60: =CEILING((N60*VLOOKUP(O60,Коэффициенты!N3:O11,2,FALSE)+2*P60)*0.9,3)&" кг" -> #N/A | AP60: 2х6
L61: Тяга горизонтального блока к поясу | N61: ='Программа тренировок '!C135 -> 120 | O61: ='Программа тренировок '!D135 -> 8 | P61: ='Программа тренировок '!E135 -> 2 | Q61: =CEILING(N61*VLOOKUP(O61, Коэффициенты!N3:O11, 2,FALSE)*0.6,3)&" кг" -> #N/A | R61: 5х10 | S61: =CEILING(N61*VLOOKUP(O61, Коэффициенты!N3:O11, 2,FALSE)*0.65,3)&" кг" -> #N/A | T61: 4x10 | U61: =CEILING(N61*VLOOKUP(O61, Коэффициенты!N3:O11, 2,FALSE)*0.7,3)&" кг" -> #N/A | V61: 4х8 | W61: =CEILING(N61*VLOOKUP(O61, Коэффициенты!N3:O11, 2,FALSE)*0.75,3)&" кг" -> #N/A | X61: 3х8 | Y61: =CEILING(N61*VLOOKUP(O61, Коэффициенты!N3:O11, 2,FALSE)*0.85,3)&" кг" -> #N/A | Z61: 3х6 | AA61: =CEILING((N61*VLOOKUP(O61, Коэффициенты!N3:O11, 2,FALSE)+P61)*0.9,3)&" кг" -> #N/A | AB61: 2х6 | AE61: =CEILING((N61*VLOOKUP(O61, Коэффициенты!N3:O11, 2,FALSE)+P61)*0.6,3)&" кг" -> #N/A | AF61: 5х10 | AG61: =CEILING((N61*VLOOKUP(O61, Коэффициенты!N3:O11, 2,FALSE)+P61)*0.65,3)&" кг" -> #N/A | AH61: 4x10 | AI61: =CEILING((N61*VLOOKUP(O61, Коэффициенты!N3:O11, 2,FALSE)+P61)*0.7,3)&" кг" -> #N/A | AJ61: 4х8 | AK61: =CEILING((N61*VLOOKUP(O61, Коэффициенты!N3:O11, 2,FALSE)+P61)*0.75,3)&" кг" -> #N/A | AL61: 3х8 | AM61: =CEILING((N61*VLOOKUP(O61, Коэффициенты!N3:O11, 2,FALSE)+P61)*0.85,3)&" кг" -> #N/A | AN61: 3х6 | AO61: =CEILING((N61*VLOOKUP(O61,Коэффициенты!N3:O11,2,FALSE)+2*P61)*0.9,3)&" кг" -> #N/A | AP61: 2х6
L63: +
...

Sheet Коэффициенты
C2: 1 | H2: Шаг: | I2: 1ПМ: | K2: Шаг: | L2: 1ПМ:
C3: 2 | D3: 2.5 | E3: 3 | F3: 2.5 | H3: =IF('Программа тренировок '!D206="boosty.to/yetiblog", 4, 9) -> 4 | I3: =100/92 -> 1.0869565 | K3: 4 | L3: =100/85 -> 1.1764706 | N3: 4 | O3: =100/97 -> 1.0309278 | Q3: 2
C4: 3 | D4: 5 | E4: 6 | F4: 3 | H4: 5 | I4: =100/89 -> 1.1235955 | K4: 5 | L4: =100/80 -> 1.25 | N4: 5 | O4: =100/95 -> 1.0526316 | Q4: 4
C5: 4 | D5: 7.5 | E5: 9 | F5: 5 | H5: 6 | I5: =IF('Программа тренировок '!B6=S154, 100/87, "") -> 1.1494253 | K5: 6 | L5: =100/75 -> 1.3333333 | N5: 6 | O5: =100/92 -> 1.0869565 | Q5: 6
C6: 5 | D6: 10 | F6: 6 | H6: 7 | I6: =100/85 -> 1.1764706 | K6: 7 | L6: =100/70 -> 1.4285714 | N6: 7 | O6: =IF('Программа тренировок '!B6=S154, 100/90,"") -> 1.1111111
C7: 6 | D7: 15 | F7: 7.5 | N7: =IF('Программа тренировок '!B205=S153, "8", "") -> 8 | O7: =100/87 -> 1.1494253
C8: 7 | D8: 20 | F8: 9 | N8: 9 | O8: =100/85 -> 1.1764706
C9: 8 | F9: 10 | N9: 10 | O9: =100/83 -> 1.2048193
C10: 9 | F10: 15 | N10: 11 | O10: =100/81 -> 1.2345679
C11: 10 | F11: 20 | N11: 12 | O11: =100/79 -> 1.2658228
E16: 1
E17: 2
E18: 3
E19: 4
E20: 5
E21: 6
E22: 7
E23: 8
E24: 9
E25: 10
E26: 11
E27: 12
... E61: 46
S153: Авторские видео-гайды по упражнениям и другие программы тренировок доступны подписчикам на Boosty
S154: ВИДЕО-ИНСТРУКЦИЯ К ДАННОЙ ПРОГРАММЕ ТРЕНИРОВОК
