Workbook
Name Нет: Коэффициенты!$C$2:$C$7
Name Подтягивания: Коэффициенты!$C$2:$C$7

Sheet Программа тренировок 
B7: ВИДЕО-ИНСТРУКЦИЯ К ДАННОЙ ПРОГРАММЕ ТРЕНИРОВОК
B8: Если у вас возникнут вопросы, то у меня есть постоянная поддержка к программам тренировок для всех подписчиков Boosty
B10: ПРАВИЛА СИЛОВОЙ ТРЕНИРОВКИ:
B11: Разминка:
B12: Каждая тренировка начинается с суставной гимнастики - необходимо в течение 5-10 минут разогреть все суставы (выполнить вращательные, сгибательные и разгибательные движения всеми доступными частями тела) - уделить особое внимание плечевому суставу, позвоночнику, коленям
B14: Разминочные подходы:
B15: В каждом упражнении делаем от 1 до 4,5 или даже 6 разминочных подходов перед рабочим весом (чем больше рабочий вес - тем больше подходов необходимо чтобы подготовить тело).
B16: В упражнениях с маленьким весом в качестве разминки достаточно взять 50% от рабочего веса и медленно поработать на 8-10 повторений в одном подходе (не закисляясь)
B17: Чем больше рабочий вес, тем больше требуется разминочных подходов перед рабочим весом, при этом во время разминки не делать большого кол-ва повторений, чтобы не закисляться (1х8, 1х6, 1х4, 1х2, 1х1)
B18: Например если приседания 120 кг, то понадобится сделать 20*8, 50*6, 70*4, 90*2, 110*1, а только затем рабочий вес (делать большие шаги в увеличении веса после 50%ПМ травмоопасно - 10-20 кг оптимальный шаг)
B20: Отдых между подходами:
B21: Во время силовой тренировки на 3-6 повторений с субмаксимальными весами используются большие интервалы времени отдыха 5-10 минут
... B35: Для этого нажмите на название упражнения в списке подготовительного периода и программа выдаст доступные варианты на замену каждого упражнения
E37: Если нажать на "+", то в программу добавится ещё одно упражнение на выбор
B48: 2. Подберите рабочие веса, которые соответствуют "ПМ" указанным в таблице и проведите с ними тренировку
B53: ПМ - это обозначение повторного максимума (например если вы можете пожать 100 кг только на 1 повторение, а 80 кг на 8 повторений, то 100 кг = 1ПМ, а 80 кг = 8ПМ)
B54: В таблице подготовительного периода указаны ПМ, с которыми вам необходимо выполнять упражнения
B56: Колонка Подх - это количество подходов с данным рабочим весом
B58: Колонка RIR - это количество повторений в запасе перед тем как наступит отказ.
B59: В данном случае 10ПМ 1 ПОДХ 2RIR означает что вам нужно выполнить 1 подход с весом, который вы можете пожать максимум на 10 повторений
B60: и остановиться за 2 повторения до отказа (то есть выполнить всего 8 повторений)
C63: ПОДГОТОВИТЕЛЬНЫЙ ПЕРИОД
C65: Неделя 1 | F65: Неделя 2
B66: День 1: | C66: ПМ | D66: Подх | E66: RIR (повт в запасе) | F66: ПМ | G66: Подх | H66: RIR (повт в запасе)
B67: Жим штанги лёжа | C67: 8ПМ | D67: 2 | E67: 2 | F67: 6ПМ | G67: 3 | H67: 2
B68: Подтягивания (с отягощением) | C68: =IF(B68=Формулы!L14, "собственный", "8ПМ") -> 8ПМ | D68: 2 | E68: 2 | F68: =IF(B68=Формулы!L14, "собственный", "6ПМ") -> 6ПМ | G68: 3 | H68: 2
B69: Жим платформы ногами | C69: 8ПМ | D69: 2 | E69: 2 | F69: 6ПМ | G69: 3 | H69: 2
B70: Махи с гантелями в стороны | C70: 10ПМ | D70: 2 | E70: 2 | F70: 8ПМ | G70: 3 | H70: 2
B71: + | C71: =IF(B71=Формулы!L39, "", "собственный") | D71: =IF(B71=Формулы!L39, "", "2") | E71: =IF(B71=Формулы!L39,"",IF(B71=Формулы!L68,"2","30 сек")) | F71: =IF(B71=Формулы!L39, "", "собственный") | G71: =IF(B71=Формулы!L39, "", "3") | H71: =IF(B71=Формулы!L39,"",IF(B71=Формулы!L68,"2","30 сек"))
B74: День 2: | C74: ПМ | D74: Подх | E74: RIR (повт в запасе) | F74: ПМ | G74: Подх | H74: RIR (повт в запасе)
B75: Становая тяга | C75: 8ПМ | D75: 2 | E75: 2 | F75: 6ПМ | G75: 3 | H75: 2
B76: Подъём штанги на бицепс | C76: 8ПМ | D76: 2 | E76: 2 | F76: 6ПМ | G76: 3 | H76: 2
B77: Жим гантелей лёжа | C77: 8ПМ | D77: 2 | E77: 2 | F77: 6ПМ | G77: 3 | H77: 2
B78: Разгибания рук на блоке | C78: =IF(B78=Формулы!L37, "собственный", "10ПМ") -> 10ПМ | D78: 2 | E78: 2 | F78: =IF(B78=Формулы!L37, "собственный", "8ПМ") -> 8ПМ | G78: 3 | H78: 2
B79: + | C79: =IF(B79=Формулы!L39, "", "10ПМ") | D79: =IF(B79=Формулы!L39, "", "2") | E79: =IF(B79=Формулы!L39, "", "2") | F79: =IF(B79=Формулы!L39, "", "8ПМ") | G79: =IF(B79=Формулы!L39, "", "3") | H79: =IF(B79=Формулы!L39, "", "2")
B82: День 3: | C82: ПМ | D82: Подх | E82: RIR (повт в запасе) | F82: ПМ | G82: Подх | H82: RIR (повт в запасе)
B83: Приседания со штангой | C83: 8ПМ | D83: 2 | E83: 2 | F83: 6ПМ | G83: 3 | H83: 2
B84: Армейский жим | C84: 8ПМ | D84: 2 | E84: 2 | F84: 6ПМ | G84: 3 | H84: 2
B85: Тяга штанги в наклоне | C85: 8ПМ | D85: 2 | E85: 2 | F85: 6ПМ | G85: 3 | H85: 2
B86: Тяга горизонтального блока к поясу | C86: =IF(B86=Формулы!L14, "собственный", "10ПМ") -> 10ПМ | D86: 2 | E86: 2 | F86: =IF(B86=Формулы!L14, "собственный", "8ПМ") -> 8ПМ | G86: 3 | H86: 2
...

Sheet Калькулятор подходов
C4: ПРОХОДКА (ВЫХОД НА 1ПМ) В ЖИМЕ ЛЁЖА ДЛЯ ЖИМА ДО 100 КГ | K4: ПРОХОДКА (ВЫХОД НА 1ПМ) В СТАНОВОЙ ТЯГЕ ДО 200 КГ
C6: Ваш ПМ: | D6: 95 | K6: Ваш ПМ: | L6: 150
D8: Вес | E8: Повт | F8: Время отдыха | L8: Вес | M8: Повт | N8: Время отдыха
C9: 1 подход | D9: 20 | E9: 10 | F9: 1 мин | K9: 1 подход | L9: 60 | M9: 6 | N9: 1-2 мин
C10: 2 подход | D10: =CEILING(D6*0.5,5) -> 50 | E10: 4 | F10: 1 мин | K10: 2 подход | L10: =CEILING(L6*0.5,5) -> 75 | M10: 4 | N10: 1-2 мин
C11: 3 подход | D11: =CEILING(D6*0.65,5) -> 65 | E11: 3 | F11: 2 мин | K11: 3 подход | L11: =CEILING(L6*0.65,5) -> 100 | M11: 3 | N11: 2-3 мин
C12: 4 подход | D12: =CEILING(D6*0.75,5) -> 75 | E12: 2 | F12: 2 мин | K12: 4 подход | L12: =CEILING(L6*0.75,5) -> 115 | M12: 2 | N12: 2-3 мин
C13: 5 подход | D13: =CEILING(D6*0.825,2.5) -> 80 | E13: 1 | F13: 3 мин | K13: 5 подход | L13: =CEILING(L6*0.825,2.5) -> 125 | M13: 1 | N13: 3 мин
C14: 6 подход | D14: =CEILING(D6*0.875,2.5) -> 85 | E14: 1 | F14: 4 мин | K14: 6 подход | L14: =CEILING(L6*0.875,2.5) -> 132.5 | M14: 1 | N14: 4 мин
C15: 7 подход | D15: =CEILING(D6*0.925,2.5) -> 90 | E15: 1 | F15: 5 мин | K15: 7 подход | L15: =CEILING(L6*0.925,2.5) -> 140 | M15: 1 | N15: 5 мин
C16: 8 подход | D16: =FLOOR(D6*0.975,2.5) -> 92.5 | E16: 1 | F16: 5 мин | K16: 8 подход | L16: =FLOOR(L6*0.975,2.5) -> 145 | M16: 1 | N16: 5 мин
C17: 9 подход | D17: =CEILING(D6*1,2.5) -> 95 | E17: 1 | F17: 6 мин | K17: 9 подход | L17: =CEILING(L6*1,2.5) -> 150 | M17: 1 | N17: 6 мин
C21: ПРОХОДКА (ВЫХОД НА 1ПМ) В ЖИМЕ ЛЁЖА ДЛЯ ЖИМА 100-150 кг | K21: ПРОХОДКА (ВЫХОД НА 1ПМ) В СТАНОВОЙ ТЯГЕ 200-250 КГ
C23: Ваш ПМ: | D23: 140 | K23: Ваш ПМ: | L23: 220
D25: Вес | E25: Повт | F25: Время отдыха | L25: Вес | M25: Повт | N25: Время отдыха
C26: 1 подход | D26: 20 | E26: 10 | F26: 1 мин | K26: 1 подход | L26: 70 | M26: 10 | N26: 1-2 мин
C27: 2 подход | D27: =CEILING(D23*0.4,5) -> 60 | E27: 6 | F27: 1 мин | K27: 2 подход | L27: =CEILING(L23*0.4,5) -> 90 | M27: 6 | N27: 1-2 мин
C28: 3 подход | D28: =CEILING(D23*0.55,5) -> 80 | E28: 4 | F28: 2 мин | K28: 3 подход | L28: =CEILING(L23*0.55,5) -> 125 | M28: 4 | N28: 2-3 мин
C29: 4 подход | D29: =CEILING(D23*0.7,5) -> 100 | E29: 2 | F29: 2 мин | K29: 4 подход | L29: =CEILING(L23*0.7,5) -> 155 | M29: 2 | N29: 2-3 мин
C30: 5 подход | D30: =CEILING(D23*0.775,2.5) -> 110 | E30: 1 | F30: 3 мин | K30: 5 подход | L30: =CEILING(L23*0.775,2.5) -> 172.5 | M30: 1 | N30: 3 мин
C31: 6 подход | D31: =CEILING(D23*0.825,2.5) -> 117.5 | E31: 1 | F31: 4 мин | K31: 6 подход | L31: =CEILING(L23*0.825,2.5) -> 182.5 | M31: 1 | N31: 4 мин
C32: 7 подход | D32: =CEILING(D23*0.875,2.5) -> 122.5 | E32: 1 | F32: 5 мин | K32: 7 подход | L32: =CEILING(L23*0.875,2.5) -> 192.5 | M32: 1 | N32: 5 мин
C33: 8 подход | D33: =FLOOR(D23*0.925,2.5) -> 127.5 | E33: 1 | F33: 5 мин | K33: 8 подход | L33: =FLOOR(L23*0.925,2.5) -> 202.5 | M33: 1 | N33: 5 мин
C34: 9 подход | D34: =CEILING(D23*0.95,2.5) -> 135 | E34: 1 | F34: 6 мин | K34: 9 подход | L34: =CEILING(L23*0.95,2.5) -> 210 | M34: 1 | N34: 6 мин
C35: 10 подход | D35: =CEILING(D23*1,2.5) -> 140 | E35: 1 | F35: 6 мин | K35: 10 подход | L35: =CEILING(L23*1,2.5) -> 220 | M35: 1 | N35: 6 мин
C40: ПРОХОДКА (ВЫХОД НА 1ПМ) В ЖИМЕ ЛЁЖА ДЛЯ ЖИМА БОЛЕЕ 150 КГ | K40: ПРОХОДКА (ВЫХОД НА 1ПМ) В СТАНОВОЙ СВЫШЕ 300 КГ
C42: Ваш ПМ: | D42: 150 | K42: Ваш ПМ: | L42: 310
D44: Вес | E44: Повт | F44: Время отдыха | L44: Вес | M44: Повт | N44: Время отдыха
C45: 1 подход | D45: 20 | E45: 10 | F45: 1 мин | K45: 1 подход | L45: 20 | M45: 10 | N45: 1-2 мин
C46: 2 подход | D46: =CEILING(D42*0.4,5) -> 60 | E46: 6 | F46: 1 мин | K46: 2 подход | L46: =CEILING(L42*0.4,5) -> 125 | M46: 6 | N46: 1-2 мин
C47: 3 подход | D47: =CEILING(D42*0.55,5) -> 85 | E47: 4 | F47: 2 мин | K47: 3 подход | L47: =CEILING(L42*0.55,5) -> 175 | M47: 4 | N47: 2-3 мин
C48: 4 подход | D48: =CEILING(D42*0.65,5) -> 100 | E48: 3 | F48: 2 мин | K48: 4 подход | L48: =CEILING(L42*0.65,5) -> 205 | M48: 3 | N48: 2-3 мин
C49: 5 подход | D49: =CEILING(D42*0.75,2.5) -> 112.5 | E49: 2 | F49: 3 мин | K49: 5 подход | L49: =CEILING(L42*0.75,2.5) -> 232.5 | M49: 2 | N49: 3 мин
C50: 6 подход | D50: =CEILING(D42*0.8,2.5) -> 120 | E50: 1 | F50: 4 мин | K50: 6 подход | L50: =CEILING(L42*0.8,2.5) -> 250 | M50: 1 | N50: 4 мин
C51: 7 подход | D51: =CEILING(D42*0.85,2.5) -> 127.5 | E51: 1 | F51: 5 мин | K51: 7 подход | L51: =CEILING(L42*0.85,2.5) -> 265 | M51: 1 | N51: 5 мин
C52: 8 подход | D52: =FLOOR(D42*0.9,2.5) -> 135 | E52: 1 | F52: 5 мин | K52: 8 подход | L52: =FLOOR(L42*0.9,2.5) -> 277.5 | M52: 1 | N52: 5 мин
C53: 9 подход | D53: =CEILING(D42*0.925,2.5) -> 140 | E53: 1 | F53: 6 мин | K53: 9 подход | L53: =CEILING(L42*0.925,2.5) -> 287.5 | M53: 1 | N53: 6 мин
C54: 10 подход | D54: =CEILING(D42*0.95,2.5) -> 142.5 | E54: 1 | F54: 6 мин | K54: 10 подход | L54: =CEILING(L42*0.95,2.5) -> 295 | M54: 1 | N54: 6 мин
C55: 11 подход | D55: =CEILING(D42*0.975,2.5) -> 147.5 | E55: 1 | F55: 6 мин | K55: 11 подход | L55: =CEILING(L42*0.975,2.5) -> 302.5 | M55: 1 | N55: 6 мин
C56: 12 подход | D56: =CEILING(D42*1,2.5) -> 150 | E56: 1 | F56: 6 мин | K56: 12 подход | L56: =CEILING(L42*1,2.5) -> 310 | M56: 1 | N56: 6 мин

Sheet Формулы
M3: 100
N7: Введите свой 4-7ПМ в ячейки: | Q7: Неделя 1 | U7: Неделя 2 | Y7: Неделя 3 | AC7: Неделя 4 (разгруз) | AE7: Неделя 5 | AI7: Неделя 6 | AM7: Неделя 7 (Разгрузка)
N8: вес (кг) ↓ | O8: ПМ (повт до отказа)↓ | P8: Округл ↓: | Q8: Вес | R8: Подх x повт | S8: Вес | T8: Подх x повт | U8: Вес | V8: Подх x повт | W8: Вес | X8: Подх x повт | Y8: Вес | Z8: Подх x повт | AA8: Вес | AB8: Подх x повт | AE8: Вес | AF8: Подх x повт | AG8: Вес | AH8: Подх x повт | AI8: Вес | AJ8: Подх x повт | AK8: Вес | AL8: Повт | AM8: Вес | AN8: Подх x повт | AO8: Вес | AP8: Подх x повт
L9: Жим штанги лёжа | N9: ='Программа тренировок '!C116 -> 0 | O9: ='Программа тренировок '!D116 -> 0 | P9: ='Программа тренировок '!E116 -> 0 | Q9: =CEILING(N9*0.85,P9)&" кг" -> 0 кг | R9: 1х1 | S9: =CEILING(N9*0.8,P9)&" кг" -> 0 кг | T9: 5х3 | U9: =CEILING(N9*0.925,P9)&" кг" -> 0 кг | V9: 1х1 | W9: =CEILING(N9*0.875,P9)&" кг" -> 0 кг | X9: 4x2 | Y9: =CEILING(N9*0.95,P9)&" кг" -> 0 кг | Z9: 4х1 | AA9: =CEILING(N9*0.9,P9)&" кг" -> 0 кг | AB9: ='Программа тренировок '!N154 -> 0 | AC9: =CEILING((100*(CEILING(N9*0.9,P9)))/(101.3-2.67123*(AB9+1))*0.65,P9)&" кг" -> 0 кг | AD9: 4х4 | AE9: =CEILING((100*(CEILING(N9*0.9,P9)))/(101.3-2.67123*(AB9+1))*0.875,P9)&" кг" -> 0 кг | AF9: 1х1 | AG9: =CEILING((100*(CEILING(N9*0.9,P9)))/(101.3-2.67123*(AB9+1))*0.825,P9)&" кг" -> 0 кг | AH9: 4х3 | AI9: =CEILING((100*(CEILING(N9*0.9,P9)))/(101.3-2.67123*(AB9+1))*0.925,P9)&" кг" -> 0 кг | AJ9: 1х1 | AK9: =CEILING((100*(CEILING(N9*0.9,P9)))/(101.3-2.67123*(AB9+1))*0.875,P9)&" кг" -> 0 кг | AL9: 4х2 | AM9: =CEILING((100*(CEILING(N9*0.9,P9)))/(101.3-2.67123*(AB9))*0.975,P9)&" (±5) кг (≈100%ПМ)" -> 0 (±5) кг (≈100%ПМ) | AN9: 1х1 | AO9: =CEILING((100*(CEILING(N9*0.9,P9)))/(101.3-2.67123*(AB9))*0.9,P9)&" кг" -> 0 кг
L10: Отжимания на брусьях (с доп весом) | N10: ='Программа тренировок '!C116 -> 0 | O10: ='Программа тренировок '!D116 -> 0 | P10: ='Программа тренировок '!E116 -> 0 | Q10: =CEILING(N10*0.85,P10)&" кг" -> 0 кг | R10: 1х1 | S10: =CEILING(N10*0.8,P10)&" кг" -> 0 кг | T10: 5х3 | U10: =CEILING(N10*0.925,P10)&" кг" -> 0 кг | V10: 1х1 | W10: =CEILING(N10*0.875,P10)&" кг" -> 0 кг | X10: 4x2 | Y10: =CEILING(N10*0.95,P10)&" кг" -> 0 кг | Z10: 4х1 | AA10: =CEILING(N10*0.9,P10)&" кг" -> 0 кг | AB10: ='Программа тренировок '!N154 -> 0 | AC10: =CEILING((100*(CEILING(N10*0.9,P10)))/(101.3-2.67123*(AB10+1))*0.65,P10)&" кг" -> 0 кг | AD10: 4х4 | AE10: =CEILING((100*(CEILING(N10*0.9,P10)))/(101.3-2.67123*(AB10+1))*0.875,P10)&" кг" -> 0 кг | AF10: 1х1 | AG10: =CEILING((100*(CEILING(N10*0.9,P10)))/(101.3-2.67123*(AB10+1))*0.825,P10)&" кг" -> 0 кг | AH10: 4х3 | AI10: =CEILING((100*(CEILING(N10*0.9,P10)))/(101.3-2.67123*(AB10+1))*0.925,P10)&" кг" -> 0 кг | AJ10: 1х1 | AK10: =CEILING((100*(CEILING(N10*0.9,P10)))/(101.3-2.67123*(AB10+1))*0.875,P10)&" кг" -> 0 кг | AL10: 4х2 | AM10: =CEILING((100*(CEILING(N10*0.9,P10)))/(101.3-2.67123*(AB10))*0.975,P10)&" (±5) кг (≈100%ПМ)" -> 0 (±5) кг (≈100%ПМ) | AN10: 1х1 | AO10: =CEILING((100*(CEILING(N10*0.9,P10)))/(101.3-2.67123*(AB10))*0.9,P10)&" кг" -> 0 кг
L11: Жим штанги лёжа на наклонной скамье | N11: ='Программа тренировок '!C116 -> 0 | O11: ='Программа тренировок '!D116 -> 0 | P11: ='Программа тренировок '!E116 -> 0 | Q11: =CEILING(N11*VLOOKUP(O11, Коэффициенты!N3:O11, 2,FALSE)*0.8,P11)&" кг" -> #N/A | R11: 1х2 | S11: =CEILING(N11*VLOOKUP(O11, Коэффициенты!N3:O11, 2,FALSE)*0.75,P11)&" кг" -> #N/A | T11: 4х4 | U11: =CEILING(N11*VLOOKUP(O11, Коэффициенты!N3:O11, 2,FALSE)*0.85,P11)&" кг" -> #N/A | V11: 1х2 | W11: =CEILING(N11*VLOOKUP(O11, Коэффициенты!N3:O11, 2,FALSE)*0.8,P11)&" кг" -> #N/A | X11: 4х3 | Y11: =CEILING(N11*VLOOKUP(O11, Коэффициенты!N3:O11, 2,FALSE)*0.9,P11)&" кг" -> #N/A | Z11: 4х1 | AA11: =CEILING((N11*VLOOKUP(O11, Коэффициенты!N3:O11, 2,FALSE))*0.85,P11)&" кг" -> #N/A | AB11: ='Программа тренировок '!N154 -> 0 | AC11: =CEILING((100*(CEILING(N11*0.85,P11)))/(101.3-2.67123*(AB11+1))*0.65,P11)&" кг" -> 0 кг | AD11: 4х4 | AE11: =CEILING((100*(CEILING(N11*0.85,P11)))/(101.3-2.67123*(AB11+1))*0.825,P11)&" кг" -> 0 кг | AF11: 1х2 | AG11: =CEILING((100*(CEILING(N11*0.85,P11)))/(101.3-2.67123*(AB11+1))*0.775,P11)&" кг" -> 0 кг | AH11: 4х4 | AI11: =CEILING((100*(CEILING(N11*0.85,P11)))/(101.3-2.67123*(AB11+1))*0.875,P11)&" кг" -> 0 кг | AJ11: 1х2 | AK11: =CEILING((100*(CEILING(N11*0.85,P11)))/(101.3-2.67123*(AB11+1))*0.825,P11)&" кг" -> 0 кг | AL11: 4х3 | AM11: =CEILING((100*(CEILING(N11*0.85,P11)))/(101.3-2.67123*(AB11))*0.95,P11)&" кг (≈95%ПМ)" -> 0 кг (≈95%ПМ) | AN11: 3х1 | AO11: =CEILING((100*(CEILING(N11*0.85,P11)))/(101.3-2.67123*(AB11))*0.875,P11)&" кг" -> 0 кг
L13: Подтягивания (с отягощением) | N13: ='Программа тренировок '!C117 -> 0 | O13: ='Программа тренировок '!D117 -> 0 | P13: ='Программа тренировок '!E117 -> 0 | Q13: =CEILING(N13*0.85,P13)&" кг" -> 0 кг | R13: 1х1 | S13: =CEILING(N13*0.8,P13)&" кг" -> 0 кг | T13: 5х3 | U13: =CEILING(N13*0.925,P13)&" кг" -> 0 кг | V13: 1х1 | W13: =CEILING(N13*0.875,P13)&" кг" -> 0 кг | X13: 4x2 | Y13: =CEILING(N13*0.95,P13)&" кг" -> 0 кг | Z13: 4х1 | AA13: =CEILING(N13*0.9,P13)&" кг" -> 0 кг | AB13: ='Программа тренировок '!N155 -> 0 | AC13: =CEILING((100*(CEILING(N13*0.9,P13)))/(101.3-2.67123*(AB13+1))*0.65,P13)&" кг" -> 0 кг | AD13: 4х4 | AE13: =CEILING((100*(CEILING(N13*0.9,P13)))/(101.3-2.67123*(AB13+1))*0.875,P13)&" кг" -> 0 кг | AF13: 1х1 | AG13: =CEILING((100*(CEILING(N13*0.9,P13)))/(101.3-2.67123*(AB13+1))*0.825,P13)&" кг" -> 0 кг | AH13: 4х3 | AI13: =CEILING((100*(CEILING(N13*0.9,P13)))/(101.3-2.67123*(AB13+1))*0.925,P13)&" кг" -> 0 кг | AJ13: 1х1 | AK13: =CEILING((100*(CEILING(N13*0.9,P13)))/(101.3-2.67123*(AB13+1))*0.875,P13)&" кг" -> 0 кг | AL13: 4х2 | AM13: =CEILING((100*(CEILING(N13*0.9,P13)))/(101.3-2.67123*(AB13+1))*0.975,P13)&"(±5) кг (≈100%ПМ)" -> 0(±5) кг (≈100%ПМ) | AN13: 1х1 | AO13: =CEILING((100*(CEILING(N13*0.9,P13)))/(101.3-2.67123*(AB13+1))*0.9,P13)&" кг" -> 0 кг
L14: Подтягивания (собственный вес) | N14: ='Программа тренировок '!C117 -> 0 | O14: ='Программа тренировок '!D117 -> 0 | P14: ='Программа тренировок '!E117 -> 0 | Q14: 5 подходов | R14: =FLOOR(0.45*O14,1)&" повт" -> 0 повт | S14: 1 подход | T14: =FLOOR(0.7*O14,1)&" повт" -> 0 повт | U14: 4 подхода | V14: =FLOOR(0.6*O14,1)&" повт" -> 0 повт | W14: 1 подход | X14: =CEILING(0.75*O14,1)&" повт" -> 0 повт | Y14: 2 подхода | Z14: =CEILING(0.5*O14,1)&" повт" -> 0 повт | AA14: 1 подход | AB14: ='Программа тренировок '!N155 -> 0 | AC14: 4 подхода | AD14: =FLOOR(0.45*AB14,1)&" повт" -> 0 повт | AE14: 3 подхода | AF14: =FLOOR(0.5*AB14,1)&" повт" -> 0 повт | AG14: 2 подхода | AH14: =FLOOR(0.65*AB14,1)&" повт" -> 0 повт | AI14: 2 подхода | AJ14: =FLOOR(0.65*AB14,1)&" повт" -> 0 повт | AK14: 2 подхода | AL14: =FLOOR(0.75*AB14,1)&" повт" -> 0 повт | AM14: ="1 подход" -> 1 подход | AN14: до отказа
L15: Тяга вертикального блока | N15: ='Программа тренировок '!C117 -> 0 | O15: ='Программа тренировок '!D117 -> 0 | P15: ='Программа тренировок '!E117 -> 0 | Q15: =CEILING(N15*VLOOKUP(O15, Коэффициенты!N3:O11, 2,FALSE)*0.775,P15)&" кг" -> #N/A | R15: 1х3 | S15: =CEILING(N15*VLOOKUP(O15, Коэффициенты!N3:O11, 2,FALSE)*0.725,P15)&" кг" -> #N/A | T15: 4х5 | U15: =CEILING(N15*VLOOKUP(O15, Коэффициенты!N3:O11, 2,FALSE)*0.825,P15)&" кг" -> #N/A | V15: 1х2 | W15: =CEILING(N15*VLOOKUP(O15, Коэффициенты!N3:O11, 2,FALSE)*0.775,P15)&" кг" -> #N/A | X15: 4х4 | Y15: =CEILING(N15*VLOOKUP(O15, Коэффициенты!N3:O11, 2,FALSE)*0.85,P15)&" кг" -> #N/A | Z15: 3х2 | AA15: =CEILING(N15*VLOOKUP(O15, Коэффициенты!N3:O11, 2,FALSE)*0.8,P15)&" кг" -> #N/A | AB15: ='Программа тренировок '!N155 -> 0 | AC15: =CEILING((100*(CEILING(N15*0.9,P15)))/(101.3-2.67123*(AB15+1))*0.675,P15)&" кг" -> 0 кг | AD15: 4х4 | AE15: =CEILING((100*(CEILING(N15*0.9,P15)))/(101.3-2.67123*(AB15))*0.8,P15)&" кг" -> 0 кг | AF15: 1х3 | AG15: =CEILING((100*(CEILING(N15*0.9,P15)))/(101.3-2.67123*(AB15))*0.75,P15)&" кг" -> 0 кг | AH15: 4x4 | AI15: =CEILING((100*(CEILING(N15*0.9,P15)))/(101.3-2.67123*(AB15))*0.85,P15)&" кг" -> 0 кг | AJ15: 1х2 | AK15: =CEILING((100*(CEILING(N15*0.9,P15)))/(101.3-2.67123*(AB15))*0.8,P15)&" кг" -> 0 кг | AL15: 4х3 | AM15: =CEILING((100*(CEILING(N15*0.9,P15)))/(101.3-2.67123*(AB15))*0.9,P15)&" кг (≈90%ПМ)" -> 0 кг (≈90%ПМ) | AN15: 3х1 | AO15: =CEILING((100*(CEILING(N15*0.9,P15)))/(101.3-2.67123*(AB15))*0.825,P15)&" кг" -> 0 кг
L17: Приседания со штангой | N17: =IF('Программа тренировок '!B132='Программа тренировок '!B118,'Программа тренировок '!C118,'Программа тренировок '!C132) -> 0 | O17: =IF('Программа тренировок '!B132='Программа тренировок '!B118,O54,'Программа тренировок '!D132) -> 0 | P17: =IF('Программа тренировок '!B132='Программа тренировок '!B118,P54,'Программа тренировок '!E132) -> 0 | Q17: =CEILING(N17*0.85,P17)&" кг" -> 0 кг | R17: 1х1 | S17: =CEILING(N17*0.8,P17)&" кг" -> 0 кг | T17: 4х3 | U17: =CEILING(N17*0.925,P17)&" кг" -> 0 кг | V17: 1х1 | W17: =CEILING(N17*0.875,P17)&" кг" -> 0 кг | X17: 4x2 | Y17: =CEILING(N17*0.95,P17)&" кг" -> 0 кг | Z17: 4х1 | AA17: =CEILING(N17*0.9,P17)&" кг" -> 0 кг | AB17: ='Программа тренировок '!N170 -> 0 | AC17: =CEILING((100*(CEILING(N17*0.9,P17)))/(101.3-2.67123*(AB17+1))*0.65,P17)&" кг" -> 0 кг | AD17: 4х4 | AE17: =CEILING((100*(CEILING(N17*0.9,P17)))/(101.3-2.67123*(AB17+1))*0.85,P17)&" кг" -> 0 кг | AF17: 1х1 | AG17: =CEILING((100*(CEILING(N17*0.9,P17)))/(101.3-2.67123*(AB17+1))*0.8,P17)&" кг" -> 0 кг | AH17: 4х3 | AI17: =CEILING((100*(CEILING(N17*0.9,P17)))/(101.3-2.67123*(AB17+1))*0.925,P17)&" кг" -> 0 кг | AJ17: 1х1 | AK17: =CEILING((100*(CEILING(N17*0.9,P17)))/(101.3-2.67123*(AB17+1))*0.875,P17)&" кг" -> 0 кг | AL17: 4х2 | AM17: =CEILING((100*(CEILING(N17*0.9,P17)))/(101.3-2.67123*(AB17+1))*0.975,P17)&" (±5) кг (≈100%ПМ)" -> 0 (±5) кг (≈100%ПМ) | AN17: 1х1 | AO17: =CEILING((100*(CEILING(N17*0.9,P17)))/(101.3-2.67123*(AB17+1))*0.9,P17)&" кг" -> 0 кг
L18: Приседания в колодец | N18: ='Программа тренировок '!C132 -> 0 | O18: ='Программа тренировок '!D132 -> 0 | P18: ='Программа тренировок '!E132 -> 0 | Q18: =CEILING(N18*0.85,P18)&" кг" -> 0 кг | R18: 1х1 | S18: =CEILING(N18*0.8,P18)&" кг" -> 0 кг | T18: 4х3 | U18: =CEILING(N18*0.925,P18)&" кг" -> 0 кг | V18: 1х1 | W18: =CEILING(N18*0.875,P18)&" кг" -> 0 кг | X18: 4x2 | Y18: =CEILING(N18*0.95,P18)&" кг" -> 0 кг | Z18: 4х1 | AA18: =CEILING(N18*0.9,P18)&" кг" -> 0 кг | AB18: ='Программа тренировок '!N170 -> 0 | AC18: =CEILING((100*(CEILING(N18*0.9,P18)))/(101.3-2.67123*(AB18+1))*0.65,P18)&" кг" -> 0 кг | AD18: 4х4 | AE18: =CEILING((100*(CEILING(N18*0.9,P18)))/(101.3-2.67123*(AB18+1))*0.85,P18)&" кг" -> 0 кг | AF18: 1х1 | AG18: =CEILING((100*(CEILING(N18*0.9,P18)))/(101.3-2.67123*(AB18+1))*0.8,P18)&" кг" -> 0 кг | AH18: 4х3 | AI18: =CEILING((100*(CEILING(N18*0.9,P18)))/(101.3-2.67123*(AB18+1))*0.925,P18)&" кг" -> 0 кг | AJ18: 1х1 | AK18: =CEILING((100*(CEILING(N18*0.9,P18)))/(101.3-2.67123*(AB18+1))*0.875,P18)&" кг" -> 0 кг | AL18: 4х2 | AM18: =CEILING((100*(CEILING(N18*0.9,P18)))/(101.3-2.67123*(AB18+1))*0.975,P18)&" (±5) кг (≈100%ПМ)" -> 0 (±5) кг (≈100%ПМ) | AN18: 1х1 | AO18: =CEILING((100*(CEILING(N18*0.9,P18)))/(101.3-2.67123*(AB18+1))*0.9,P18)&" кг" -> 0 кг
L19: Ягодичный мост | N19: =IF('Программа тренировок '!B124='Программа тренировок '!B132,'Программа тренировок '!C124,'Программа тренировок '!C132) -> 0 | O19: =IF('Программа тренировок '!B124='Программа тренировок '!B132,'Программа тренировок '!D124,'Программа тренировок '!D132) -> 0 | P19: =IF('Программа тренировок '!B124='Программа тренировок '!B132,'Программа тренировок '!E124,'Программа тренировок '!E132) -> 0 | Q19: =CEILING(N19*VLOOKUP(O19, Коэффициенты!N3:O11, 2,FALSE)*0.7,P19)&" кг" -> #N/A | R19: 1х3 | S19: =CEILING(N19*VLOOKUP(O19, Коэффициенты!N3:O11, 2,FALSE)*0.65,P19)&" кг" -> #N/A | T19: 3х4 | U19: =CEILING(N19*VLOOKUP(O19, Коэффициенты!N3:O11, 2,FALSE)*0.75,P19)&" кг" -> #N/A | V19: 1х2 | W19: =CEILING(N19*VLOOKUP(O19, Коэффициенты!N3:O11, 2,FALSE)*0.7,P19)&" кг" -> #N/A | X19: 3х3 | Y19: =CEILING(N19*VLOOKUP(O19, Коэффициенты!N3:O11, 2,FALSE)*0.75,P19)&" кг" -> #N/A | Z19: 3х2 | AC19: =CEILING(N19*VLOOKUP(O19, Коэффициенты!N3:O11, 2,FALSE)*0.65,P19)&" кг" -> #N/A | AD19: 4х4 | AE19: =CEILING(N19*VLOOKUP(O19, Коэффициенты!N3:O11, 2,FALSE)*0.725,P19)&" кг" -> #N/A | AF19: 1х3 | AG19: =CEILING(N19*VLOOKUP(O19, Коэффициенты!N3:O11, 2,FALSE)*0.675,P19)&" кг" -> #N/A | AH19: 3x4 | AI19: =CEILING(N19*VLOOKUP(O19, Коэффициенты!N3:O11, 2,FALSE)*0.775,P19)&" кг" -> #N/A | AJ19: 1х2 | AK19: =CEILING(N19*VLOOKUP(O19, Коэффициенты!N3:O11, 2,FALSE)*0.725,P19)&" кг" -> #N/A | AL19: 3х3 | AM19: =CEILING(N19*VLOOKUP(O19, Коэффициенты!N3:O11, 2,FALSE)*0.775,P19)&" кг" -> #N/A | AN19: 3х2
L21: Махи с гантелями в стороны | N21: ='Программа тренировок '!C119 -> 0 | O21: ='Программа тренировок '!D119 -> 0 | P21: ='Программа тренировок '!E119 -> 0 | Q21: =CEILING(N21*VLOOKUP(O21, Коэффициенты!N3:O11, 2,FALSE)*0.6,P21)&" кг" -> #N/A | R21: 3х12 | U21: =CEILING(N21*VLOOKUP(O21, Коэффициенты!N3:O11, 2,FALSE)*0.7,P21)&" кг" -> #N/A | V21: 3х10 | W21: =CEILING(N21*VLOOKUP(O21, Коэффициенты!N3:O11, 2,FALSE)*0.65,P21)&" кг" -> #N/A | X21: RIR-1 | Y21: =CEILING(N21*VLOOKUP(O21, Коэффициенты!N3:O11, 2,FALSE)*0.85,P21)&" кг" -> #N/A | Z21: 1х3 | AA21: =CEILING((N21*VLOOKUP(O21, Коэффициенты!N3:O11, 2,FALSE))*0.8,P21)&" кг" -> #N/A | AB21: ='Программа тренировок '!N157 -> 0 | AE21: =CEILING((100*(CEILING(N21*0.8,P21)))/(101.3-2.67123*(AB21+1))*0.65,P21)&" кг" -> 0 кг | AF21: 3х10 | AI21: =CEILING((100*(CEILING(N21*0.8,P21)))/(101.3-2.67123*(AB21+1))*0.75,P21)&" кг" -> 0 кг | AJ21: 3х8 | AK21: =CEILING(N21*VLOOKUP(O21, Коэффициенты!N3:O11, 2,FALSE)*0.7,P21)&" кг" -> #N/A | AL21: RIR-1 | AM21: =CEILING((100*(CEILING(N21*0.8,P21)))/(101.3-2.67123*(AB21+1))*0.85,P21)&" кг" -> 0 кг | AN21: 1х4 | AO21: =CEILING((100*(CEILING(N21*0.85,P21)))/(101.3-2.67123*(AB21))*0.8,P21)&" кг" -> 0 кг
L22: Тяга к подбородку | N22: ='Программа тренировок '!C119 -> 0 | O22: ='Программа тренировок '!D119 -> 0 | P22: ='Программа тренировок '!E119 -> 0 | Q22: =CEILING(N22*VLOOKUP(O22, Коэффициенты!N3:O11, 2,FALSE)*0.8,P22)&" кг" -> #N/A | R22: 1х2 | S22: =CEILING(N22*VLOOKUP(O22, Коэффициенты!N3:O11, 2,FALSE)*0.7,P22)&" кг" -> #N/A | T22: 3х5 | U22: =CEILING(N22*VLOOKUP(O22, Коэффициенты!N3:O11, 2,FALSE)*0.85,P22)&" кг" -> #N/A | V22: 1х2 | W22: =CEILING(N22*VLOOKUP(O22, Коэффициенты!N3:O11, 2,FALSE)*0.75,P22)&" кг" -> #N/A | X22: 3х4 | Y22: =CEILING(N22*VLOOKUP(O22, Коэффициенты!N3:O11, 2,FALSE)*0.9,P22)&" кг" -> #N/A | Z22: 4х1 | AA22: =CEILING((N22*VLOOKUP(O22, Коэффициенты!N3:O11, 2,FALSE))*0.8,P22)&" кг" -> #N/A | AB22: ='Программа тренировок '!N157 -> 0 | AC22: =CEILING((100*(CEILING(N22*0.8,P22)))/(101.3-2.67123*(AB22+1))*0.65,P22)&" кг" -> 0 кг | AD22: 3х4 | AE22: =CEILING((100*(CEILING(N22*0.8,P22)))/(101.3-2.67123*(AB22+1))*0.825,P22)&" кг" -> 0 кг | AF22: 1х2 | AG22: =CEILING((100*(CEILING(N22*0.8,P22)))/(101.3-2.67123*(AB22+1))*0.725,P22)&" кг" -> 0 кг | AH22: 3х5 | AI22: =CEILING((100*(CEILING(N22*0.8,P22)))/(101.3-2.67123*(AB22+1))*0.85,P22)&" кг" -> 0 кг | AJ22: 1х2 | AK22: =CEILING((100*(CEILING(N22*0.8,P22)))/(101.3-2.67123*(AB22+1))*0.75,P22)&" кг" -> 0 кг | AL22: 4х3 | AM22: =CEILING((100*(CEILING(N22*0.8,P22)))/(101.3-2.67123*(AB22+1))*0.9,P22)&" кг" -> 0 кг | AN22: 1х2 | AO22: =CEILING((100*(CEILING(N22*0.8,P22)))/(101.3-2.67123*(AB22+1))*0.8,P22)&" кг" -> 0 кг
L24: Становая тяга | N24: ='Программа тренировок '!C124 -> 0 | O24: ='Программа тренировок '!D124 -> 0 | P24: ='Программа тренировок '!E124 -> 0 | Q24: =CEILING(N24*0.85,P24)&" кг" -> 0 кг | R24: 1х1 | S24: =CEILING(N24*0.8,P24)&" кг" -> 0 кг | T24: 4х3 | U24: =CEILING(N24*0.925,P24)&" кг" -> 0 кг | V24: 1х1 | W24: =CEILING(N24*0.875,P24)&" кг" -> 0 кг | X24: 4x2 | Y24: =CEILING(N24*0.95,P24)&" кг" -> 0 кг | Z24: 4х1 | AA24: =CEILING(N24*0.9,P24)&" кг" -> 0 кг | AB24: ='Программа тренировок '!N162 -> 0 | AC24: =CEILING((100*(CEILING(N24*0.9,P24)))/(101.3-2.67123*(AB24+1))*0.65,P24)&" кг" -> 0 кг | AD24: 4х4 | AE24: =CEILING((100*(CEILING(N24*0.9,P24)))/(101.3-2.67123*(AB24+1))*0.85,P24)&" кг" -> 0 кг | AF24: 1х1 | AG24: =CEILING((100*(CEILING(N24*0.9,P24)))/(101.3-2.67123*(AB24+1))*0.8,P24)&" кг" -> 0 кг | AH24: 4х3 | AI24: =CEILING((100*(CEILING(N24*0.9,P24)))/(101.3-2.67123*(AB24+1))*0.925,P24)&" кг" -> 0 кг | AJ24: 1х1 | AK24: =CEILING((100*(CEILING(N24*0.9,P24)))/(101.3-2.67123*(AB24+1))*0.875,P24)&" кг" -> 0 кг | AL24: 4х2 | AM24: =CEILING((100*(CEILING(N24*0.9,P24)))/(101.3-2.67123*(AB24+1))*0.975,P24)&" (±5) кг (≈100%ПМ)" -> 0 (±5) кг (≈100%ПМ) | AN24: 1х1 | AO24: =CEILING((100*(CEILING(N24*0.9,P24)))/(101.3-2.67123*(AB24+1))*0.9,P24)&" кг" -> 0 кг
L25: Мёртвая тяга | N25: ='Программа тренировок '!C124 -> 0 | O25: ='Программа тренировок '!D124 -> 0 | P25: ='Программа тренировок '!E124 -> 0 | Q25: =CEILING(N25*VLOOKUP(O25, Коэффициенты!N3:O11, 2,FALSE)*0.8,P25)&" кг" -> #N/A | R25: 1х2 | S25: =CEILING(N25*VLOOKUP(O25, Коэффициенты!N3:O11, 2,FALSE)*0.75,P25)&" кг" -> #N/A | T25: 5х4 | U25: =CEILING(N25*VLOOKUP(O25, Коэффициенты!N3:O11, 2,FALSE)*0.85,P25)&" кг" -> #N/A | V25: 1х2 | W25: =CEILING(N25*VLOOKUP(O25, Коэффициенты!N3:O11, 2,FALSE)*0.8,P25)&" кг" -> #N/A | X25: 4х3 | Y25: =CEILING(N25*VLOOKUP(O25, Коэффициенты!N3:O11, 2,FALSE)*0.9,P25)&" кг" -> #N/A | Z25: 4х1 | AA25: =CEILING((N25*VLOOKUP(O25, Коэффициенты!N3:O11, 2,FALSE))*0.85,P25)&" кг" -> #N/A | AB25: ='Программа тренировок '!N162 -> 0 | AC25: =CEILING((100*(CEILING(N25*0.85,P25)))/(101.3-2.67123*(AB25+1))*0.65,P25)&" кг" -> 0 кг | AD25: 4х4 | AE25: =CEILING((100*(CEILING(N25*0.85,P25)))/(101.3-2.67123*(AB25+1))*0.825,P25)&" кг" -> 0 кг | AF25: 1х2 | AG25: =CEILING((100*(CEILING(N25*0.85,P25)))/(101.3-2.67123*(AB25+1))*0.775,P25)&" кг" -> 0 кг | AH25: 4х4 | AI25: =CEILING((100*(CEILING(N25*0.85,P25)))/(101.3-2.67123*(AB25+1))*0.875,P25)&" кг" -> 0 кг | AJ25: 1х2 | AK25: =CEILING((100*(CEILING(N25*0.85,P25)))/(101.3-2.67123*(AB25+1))*0.825,P25)&" кг" -> 0 кг | AL25: 4х3 | AM25: =CEILING((100*(CEILING(N25*0.85,P25)))/(101.3-2.67123*(AB25))*0.95,P25)&" кг (≈95%ПМ)" -> 0 кг (≈95%ПМ) | AN25: 3х1 | AO25: =CEILING((100*(CEILING(N25*0.85,P25)))/(101.3-2.67123*(AB25))*0.875,P25)&" кг" -> 0 кг
L26: Ягодичный мост | N26: ='Программа тренировок '!C124 -> 0 | O26: ='Программа тренировок '!D124 -> 0 | P26: ='Программа тренировок '!E124 -> 0 | Q26: =CEILING(N26*0.85,P26)&" кг" -> 0 кг | R26: 1х1 | S26: =CEILING(N26*0.8,P26)&" кг" -> 0 кг | T26: 4х3 | U26: =CEILING(N26*0.925,P26)&" кг" -> 0 кг | V26: 1х1 | W26: =CEILING(N26*0.875,P26)&" кг" -> 0 кг | X26: 4x2 | Y26: =CEILING(N26*0.95,P26)&" кг" -> 0 кг | Z26: 4х1 | AA26: =CEILING(N26*0.9,P26)&" кг" -> 0 кг | AB26: ='Программа тренировок '!N162 -> 0 | AC26: =CEILING((100*(CEILING(N26*0.9,P26)))/(101.3-2.67123*(AB26+1))*0.65,P26)&" кг" -> 0 кг | AD26: 4х4 | AE26: =CEILING((100*(CEILING(N26*0.9,P26)))/(101.3-2.67123*(AB26+1))*0.85,P26)&" кг" -> 0 кг | AF26: 1х1 | AG26: =CEILING((100*(CEILING(N26*0.9,P26)))/(101.3-2.67123*(AB26+1))*0.8,P26)&" кг" -> 0 кг | AH26: 4х3 | AI26: =CEILING((100*(CEILING(N26*0.9,P26)))/(101.3-2.67123*(AB26+1))*0.925,P26)&" кг" -> 0 кг | AJ26: 1х1 | AK26: =CEILING((100*(CEILING(N26*0.9,P26)))/(101.3-2.67123*(AB26+1))*0.875,P26)&" кг" -> 0 кг | AL26: 4х2 | AM26: =CEILING((100*(CEILING(N26*0.9,P26)))/(101.3-2.67123*(AB26+1))*0.975,P26)&" (±5) кг (≈100%ПМ)" -> 0 (±5) кг (≈100%ПМ) | AN26: 1х1 | AO26: =CEILING((100*(CEILING(N26*0.9,P26)))/(101.3-2.67123*(AB26+1))*0.9,P26)&" кг" -> 0 кг
L28: Жим штанги лёжа | N28: =IF('Программа тренировок '!B67='Программа тренировок '!B77, Формулы!N9, 'Программа тренировок '!C126) -> 0 | O28: =IF('Программа тренировок '!B67='Программа тренировок '!B77, Формулы!O9, 'Программа тренировок '!D126) -> 0 | P28: =IF('Программа тренировок '!B67='Программа тренировок '!B77, P9, 'Программа тренировок '!E126) -> 0 | Q28: =CEILING(N28*VLOOKUP(O28, Коэффициенты!N1:O9, 2,FALSE)*0.7,P28)&" кг" -> #N/A | R28: 1х2 | S28: =CEILING(N28*VLOOKUP(O28, Коэффициенты!N1:O9, 2,FALSE)*0.65,P28)&" кг" -> #N/A | T28: 3х5 | U28: =CEILING(N28*VLOOKUP(O28, Коэффициенты!N1:O9, 2,FALSE)*0.75,P28)&" кг" -> #N/A | V28: 1х2 | W28: =CEILING(N28*VLOOKUP(O28, Коэффициенты!N1:O9, 2,FALSE)*0.7,P28)&" кг" -> #N/A | X28: 3х4 | Y28: =CEILING(N28*VLOOKUP(O28, Коэффициенты!N1:O9, 2,FALSE)*0.8,P28)&" кг" -> #N/A | Z28: 3х3 | AC28: =CEILING(N28*VLOOKUP(O28, Коэффициенты!N1:O9, 2,FALSE)*0.65,P28)&" кг" -> #N/A | AD28: 4х4 | AE28: =CEILING(N28*VLOOKUP(O28, Коэффициенты!N1:O9, 2,FALSE)*0.725,P28)&" кг" -> #N/A | AF28: 1х2 | AG28: =CEILING(N28*VLOOKUP(O28, Коэффициенты!N1:O9, 2,FALSE)*0.675,P28)&" кг" -> #N/A | AH28: 3х5 | AI28: =CEILING(N28*VLOOKUP(O28, Коэффициенты!N1:O9, 2,FALSE)*0.775,P28)&" кг" -> #N/A | AJ28: 1х2 | AK28: =CEILING(N28*VLOOKUP(O28, Коэффициенты!N1:O9, 2,FALSE)*0.725,P28)&" кг" -> #N/A | AL28: 3х4 | AM28: =CEILING(N28*VLOOKUP(O28, Коэффициенты!N1:O9, 2,FALSE)*0.825,P28)&" кг" -> #N/A | AN28: 3х3
L29: Жим гантелей лёжа | N29: ='Программа тренировок '!C126 -> 0 | O29: ='Программа тренировок '!D126 -> 0 | P29: ='Программа тренировок '!E126 -> 0 | Q29: =CEILING(N29*VLOOKUP(O29, Коэффициенты!N3:O11, 2,FALSE)*0.775,P29)&" кг" -> #N/A | R29: 1х3 | S29: =CEILING(N29*VLOOKUP(O29, Коэффициенты!N3:O11, 2,FALSE)*0.725,P29)&" кг" -> #N/A | T29: 3х5 | U29: =CEILING(N29*VLOOKUP(O29, Коэффициенты!N3:O11, 2,FALSE)*0.825,P29)&" кг" -> #N/A | V29: 1х2 | W29: =CEILING(N29*VLOOKUP(O29, Коэффициенты!N3:O11, 2,FALSE)*0.775,P29)&" кг" -> #N/A | X29: 4х4 | Y29: =CEILING(N29*VLOOKUP(O29, Коэффициенты!N3:O11, 2,FALSE)*0.85,P29)&" кг" -> #N/A | Z29: 3х2 | AA29: =CEILING(N29*VLOOKUP(O29, Коэффициенты!N3:O11, 2,FALSE)*0.8,P29)&" кг" -> #N/A | AB29: ='Программа тренировок '!N164 -> 0 | AC29: =CEILING((100*(CEILING(N29*0.8,P29)))/(101.3-2.67123*(AB29+1))*0.65,P29)&" кг" -> 0 кг | AD29: 4х4 | AE29: =CEILING((100*(CEILING(N29*0.8,P29)))/(101.3-2.67123*(AB29))*0.8,P29)&" кг" -> 0 кг | AF29: 1х3 | AG29: =CEILING((100*(CEILING(N29*0.8,P29)))/(101.3-2.67123*(AB29))*0.75,P29)&" кг" -> 0 кг | AH29: 3x4 | AI29: =CEILING((100*(CEILING(N29*0.8,P29)))/(101.3-2.67123*(AB29))*0.85,P29)&" кг" -> 0 кг | AJ29: 1х2 | AK29: =CEILING((100*(CEILING(N29*0.8,P29)))/(101.3-2.67123*(AB29))*0.8,P29)&" кг" -> 0 кг | AL29: 3х3 | AM29: =CEILING((100*(CEILING(N29*0.8,P29)))/(101.3-2.67123*(AB29))*0.875,P29)&" кг" -> 0 кг | AN29: 1х2 | AO29: =CEILING((100*(CEILING(N29*0.8,P29)))/(101.3-2.67123*(AB29))*0.825,P29)&" кг" -> 0 кг
L30: Жим штанги лёжа на наклонной скамье | N30: =IF('Программа тренировок '!B67='Программа тренировок '!B77, Формулы!N9, 'Программа тренировок '!C126) -> 0 | O30: =IF('Программа тренировок '!B67='Программа тренировок '!B77, Формулы!O11, 'Программа тренировок '!D126) -> 0 | P30: =IF('Программа тренировок '!B67='Программа тренировок '!B77, P11, 'Программа тренировок '!E126) -> 0 | Q30: =CEILING(N30*VLOOKUP(O30, Коэффициенты!N3:O11, 2,FALSE)*0.7,P30)&" кг" -> #N/A | R30: 1х2 | S30: =CEILING(N30*VLOOKUP(O30, Коэффициенты!N3:O11, 2,FALSE)*0.65,P30)&" кг" -> #N/A | T30: 3х5 | U30: =CEILING(N30*VLOOKUP(O30, Коэффициенты!N3:O11, 2,FALSE)*0.75,P30)&" кг" -> #N/A | V30: 1х2 | W30: =CEILING(N30*VLOOKUP(O30, Коэффициенты!N3:O11, 2,FALSE)*0.7,P30)&" кг" -> #N/A | X30: 3х4 | Y30: =CEILING(N30*VLOOKUP(O30, Коэффициенты!N3:O11, 2,FALSE)*0.8,P30)&" кг" -> #N/A | Z30: 3х3 | AC30: =CEILING(N30*VLOOKUP(O30, Коэффициенты!N3:O11, 2,FALSE)*0.65,P30)&" кг" -> #N/A | AD30: 4х4 | AE30: =CEILING(N30*VLOOKUP(O30, Коэффициенты!N3:O11, 2,FALSE)*0.725,P30)&" кг" -> #N/A | AF30: 1х2 | AG30: =CEILING(N30*VLOOKUP(O30, Коэффициенты!N3:O11, 2,FALSE)*0.675,P30)&" кг" -> #N/A | AH30: 3х5 | AI30: =CEILING(N30*VLOOKUP(O30, Коэффициенты!N3:O11, 2,FALSE)*0.775,P30)&" кг" -> #N/A | AJ30: 1х2 | AK30: =CEILING(N30*VLOOKUP(O30, Коэффициенты!N3:O11, 2,FALSE)*0.725,P30)&" кг" -> #N/A | AL30: 3х4 | AM30: =CEILING(N30*VLOOKUP(O30, Коэффициенты!N3:O11, 2,FALSE)*0.825,P30)&" кг" -> #N/A | AN30: 3х3
L33: Подъём штанги на бицепс | N33: ='Программа тренировок '!C125 -> 0 | O33: ='Программа тренировок '!D125 -> 0 | P33: ='Программа тренировок '!E125 -> 0 | Q33: =CEILING(N33*0.85,P33)&" кг" -> 0 кг | R33: 1х1 | S33: =CEILING(N33*0.8,P33)&" кг" -> 0 кг | T33: 4х3 | U33: =CEILING(N33*0.925,P33)&" кг" -> 0 кг | V33: 1х1 | W33: =CEILING(N33*0.875,P33)&" кг" -> 0 кг | X33: 4x2 | Y33: =CEILING(N33*0.95,P33)&" кг" -> 0 кг | Z33: 4х1 | AA33: =CEILING(N33*0.9,P33)&" кг" -> 0 кг | AB33: ='Программа тренировок '!N160 -> 0 | AC33: =CEILING((100*(CEILING(N33*0.9,P33)))/(101.3-2.67123*(AB33+1))*0.65,P33)&" кг" -> 0 кг | AD33: 4х4 | AE33: =CEILING((100*(CEILING(N33*0.9,P33)))/(101.3-2.67123*(AB33+1))*0.875,P33)&" кг" -> 0 кг | AF33: 1х1 | AG33: =CEILING((100*(CEILING(N33*0.9,P33)))/(101.3-2.67123*(AB33+1))*0.825,P33)&" кг" -> 0 кг | AH33: 4х3 | AI33: =CEILING((100*(CEILING(N33*0.9,P33)))/(101.3-2.67123*(AB33+1))*0.925,P33)&" кг" -> 0 кг | AJ33: 1х1 | AK33: =CEILING((100*(CEILING(N33*0.9,P33)))/(101.3-2.67123*(AB33+1))*0.875,P33)&" кг" -> 0 кг | AL33: 4х2 | AM33: =CEILING((100*(CEILING(N33*0.9,P33)))/(101.3-2.67123*(AB33+1))*0.975,P33)&" (±5) кг (≈100%ПМ)" -> 0 (±5) кг (≈100%ПМ) | AN33: 1х1 | AO33: =CEILING((100*(CEILING(N33*0.9,P33)))/(101.3-2.67123*(AB33+1))*0.9,P33)&" кг" -> 0 кг
L34: Молот | N34: ='Программа тренировок '!C125 -> 0 | O34: ='Программа тренировок '!D125 -> 0 | P34: ='Программа тренировок '!E125 -> 0 | Q34: =CEILING(N34*VLOOKUP(O34, Коэффициенты!N3:O11, 2,FALSE)*0.775,P34)&" кг" -> #N/A | R34: 1х3 | S34: =CEILING(N34*VLOOKUP(O34, Коэффициенты!N3:O11, 2,FALSE)*0.725,P34)&" кг" -> #N/A | T34: 4х5 | U34: =CEILING(N34*VLOOKUP(O34, Коэффициенты!N3:O11, 2,FALSE)*0.825,P34)&" кг" -> #N/A | V34: 1х2 | W34: =CEILING(N34*VLOOKUP(O34, Коэффициенты!N3:O11, 2,FALSE)*0.775,P34)&" кг" -> #N/A | X34: 4х4 | Y34: =CEILING(N34*VLOOKUP(O34, Коэффициенты!N3:O11, 2,FALSE)*0.85,P34)&" кг" -> #N/A | Z34: 3х2 | AA34: =CEILING(N34*VLOOKUP(O34, Коэффициенты!N3:O11, 2,FALSE)*0.8,P34)&" кг" -> #N/A | AB34: ='Программа тренировок '!N160 -> 0 | AC34: =CEILING((100*(CEILING(N34*0.9,P34)))/(101.3-2.67123*(AB34+1))*0.675,P34)&" кг" -> 0 кг | AD34: 4х4 | AE34: =CEILING((100*(CEILING(N34*0.8,P34)))/(101.3-2.67123*(AB34))*0.8,P34)&" кг" -> 0 кг | AF34: 1х3 | AG34: =CEILING((100*(CEILING(N34*0.8,P34)))/(101.3-2.67123*(AB34))*0.75,P34)&" кг" -> 0 кг | AH34: 4x4 | AI34: =CEILING((100*(CEILING(N34*0.8,P34)))/(101.3-2.67123*(AB34))*0.85,P34)&" кг" -> 0 кг | AJ34: 1х2 | AK34: =CEILING((100*(CEILING(N34*0.8,P34)))/(101.3-2.67123*(AB34))*0.8,P34)&" кг" -> 0 кг | AL34: 4х3 | AM34: =CEILING((100*(CEILING(N34*0.8,P34)))/(101.3-2.67123*(AB34))*0.9,P34)&" кг (≈90%ПМ)" -> 0 кг (≈90%ПМ) | AN34: 3х1 | AO34: =CEILING((100*(CEILING(N34*0.8,P34)))/(101.3-2.67123*(AB34))*0.825,P34)&" кг" -> 0 кг
L36: Жим лёжа узким хватом | N36: ='Программа тренировок '!C127 -> 0 | O36: ='Программа тренировок '!D127 -> 0 | P36: ='Программа тренировок '!E127 -> 0 | Q36: =CEILING(N36*VLOOKUP(O36, Коэффициенты!N3:O11, 2,FALSE)*0.775,P36)&" кг" -> #N/A | R36: 1х2 | S36: =CEILING(N36*VLOOKUP(O36, Коэффициенты!N3:O11, 2,FALSE)*0.725,P36)&" кг" -> #N/A | T36: 4х5 | U36: =CEILING(N36*VLOOKUP(O36, Коэффициенты!N3:O11, 2,FALSE)*0.825,P36)&" кг" -> #N/A | V36: 1х2 | W36: =CEILING(N36*VLOOKUP(O36, Коэффициенты!N3:O11, 2,FALSE)*0.775,P36)&" кг" -> #N/A | X36: 4х4 | Y36: =CEILING(N36*VLOOKUP(O36, Коэффициенты!N3:O11, 2,FALSE)*0.85,P36)&" кг" -> #N/A | Z36: 3х2 | AA36: =CEILING(N36*VLOOKUP(O36, Коэффициенты!N3:O11, 2,FALSE)*0.8,P36)&" кг" -> #N/A | AB36: ='Программа тренировок '!N165 -> 0 | AC36: =CEILING((100*(CEILING(N36*0.8,P36)))/(101.3-2.67123*(AB36+1))*0.675,P36)&" кг" -> 0 кг | AD36: 4х4 | AE36: =CEILING((100*(CEILING(N36*0.8,P36)))/(101.3-2.67123*(AB36))*0.8,P36)&" кг" -> 0 кг | AF36: 1х3 | AG36: =CEILING((100*(CEILING(N36*0.8,P36)))/(101.3-2.67123*(AB36))*0.75,P36)&" кг" -> 0 кг | AH36: 4x4 | AI36: =CEILING((100*(CEILING(N36*0.8,P36)))/(101.3-2.67123*(AB36))*0.85,P36)&" кг" -> 0 кг | AJ36: 1х2 | AK36: =CEILING((100*(CEILING(N36*0.8,P36)))/(101.3-2.67123*(AB36))*0.8,P36)&" кг" -> 0 кг | AL36: 4х3 | AM36: =CEILING((100*(CEILING(N36*0.8,P36)))/(101.3-2.67123*(AB36))*0.9,P36)&" кг (≈90%ПМ)" -> 0 кг (≈90%ПМ) | AN36: 3х1 | AO36: =CEILING((100*(CEILING(N36*0.8,P36)))/(101.3-2.67123*(AB36))*0.825,P36)&" кг" -> 0 кг
L37: Отжимания на брусьях (собственный вес) | N37: ='Программа тренировок '!C127 -> 0 | O37: ='Программа тренировок '!D127 -> 0 | P37: ='Программа тренировок '!E127 -> 0 | Q37: 5 подходов | R37: =FLOOR(0.45*O37,1)&" повт" -> 0 повт | S37: 1 подход | T37: =FLOOR(0.7*O37,1)&" повт" -> 0 повт | U37: 4 подхода | V37: =FLOOR(0.6*O37,1)&" повт" -> 0 повт | W37: 1 подход | X37: =CEILING(0.75*O37,1)&" повт" -> 0 повт | Y37: 2 подхода | Z37: =CEILING(0.5*O37,1)&" повт" -> 0 повт | AA37: 1 подход | AB37: ='Программа тренировок '!N178 -> 0 | AC37: 4 подхода | AD37: =FLOOR(0.45*AB37,1)&" повт" -> 0 повт | AE37: 3 подхода | AF37: =FLOOR(0.5*AB37,1)&" повт" -> 0 повт | AG37: 2 подхода | AH37: =FLOOR(0.65*AB37,1)&" повт" -> 0 повт | AI37: 2 подхода | AJ37: =FLOOR(0.65*AB37,1)&" повт" -> 0 повт | AK37: 2 подхода | AL37: =FLOOR(0.75*AB37,1)&" повт" -> 0 повт | AM37: ="1 подход" -> 1 подход | AN37: до отказа
L38: Разгибания рук на блоке | N38: ='Программа тренировок '!C127 -> 0 | O38: ='Программа тренировок '!D127 -> 0 | P38: ='Программа тренировок '!E127 -> 0 | Q38: =CEILING(N38*VLOOKUP(O38, Коэффициенты!N3:O11, 2,FALSE)*0.775,P38)&" кг" -> #N/A | R38: 1х4 | S38: =CEILING(N38*VLOOKUP(O38, Коэффициенты!N3:O11, 2,FALSE)*0.725,P38)&" кг" -> #N/A | T38: 3х6 | U38: =CEILING(N38*VLOOKUP(O38, Коэффициенты!N3:O11, 2,FALSE)*0.825,P38)&" кг" -> #N/A | V38: 1х3 | W38: =CEILING(N38*VLOOKUP(O38, Коэффициенты!N3:O11, 2,FALSE)*0.775,P38)&" кг" -> #N/A | X38: 3х5 | Y38: =CEILING(N38*VLOOKUP(O38, Коэффициенты!N3:O11, 2,FALSE)*0.875,P38)&" кг" -> #N/A | Z38: 1х2 | AA38: =CEILING(N38*VLOOKUP(O38, Коэффициенты!N3:O11, 2,FALSE)*0.825,P38)&" кг" -> #N/A | AB38: ='Программа тренировок '!N165 -> 0 | AC38: =CEILING((100*(CEILING(N38*0.825,P38)))/(101.3-2.67123*(AB38+1))*0.65,P38)&" кг" -> 0 кг | AD38: 4х4 | AE38: =CEILING((100*(CEILING(N38*0.825,P38)))/(101.3-2.67123*(AB38))*0.8,P38)&" кг" -> 0 кг | AF38: 1х3 | AG38: =CEILING((100*(CEILING(N38*0.825,P38)))/(101.3-2.67123*(AB38))*0.75,P38)&" кг" -> 0 кг | AH38: 3x5 | AI38: =CEILING((100*(CEILING(N38*0.825,P38)))/(101.3-2.67123*(AB38))*0.85,P38)&" кг" -> 0 кг | AJ38: 1х2 | AK38: =CEILING((100*(CEILING(N38*0.825,P38)))/(101.3-2.67123*(AB38))*0.8,P38)&" кг" -> 0 кг | AL38: 3х4 | AM38: =CEILING((100*(CEILING(N38*0.825,P38)))/(101.3-2.67123*(AB38))*0.9,P38)&" кг" -> 0 кг | AN38: 3х1 | AO38: =CEILING((100*(CEILING(N38*0.825,P38)))/(101.3-2.67123*(AB38))*0.825,P38)&" кг" -> 0 кг
L39: + | AH39: =+AH3AH39:AI39 -> #NAME?
L40: Шраги | N40: ='Программа тренировок '!C128 -> 0 | O40: ='Программа тренировок '!D128 -> 0 | P40: ='Программа тренировок '!E128 -> 0 | Q40: =CEILING(N40*VLOOKUP(O40, Коэффициенты!N3:O11, 2,FALSE)*0.8,P40)&" кг" -> #N/A | R40: 1х2 | S40: =CEILING(N40*VLOOKUP(O40, Коэффициенты!N3:O11, 2,FALSE)*0.7,P40)&" кг" -> #N/A | T40: 3х5 | U40: =CEILING(N40*VLOOKUP(O40, Коэффициенты!N3:O11, 2,FALSE)*0.85,P40)&" кг" -> #N/A | V40: 1х2 | W40: =CEILING(N40*VLOOKUP(O40, Коэффициенты!N3:O11, 2,FALSE)*0.75,P40)&" кг" -> #N/A | X40: 3х4 | Y40: =CEILING(N40*VLOOKUP(O40, Коэффициенты!N3:O11, 2,FALSE)*0.9,P40)&" кг" -> #N/A | Z40: 4х1 | AA40: =CEILING((N40*VLOOKUP(O40, Коэффициенты!N3:O11, 2,FALSE))*0.8,P40)&" кг" -> #N/A | AB40: ='Программа тренировок '!N166 -> 0 | AC40: =CEILING((100*(CEILING(N40*0.8,P40)))/(101.3-2.67123*(AB40+1))*0.65,P40)&" кг" -> 0 кг | AD40: 3х4 | AE40: =CEILING((100*(CEILING(N40*0.8,P40)))/(101.3-2.67123*(AB40+1))*0.825,P40)&" кг" -> 0 кг | AF40: 1х2 | AG40: =CEILING((100*(CEILING(N40*0.8,P40)))/(101.3-2.67123*(AB40+1))*0.725,P40)&" кг" -> 0 кг | AH40: 3х5 | AI40: =CEILING((100*(CEILING(N40*0.8,P40)))/(101.3-2.67123*(AB40+1))*0.85,P40)&" кг" -> 0 кг | AJ40: 1х2 | AK40: =CEILING((100*(CEILING(N40*0.8,P40)))/(101.3-2.67123*(AB40+1))*0.75,P40)&" кг" -> 0 кг | AL40: 4х3 | AM40: =CEILING((100*(CEILING(N40*0.8,P40)))/(101.3-2.67123*(AB40+1))*0.9,P40)&" кг" -> 0 кг | AN40: 1х2 | AO40: =CEILING((100*(CEILING(N40*0.8,P40)))/(101.3-2.67123*(AB40+1))*0.8,P40)&" кг" -> 0 кг
L41: Подъёмы на носки | N41: ='Программа тренировок '!C128 -> 0 | O41: ='Программа тренировок '!D128 -> 0 | P41: ='Программа тренировок '!E128 -> 0 | Q41: =CEILING(N41*VLOOKUP(O41, Коэффициенты!N3:O11, 2,FALSE)*0.6,P41)&" кг" -> #N/A | R41: 3х10 | U41: =CEILING(N41*VLOOKUP(O41, Коэффициенты!N3:O11, 2,FALSE)*0.7,P41)&" кг" -> #N/A | V41: 3х8 | AA41: =CEILING(N41*VLOOKUP(O41, Коэффициенты!N3:O11, 2,FALSE)*0.75,P41)&" кг" -> #N/A | AB41: ='Программа тренировок '!N151 -> 0 | AC41: =CEILING((100*(CEILING(N41*0.75,P41)))/(101.3-2.67123*(AB41+1))*0.675,P41)&" кг" -> 0 кг | AD41: 4х4 | AE41: =CEILING((100*(CEILING(N41*0.75,P41)))/(101.3-2.67123*(AB41))*0.625,P41)&" кг" -> 0 кг | AF41: 3x10 | AI41: =CEILING((100*(CEILING(N41*0.8,P41)))/(101.3-2.67123*(AB41))*0.7,P41)&" кг" -> 0 кг | AJ41: 3x8 | AO41: =CEILING((100*(CEILING(N41*0.8,P41)))/(101.3-2.67123*(AB41))*0.75,P41)&" кг" -> 0 кг
L44: Армейский жим | N44: ='Программа тренировок '!C133 -> 0 | O44: ='Программа тренировок '!D133 -> 0 | P44: ='Программа тренировок '!E133 -> 0 | Q44: =CEILING(N44*0.85,P44)&" кг" -> 0 кг | R44: 1х1 | S44: =CEILING(N44*0.8,P44)&" кг" -> 0 кг | T44: 4х3 | U44: =CEILING(N44*0.925,P44)&" кг" -> 0 кг | V44: 1х1 | W44: =CEILING(N44*0.875,P44)&" кг" -> 0 кг | X44: 4x2 | Y44: =CEILING(N44*0.95,P44)&" кг" -> 0 кг | Z44: 4х1 | AA44: =CEILING(N44*0.9,P44)&" кг" -> 0 кг | AB44: ='Программа тренировок '!N171 -> 0 | AC44: =CEILING((100*(CEILING(N44*0.9,P44)))/(101.3-2.67123*(AB44+1))*0.65,P44)&" кг" -> 0 кг | AD44: 4х4 | AE44: =CEILING((100*(CEILING(N44*0.9,P44)))/(101.3-2.67123*(AB44+1))*0.875,P44)&" кг" -> 0 кг | AF44: 1х1 | AG44: =CEILING((100*(CEILING(N44*0.9,P44)))/(101.3-2.67123*(AB44+1))*0.825,P44)&" кг" -> 0 кг | AH44: 4х3 | AI44: =CEILING((100*(CEILING(N44*0.9,P44)))/(101.3-2.67123*(AB44+1))*0.925,P44)&" кг" -> 0 кг | AJ44: 1х1 | AK44: =CEILING((100*(CEILING(N44*0.9,P44)))/(101.3-2.67123*(AB44+1))*0.875,P44)&" кг" -> 0 кг | AL44: 4х2 | AM44: =CEILING((100*(CEILING(N44*0.9,P44)))/(101.3-2.67123*(AB44+1))*0.975,P44)&" (±5) кг (≈100%ПМ)" -> 0 (±5) кг (≈100%ПМ) | AN44: 1х1 | AO44: =CEILING((100*(CEILING(N44*0.9,P44)))/(101.3-2.67123*(AB44+1))*0.9,P44)&" кг" -> 0 кг
L45: Жим гантелей сидя | N45: ='Программа тренировок '!C133 -> 0 | O45: ='Программа тренировок '!D133 -> 0 | P45: ='Программа тренировок '!E133 -> 0 | Q45: =CEILING(N45*VLOOKUP(O45, Коэффициенты!N3:O11, 2,FALSE)*0.775,P45)&" кг" -> #N/A | R45: 1х3 | S45: =CEILING(N45*VLOOKUP(O45, Коэффициенты!N3:O11, 2,FALSE)*0.725,P45)&" кг" -> #N/A | T45: 4х5 | U45: =CEILING(N45*VLOOKUP(O45, Коэффициенты!N3:O11, 2,FALSE)*0.825,P45)&" кг" -> #N/A | V45: 1х2 | W45: =CEILING(N45*VLOOKUP(O45, Коэффициенты!N3:O11, 2,FALSE)*0.775,P45)&" кг" -> #N/A | X45: 4х4 | Y45: =CEILING(N45*VLOOKUP(O45, Коэффициенты!N3:O11, 2,FALSE)*0.85,P45)&" кг" -> #N/A | Z45: 3х2 | AA45: =CEILING(N45*VLOOKUP(O45, Коэффициенты!N3:O11, 2,FALSE)*0.8,P45)&" кг" -> #N/A | AB45: ='Программа тренировок '!N171 -> 0 | AC45: =CEILING((100*(CEILING(N45*0.9,P45)))/(101.3-2.67123*(AB45+1))*0.65,P45)&" кг" -> 0 кг | AD45: 4х4 | AE45: =CEILING((100*(CEILING(N45*0.9,P45)))/(101.3-2.67123*(AB45))*0.8,P45)&" кг" -> 0 кг | AF45: 1х3 | AG45: =CEILING((100*(CEILING(N45*0.9,P45)))/(101.3-2.67123*(AB45))*0.75,P45)&" кг" -> 0 кг | AH45: 4x4 | AI45: =CEILING((100*(CEILING(N45*0.9,P45)))/(101.3-2.67123*(AB45))*0.85,P45)&" кг" -> 0 кг | AJ45: 1х2 | AK45: =CEILING((100*(CEILING(N45*0.9,P45)))/(101.3-2.67123*(AB45))*0.8,P45)&" кг" -> 0 кг | AL45: 4х3 | AM45: =CEILING((100*(CEILING(N45*0.9,P45)))/(101.3-2.67123*(AB45))*0.9,P45)&" кг (≈90%ПМ)" -> 0 кг (≈90%ПМ) | AN45: 3х1 | AO45: =CEILING((100*(CEILING(N45*0.9,P45)))/(101.3-2.67123*(AB45))*0.825,P45)&" кг" -> 0 кг
L48: Тяга штанги в наклоне | N48: ='Программа тренировок '!C134 -> 0 | O48: ='Программа тренировок '!D134 -> 0 | P48: ='Программа тренировок '!E134 -> 0 | Q48: =CEILING(N48*VLOOKUP(O48, Коэффициенты!N3:O11, 2,FALSE)*0.8,P48)&" кг" -> #N/A | R48: 1х2 | S48: =CEILING(N48*VLOOKUP(O48, Коэффициенты!N3:O11, 2,FALSE)*0.75,P48)&" кг" -> #N/A | T48: 4х4 | U48: =CEILING(N48*VLOOKUP(O48, Коэффициенты!N3:O11, 2,FALSE)*0.85,P48)&" кг" -> #N/A | V48: 1х2 | W48: =CEILING(N48*VLOOKUP(O48, Коэффициенты!N3:O11, 2,FALSE)*0.8,P48)&" кг" -> #N/A | X48: 4х3 | Y48: =CEILING(N48*VLOOKUP(O48, Коэффициенты!N3:O11, 2,FALSE)*0.9,P48)&" кг" -> #N/A | Z48: 4х1 | AA48: =CEILING((N48*VLOOKUP(O48, Коэффициенты!N3:O11, 2,FALSE))*0.85,P48)&" кг" -> #N/A | AB48: ='Программа тренировок '!N172 -> 0 | AC48: =CEILING((100*(CEILING(N48*0.85,P48)))/(101.3-2.67123*(AB48+1))*0.65,P48)&" кг" -> 0 кг | AD48: 3х4 | AE48: =CEILING((100*(CEILING(N48*0.85,P48)))/(101.3-2.67123*(AB48+1))*0.825,P48)&" кг" -> 0 кг | AF48: 1х2 | AG48: =CEILING((100*(CEILING(N48*0.85,P48)))/(101.3-2.67123*(AB48+1))*0.775,P48)&" кг" -> 0 кг | AH48: 4х4 | AI48: =CEILING((100*(CEILING(N48*0.85,P48)))/(101.3-2.67123*(AB48+1))*0.875,P48)&" кг" -> 0 кг | AJ48: 1х2 | AK48: =CEILING((100*(CEILING(N48*0.85,P48)))/(101.3-2.67123*(AB48+1))*0.825,P48)&" кг" -> 0 кг | AL48: 4х3 | AM48: =CEILING((100*(CEILING(N48*0.85,P48)))/(101.3-2.67123*(AB48+1))*0.9,P48)&" кг (≈90%ПМ)" -> 0 кг (≈90%ПМ) | AN48: 3х1 | AO48: =CEILING((100*(CEILING(N48*0.85,P48)))/(101.3-2.67123*(AB48+1))*0.85,P48)&" кг" -> 0 кг
L49: Тяга гантели в наклоне | N49: ='Программа тренировок '!C134 -> 0 | O49: ='Программа тренировок '!D134 -> 0 | P49: ='Программа тренировок '!E134 -> 0 | Q49: =CEILING(N49*VLOOKUP(O49, Коэффициенты!N3:O11, 2,FALSE)*0.775,P49)&" кг" -> #N/A | R49: 1х3 | S49: =CEILING(N49*VLOOKUP(O49, Коэффициенты!N3:O11, 2,FALSE)*0.725,P49)&" кг" -> #N/A | T49: 4х5 | U49: =CEILING(N49*VLOOKUP(O49, Коэффициенты!N3:O11, 2,FALSE)*0.825,P49)&" кг" -> #N/A | V49: 1х2 | W49: =CEILING(N49*VLOOKUP(O49, Коэффициенты!N3:O11, 2,FALSE)*0.775,P49)&" кг" -> #N/A | X49: 4х4 | Y49: =CEILING(N49*VLOOKUP(O49, Коэффициенты!N3:O11, 2,FALSE)*0.85,P49)&" кг" -> #N/A | Z49: 3х2 | AA49: =CEILING(N49*VLOOKUP(O49, Коэффициенты!N3:O11, 2,FALSE)*0.8,P49)&" кг" -> #N/A | AB49: ='Программа тренировок '!N172 -> 0 | AC49: =CEILING((100*(CEILING(N49*0.8,P49)))/(101.3-2.67123*(AB49+1))*0.65,P49)&" кг" -> 0 кг | AD49: 4х4 | AE49: =CEILING((100*(CEILING(N49*0.8,P49)))/(101.3-2.67123*(AB49))*0.8,P49)&" кг" -> 0 кг | AF49: 1х3 | AG49: =CEILING((100*(CEILING(N49*0.8,P49)))/(101.3-2.67123*(AB49))*0.75,P49)&" кг" -> 0 кг | AH49: 4x4 | AI49: =CEILING((100*(CEILING(N49*0.8,P49)))/(101.3-2.67123*(AB49))*0.85,P49)&" кг" -> 0 кг | AJ49: 1х2 | AK49: =CEILING((100*(CEILING(N49*0.8,P49)))/(101.3-2.67123*(AB49))*0.8,P49)&" кг" -> 0 кг | AL49: 4х3 | AM49: =CEILING((100*(CEILING(N49*0.8,P49)))/(101.3-2.67123*(AB49))*0.9,P49)&" кг (≈90%ПМ)" -> 0 кг (≈90%ПМ) | AN49: 3х1 | AO49: =CEILING((100*(CEILING(N49*0.8,P49)))/(101.3-2.67123*(AB49))*0.825,P49)&" кг" -> 0 кг
L50: Тяга в хаммере | N50: ='Программа тренировок '!C134 -> 0 | O50: ='Программа тренировок '!D134 -> 0 | P50: ='Программа тренировок '!E134 -> 0 | Q50: =CEILING(N50*VLOOKUP(O50, Коэффициенты!N3:O11, 2,FALSE)*0.8,P50)&" кг" -> #N/A | R50: 1х2 | S50: =CEILING(N50*VLOOKUP(O50, Коэффициенты!N3:O11, 2,FALSE)*0.75,P50)&" кг" -> #N/A | T50: 4х4 | U50: =CEILING(N50*VLOOKUP(O50, Коэффициенты!N3:O11, 2,FALSE)*0.85,P50)&" кг" -> #N/A | V50: 1х2 | W50: =CEILING(N50*VLOOKUP(O50, Коэффициенты!N3:O11, 2,FALSE)*0.8,P50)&" кг" -> #N/A | X50: 4х3 | Y50: =CEILING(N50*VLOOKUP(O50, Коэффициенты!N3:O11, 2,FALSE)*0.9,P50)&" кг" -> #N/A | Z50: 4х1 | AA50: =CEILING((N50*VLOOKUP(O50, Коэффициенты!N3:O11, 2,FALSE))*0.85,P50)&" кг" -> #N/A | AB50: ='Программа тренировок '!N172 -> 0 | AC50: =CEILING((100*(CEILING(N50*0.85,P50)))/(101.3-2.67123*(AB50+1))*0.65,P50)&" кг" -> 0 кг | AD50: 3х4 | AE50: =CEILING((100*(CEILING(N50*0.85,P50)))/(101.3-2.67123*(AB50+1))*0.825,P50)&" кг" -> 0 кг | AF50: 1х2 | AG50: =CEILING((100*(CEILING(N50*0.85,P50)))/(101.3-2.67123*(AB50+1))*0.775,P50)&" кг" -> 0 кг | AH50: 4х4 | AI50: =CEILING((100*(CEILING(N50*0.85,P50)))/(101.3-2.67123*(AB50+1))*0.875,P50)&" кг" -> 0 кг | AJ50: 1х2 | AK50: =CEILING((100*(CEILING(N50*0.85,P50)))/(101.3-2.67123*(AB50+1))*0.825,P50)&" кг" -> 0 кг | AL50: 4х3 | AM50: =CEILING((100*(CEILING(N50*0.85,P50)))/(101.3-2.67123*(AB50+1))*0.9,P50)&" кг (≈90%ПМ)" -> 0 кг (≈90%ПМ) | AN50: 3х1 | AO50: =CEILING((100*(CEILING(N50*0.85,P50)))/(101.3-2.67123*(AB50+1))*0.85,P50)&" кг" -> 0 кг
L54: Приседания со штангой | N54: ='Программа тренировок '!C118 -> 0 | O54: ='Программа тренировок '!D118 -> 0 | P54: ='Программа тренировок '!E118 -> 0 | Q54: =CEILING(N54*VLOOKUP(O54, Коэффициенты!N3:O11, 2,FALSE)*0.7,P54)&" кг" -> #N/A | R54: 1х3 | S54: =CEILING(N54*VLOOKUP(O54, Коэффициенты!N3:O11, 2,FALSE)*0.65,P54)&" кг" -> #N/A | T54: 3х4 | U54: =CEILING(N54*VLOOKUP(O54, Коэффициенты!N3:O11, 2,FALSE)*0.75,P54)&" кг" -> #N/A | V54: 1х2 | W54: =CEILING(N54*VLOOKUP(O54, Коэффициенты!N3:O11, 2,FALSE)*0.7,P54)&" кг" -> #N/A | X54: 3х3 | Y54: =CEILING(N54*VLOOKUP(O54, Коэффициенты!N3:O11, 2,FALSE)*0.75,P54)&" кг" -> #N/A | Z54: 3х2 | AC54: =CEILING(N54*VLOOKUP(O54, Коэффициенты!N3:O11, 2,FALSE)*0.65,P54)&" кг" -> #N/A | AD54: 4х4 | AE54: =CEILING(N54*VLOOKUP(O54, Коэффициенты!N3:O11, 2,FALSE)*0.725,P54)&" кг" -> #N/A | AF54: 1х3 | AG54: =CEILING(N54*VLOOKUP(O54, Коэффициенты!N3:O11, 2,FALSE)*0.675,P54)&" кг" -> #N/A | AH54: 3x4 | AI54: =CEILING(N54*VLOOKUP(O54, Коэффициенты!N3:O11, 2,FALSE)*0.775,P54)&" кг" -> #N/A | AJ54: 1х2 | AK54: =CEILING(N54*VLOOKUP(O54, Коэффициенты!N3:O11, 2,FALSE)*0.725,P54)&" кг" -> #N/A | AL54: 3х3 | AM54: =CEILING(N54*VLOOKUP(O54, Коэффициенты!N3:O11, 2,FALSE)*0.775,P54)&" кг" -> #N/A | AN54: 3х2
L55: Жим платформы ногами | N55: ='Программа тренировок '!C118 -> 0 | O55: ='Программа тренировок '!D118 -> 0 | P55: ='Программа тренировок '!E118 -> 0 | Q55: =CEILING(N55*VLOOKUP(O55, Коэффициенты!N3:O11, 2,FALSE)*0.775,P55)&" кг" -> #N/A | R55: 1х4 | S55: =CEILING(N55*VLOOKUP(O55, Коэффициенты!N3:O11, 2,FALSE)*0.725,P55)&" кг" -> #N/A | T55: 4х6 | U55: =CEILING(N55*VLOOKUP(O55, Коэффициенты!N3:O11, 2,FALSE)*0.825,P55)&" кг" -> #N/A | V55: 1х3 | W55: =CEILING(N55*VLOOKUP(O55, Коэффициенты!N3:O11, 2,FALSE)*0.775,P55)&" кг" -> #N/A | X55: 4х5 | Y55: =CEILING(N55*VLOOKUP(O55, Коэффициенты!N3:O11, 2,FALSE)*0.9,P55)&" кг" -> #N/A | Z55: 1х2 | AA55: =CEILING(N55*VLOOKUP(O55, Коэффициенты!N3:O11, 2,FALSE)*0.85,P55)&" кг" -> #N/A | AB55: ='Программа тренировок '!N156 -> 0 | AC55: =CEILING((100*(CEILING(N55*0.85,P55)))/(101.3-2.67123*(AB55+1))*0.65,P55)&" кг" -> 0 кг | AD55: 4х4 | AE55: =CEILING((100*(CEILING(N55*0.85,P55)))/(101.3-2.67123*(AB55))*0.8,P55)&" кг" -> 0 кг | AF55: 1х4 | AG55: =CEILING((100*(CEILING(N55*0.85,P55)))/(101.3-2.67123*(AB55))*0.75,P55)&" кг" -> 0 кг | AH55: 3x6 | AI55: =CEILING((100*(CEILING(N55*0.85,P55)))/(101.3-2.67123*(AB55))*0.85,P55)&" кг" -> 0 кг | AJ55: 1х3 | AK55: =CEILING((100*(CEILING(N55*0.85,P55)))/(101.3-2.67123*(AB55))*0.8,P55)&" кг" -> 0 кг | AL55: 3х5 | AM55: =CEILING((100*(CEILING(N55*0.85,P55)))/(101.3-2.67123*(AB55))*0.9,P55)&" кг" -> 0 кг | AN55: 1х1 | AO55: =CEILING((100*(CEILING(N55*0.85,P55)))/(101.3-2.67123*(AB55))*0.85,P55)&" кг" -> 0 кг
L56: Фронтальные приседания | N56: ='Программа тренировок '!C118 -> 0 | O56: ='Программа тренировок '!D118 -> 0 | P56: ='Программа тренировок '!E118 -> 0 | Q56: =CEILING(N56*VLOOKUP(O56, Коэффициенты!N3:O11, 2,FALSE)*0.775,P56)&" кг" -> #N/A | R56: 1х3 | S56: =CEILING(N56*VLOOKUP(O56, Коэффициенты!N3:O11, 2,FALSE)*0.725,P56)&" кг" -> #N/A | T56: 4х5 | U56: =CEILING(N56*VLOOKUP(O56, Коэффициенты!N3:O11, 2,FALSE)*0.825,P56)&" кг" -> #N/A | V56: 1х2 | W56: =CEILING(N56*VLOOKUP(O56, Коэффициенты!N3:O11, 2,FALSE)*0.775,P56)&" кг" -> #N/A | X56: 4х4 | Y56: =CEILING(N56*VLOOKUP(O56, Коэффициенты!N3:O11, 2,FALSE)*0.85,P56)&" кг" -> #N/A | Z56: 3х2 | AA56: =CEILING(N56*VLOOKUP(O56, Коэффициенты!N3:O11, 2,FALSE)*0.8,P56)&" кг" -> #N/A | AB56: ='Программа тренировок '!N156 -> 0 | AC56: =CEILING((100*(CEILING(N56*0.8,P56)))/(101.3-2.67123*(AB56+1))*0.65,P56)&" кг" -> 0 кг | AD56: 4х4 | AE56: =CEILING((100*(CEILING(N56*0.8,P56)))/(101.3-2.67123*(AB56))*0.8,P56)&" кг" -> 0 кг | AF56: 1х3 | AG56: =CEILING((100*(CEILING(N56*0.8,P56)))/(101.3-2.67123*(AB56))*0.75,P56)&" кг" -> 0 кг | AH56: 4x4 | AI56: =CEILING((100*(CEILING(N56*0.8,P56)))/(101.3-2.67123*(AB56))*0.85,P56)&" кг" -> 0 кг | AJ56: 1х2 | AK56: =CEILING((100*(CEILING(N56*0.8,P56)))/(101.3-2.67123*(AB56))*0.8,P56)&" кг" -> 0 кг | AL56: 4х3 | AM56: =CEILING((100*(CEILING(N56*0.8,P56)))/(101.3-2.67123*(AB56))*0.9,P56)&" кг (≈90%ПМ)" -> 0 кг (≈90%ПМ) | AN56: 3х1 | AO56: =CEILING((100*(CEILING(N56*0.8,P56)))/(101.3-2.67123*(AB56))*0.825,P56)&" кг" -> 0 кг
L59: Подтягивания (собственный вес) | N59: =IF('Программа тренировок '!B155='Программа тренировок '!B173, Формулы!N14, 'Программа тренировок '!C135) -> 0 | O59: =IF('Программа тренировок '!B117='Программа тренировок '!B135, O14, 'Программа тренировок '!D135) -> 0 | P59: =IF('Программа тренировок '!B117='Программа тренировок '!B135, P14, 'Программа тренировок '!E135) -> 0 | Q59: 3 подхода | R59: =FLOOR(0.6*O59,1)&" повт" -> 0 повт | S59: 1 подход | T59: =FLOOR(0.75*O59,1)&" повт" -> 0 повт | U59: 2 подхода | V59: =FLOOR(0.65*O59,1)&" повт" -> 0 повт | W59: 2 подхода | X59: =CEILING(0.75*O59,1)&" повт" -> 0 повт | Y59: 1 подход | Z59: =CEILING(0.5*O59,1)&" повт" -> 0 повт | AA59: 1 подход | AB59: =IF('Программа тренировок '!B117='Программа тренировок '!B135, AB14, 'Программа тренировок '!N173) -> 0 | AC59: 3 подхода | AD59: =FLOOR(0.45*AB59,1)&" повт" -> 0 повт | AE59: 2 подхода | AF59: =FLOOR(0.5*AB59,1)&" повт" -> 0 повт | AG59: 2 подхода | AH59: =FLOOR(0.65*AB59,1)&" повт" -> 0 повт | AI59: 2 подхода | AJ59: =FLOOR(0.65*AB59,1)&" повт" -> 0 повт | AK59: 2 подхода | AL59: =FLOOR(0.75*AB59,1)&" повт" -> 0 повт | AM59: 2 подхода | AN59: =FLOOR(0.85*AB59,1)&" повт" -> 0 повт
L60: Пуловер | N60: ='Программа тренировок '!C135 -> 0 | O60: ='Программа тренировок '!D135 -> 0 | P60: ='Программа тренировок '!E135 -> 0 | Q60: =CEILING(N60*VLOOKUP(O60, Коэффициенты!N3:O11, 2,FALSE)*0.6,P60)&" кг" -> #N/A | R60: 3х10 | U60: =CEILING(N60*VLOOKUP(O60, Коэффициенты!N3:O11, 2,FALSE)*0.7,P60)&" кг" -> #N/A | V60: 3х8 | AA60: =CEILING(N60*VLOOKUP(O60, Коэффициенты!N3:O11, 2,FALSE)*0.75,P60)&" кг" -> #N/A | AB60: ='Программа тренировок '!N173 -> 0 | AC60: =CEILING((100*(CEILING(N60*0.75,P60)))/(101.3-2.67123*(AB60+1))*0.65,P60)&" кг" -> 0 кг | AD60: 4х4 | AE60: =CEILING((100*(CEILING(N60*0.75,P60)))/(101.3-2.67123*(AB60))*0.625,P60)&" кг" -> 0 кг | AF60: 3x10 | AI60: =CEILING((100*(CEILING(N60*0.8,P60)))/(101.3-2.67123*(AB60))*0.7,P60)&" кг" -> 0 кг | AJ60: 3x8 | AO60: =CEILING((100*(CEILING(N60*0.8,P60)))/(101.3-2.67123*(AB60))*0.75,P60)&" кг" -> 0 кг
L61: Тяга горизонтального блока к поясу | N61: ='Программа тренировок '!C135 -> 0 | O61: ='Программа тренировок '!D135 -> 0 | P61: ='Программа тренировок '!E135 -> 0 | Q61: =CEILING(N61*VLOOKUP(O61, Коэффициенты!N3:O11, 2,FALSE)*0.775,P61)&" кг" -> #N/A | R61: 1х4 | S61: =CEILING(N61*VLOOKUP(O61, Коэффициенты!N3:O11, 2,FALSE)*0.7,P61)&" кг" -> #N/A | T61: 3х8 | U61: =CEILING(N61*VLOOKUP(O61, Коэффициенты!N3:O11, 2,FALSE)*0.825,P61)&" кг" -> #N/A | V61: 1х3 | W61: =CEILING(N61*VLOOKUP(O61, Коэффициенты!N3:O11, 2,FALSE)*0.75,P61)&" кг" -> #N/A | X61: 3х6 | Y61: =CEILING(N61*VLOOKUP(O61, Коэффициенты!N3:O11, 2,FALSE)*0.85,P61)&" кг" -> #N/A | Z61: 1х2 | AA61: =CEILING(N61*VLOOKUP(O61, Коэффициенты!N3:O11, 2,FALSE)*0.8,P61)&" кг" -> #N/A | AB61: ='Программа тренировок '!N173 -> 0 | AC61: =CEILING((100*(CEILING(N61*0.8,P61)))/(101.3-2.67123*(AB61+1))*0.65,P61)&" кг" -> 0 кг | AD61: 4х4 | AE61: =CEILING((100*(CEILING(N61*0.8,P61)))/(101.3-2.67123*(AB61))*0.8,P61)&" кг" -> 0 кг | AF61: 1х3 | AG61: =CEILING((100*(CEILING(N61*0.8,P61)))/(101.3-2.67123*(AB61))*0.725,P61)&" кг" -> 0 кг | AH61: 3x8 | AI61: =CEILING((100*(CEILING(N61*0.8,P61)))/(101.3-2.67123*(AB61))*0.825,P61)&" кг" -> 0 кг | AJ61: 1х2 | AK61: =CEILING((100*(CEILING(N61*0.8,P61)))/(101.3-2.67123*(AB61))*0.75,P61)&" кг" -> 0 кг | AL61: 3х6 | AM61: =CEILING((100*(CEILING(N61*0.8,P61)))/(101.3-2.67123*(AB61))*0.875,P61)&" кг" -> 0 кг | AN61: 1х2 | AO61: =CEILING((100*(CEILING(N61*0.8,P61)))/(101.3-2.67123*(AB61))*0.825,P61)&" кг" -> 0 кг
L63: +
...

Sheet Коэффициенты
C2: 1 | H2: Шаг: | I2: 1ПМ: | K2: Шаг: | L2: 1ПМ:
C3: 2 | D3: 2.5 | E3: 3 | F3: 2.5 | H3: =IF('Программа тренировок '!D206="boosty.to/yetiblog", 4, 9) -> 4 | I3: =100/92 -> 1.0869565 | K3: 4 | L3: =100/85 -> 1.1764706 | N3: 4 | O3: =100/97 -> 1.0309278 | Q3: 2
C4: 3 | D4: 5 | E4: 6 | F4: 3 | H4: 5 | I4: =100/89 -> 1.1235955 | K4: 5 | L4: =100/80 -> 1.25 | N4: 5 | O4: =100/95 -> 1.0526316 | Q4: 4
C5: 4 | D5: 7.5 | E5: 9 | F5: 5 | H5: 6 | I5: =IF('Программа тренировок '!B7=S154, 100/87, "") -> 1.1494253 | K5: 6 | L5: =100/75 -> 1.3333333 | N5: 6 | O5: =100/92 -> 1.0869565 | Q5: 6
C6: 5 | D6: 10 | F6: 6 | H6: 7 | I6: =100/85 -> 1.1764706 | K6: 7 | L6: =100/70 -> 1.4285714 | N6: 7 | O6: =IF('Программа тренировок '!B7=S154, 100/90,"") -> 1.1111111
C7: 6 | D7: 15 | F7: 7.5 | N7: =IF('Программа тренировок '!B205=S153, "8", "") -> 8 | O7: =100/87 -> 1.1494253
C8: 7 | D8: 20 | F8: 9 | N8: 9 | O8: =100/85 -> 1.1764706
C9: 8 | F9: 10 | N9: 10 | O9: =100/83 -> 1.2048193
C10: 9 | F10: 15 | N10: 11 | O10: =100/81 -> 1.2345679
C11: 10 | F11: 20 | N11: 12 | O11: =100/79 -> 1.2658228
E16: 1
E17: 2
E18: 3 | O18: 1
E19: 4 | O19: 2
E20: 5 | O20: 2.5
E21: 6 | O21: 3
E22: 7 | O22: 5
E23: 8
E24: 9
E25: 10
E26: 11
E27: 12
E28: 13
E29: 14
E30: 15
E31: 16
E32: 17
E33: 18
E34: 19
... E61: 46
S153: Авторские видео-гайды по упражнениям и другие программы тренировок доступны подписчикам на Boosty
S154: ВИДЕО-ИНСТРУКЦИЯ К ДАННОЙ ПРОГРАММЕ ТРЕНИРОВОК
