Workbook
Name Подтягивания: 'Коэффициенты'!$C$2:$C$7
Name Нет: 'Коэффициенты'!$C$2:$C$7

Sheet Программа тренировок 
B8: Если у вас возникнут вопросы, то у меня есть постоянная поддержка к программам тренировок для всех подписчиков Boosty
B10: ПРАВИЛА СИЛОВОЙ ТРЕНИРОВКИ:
B11: Разминка:
B12: Каждая тренировка начинается с суставной гимнастики - необходимо в течение 5-10 минут разогреть все суставы (выполнить вращательные, сгибательные и разгибательные движения всеми доступными частями тела) - уделить особое внимание плечевому суставу, позвоночнику, коленям
B14: Разминочные подходы:
B15: В каждом упражнении делаем от 1 до 4,5 или даже 6 разминочных подходов перед рабочим весом (чем больше рабочий вес - тем больше подходов необходимо чтобы подготовить тело).
B16: В упражнениях с маленьким весом в качестве разминки достаточно взять 50% от рабочего веса и медленно поработать на 8-10 повторений в одном подходе (не закисляясь)
B17: Чем больше рабочий вес, тем больше требуется разминочных подходов перед рабочим весом, при этом во время разминки не делать большого кол-ва повторений, чтобы не закисляться (1х8, 1х6, 1х4, 1х2, 1х1)
B18: Например если приседания 120 кг, то понадобится сделать 20*8, 50*6, 70*4, 90*2, 110*1, а только затем рабочий вес (делать большие шаги в увеличении веса после 50%ПМ травмоопасно - 10-20 кг оптимальный шаг)
B20: Отдых между подходами:
B21: Во время силовой тренировки на 3-6 повторений с субмаксимальными весами используются большие интервалы времени отдыха 5-10 минут
B22: Во время лёгких недель при работе со средними весами на 5-12 повторений можно выполнять по 3-5 минут отдыха между подходами
... B35: Для этого нажмите на название упражнения в списке подготовительного периода и программа выдаст доступные варианты на замену каждого упражнения
F39: Если нажать на "+", то в программу добавится ещё одно упражнение на выбор
B47: 2. Выполните 1 рабочий подход с весом, который соответствует условиям приведённым в таблице
B49: Перед этим рабочим подходом обязательно выполняем разминочные!
B59: 6-8ПМ - это вес, который соответствует 6-8 повторениям в отказ (то есть вы должны выбрать вес, с которым можете сделать не менее 6 и не более 8 повторений после чего произойдёт отказ)
B60: 7-9 RPE - это близость к отказу - то есть вы должны выполнить подход, сохранив от 1 до 3 повторений в запасе до отказа
B61: Получается что 6-8ПМ и 7-9 RPE это подход с весом, который вы могли бы поднять 6-8 повторений, но сделаете с ним подход остановившись на 1-3 повторениях до отказа (получается от 3 до 7 повторений)
B62: Вносим рабочий вес и полученное количество повторений в таблицу, а также оцениваем RPE подхода по шкале от 6,5 до 10 | M62: ЧТО ТАКОЕ RPE!?
B63: После этого таблица сама будет рассчитывать рабочий вес в следующих подходах, нужно только выставлять оценку RPE
B65: Колонка "Округл" округляет рабочие веса до 1 или 2,5 (для удобства подбора веса отягощения)
B66: например для штанги стандартный шаг 2,5 кг, а для гантелей 1 или 2 кг
F72: ПОДГОТОВИТЕЛЬНЫЙ ПЕРИОД
F74: Неделя 1 | O74: Неделя 2
C75: УСЛОВИЯ 1 ПОДХОДА | F75: 1 подход | I75: 2 подход | L75: 3 подход | O75: 1 подход | R75: 2 подход | U75: 3 подход
B76: День 1: | C76: ПМ | D76: RPE | E76: Округл | F76: Вес | G76: Повт | H76: RPE | I76: Вес | J76: Повт | K76: RPE | L76: Вес | M76: Повт | N76: RPE | O76: Вес | P76: Повт | Q76: RPE | R76: Вес | S76: Повт | T76: RPE | U76: Вес | V76: Повт | W76: RPE
B77: Жим штанги лёжа | C77: 6-8ПМ | D77: 7-9 | E77: 2.5 | I77: {=MROUND(F77/INDEX($AD$80:$AM$87,MATCH(H77,$AC$80:$AC$87,0),MATCH(G77,$AD$79:$AM$79, 0))*0.8,$E$77)} -> #N/A | J77: 5 | L77: {=MROUND(I77/INDEX($AD$80:$AM$87,MATCH(K77,$AC$80:$AC$87,0),MATCH(J77,$AD$79:$AM$79, 0))*0.8,$E$77)} -> #N/A | M77: 5 | O77: {=MROUND(F77/INDEX($AD$80:$AM$87,MATCH(H77,$AC$80:$AC$87,0),MATCH(G77,$AD$79:$AM$79, 0))*0.82,$E$77)} -> #N/A | P77: 4 | R77: {=MROUND(O77/INDEX($AD$80:$AM$87,MATCH(Q77,$AC$80:$AC$87,0),MATCH(P77,$AD$79:$AM$79, 0))*0.8,$E$77)} -> #N/A | S77: 5 | U77: {=MROUND(R77/INDEX($AD$80:$AM$87,MATCH(T77,$AC$80:$AC$87,0),MATCH(S77,$AD$79:$AM$79, 0))*0.78,L77)} -> #N/A | V77: 6
B78: Подтягивания (с отягощением) | C78: 6-8ПМ | D78: 7-9 | E78: 2.5 | I78: {=MROUND(F78/INDEX($AD$80:$AM$87,MATCH(H78,$AC$80:$AC$87,0),MATCH(G78,$AD$79:$AM$79, 0))*0.8,$E$78)} -> #N/A | J78: 5 | L78: {=MROUND(I78/INDEX($AD$80:$AM$87,MATCH(K78,$AC$80:$AC$87,0),MATCH(J78,$AD$79:$AM$79, 0))*0.8,$E$78)} -> #N/A | M78: 5 | O78: {=MROUND(F78/INDEX($AD$80:$AM$87,MATCH(H78,$AC$80:$AC$87,0),MATCH(G78,$AD$79:$AM$79, 0))*0.82,$E$78)} -> #N/A | P78: 4 | R78: {=MROUND(O78/INDEX($AD$80:$AM$87,MATCH(Q78,$AC$80:$AC$87,0),MATCH(P78,$AD$79:$AM$79, 0))*0.8,$E$78)} -> #N/A | S78: 5 | U78: {=MROUND(R78/INDEX($AD$80:$AM$87,MATCH(T78,$AC$80:$AC$87,0),MATCH(S78,$AD$79:$AM$79, 0))*0.78,$E$78)} -> #N/A | V78: 6 | AD78: Повторения
B79: Жим платформы ногами | C79: 8-10ПМ | D79: 7-9 | E79: 5 | I79: {=MROUND(F79/INDEX($AD$80:$AM$87,MATCH(H79,$AC$80:$AC$87,0),MATCH(G79,$AD$79:$AM$79, 0))*0.8,$E$79)} -> #N/A | J79: 5 | L79: {=MROUND(I79/INDEX($AD$80:$AM$87,MATCH(K79,$AC$80:$AC$87,0),MATCH(J79,$AD$79:$AM$79, 0))*0.8,$E$79)} -> #N/A | M79: 5 | O79: {=MROUND(F79/INDEX($AD$80:$AM$87,MATCH(H79,$AC$80:$AC$87,0),MATCH(G79,$AD$79:$AM$79, 0))*0.82,$E$79)} -> #N/A | P79: 4 | R79: {=MROUND(O79/INDEX($AD$80:$AM$87,MATCH(Q79,$AC$80:$AC$87,0),MATCH(P79,$AD$79:$AM$79, 0))*0.8,$E$79)} -> #N/A | S79: 5 | U79: {=MROUND(R79/INDEX($AD$80:$AM$87,MATCH(T79,$AC$80:$AC$87,0),MATCH(S79,$AD$79:$AM$79, 0))*0.78,$E$79)} -> #N/A | V79: 6 | AC79: RPE | AD79: 1 | AE79: 2 | AF79: 3 | AG79: 4 | AH79: 5 | AI79: 6 | AJ79: 7 | AK79: 8 | AL79: 9 | AM79: 10
B80: Махи с гантелями в стороны | C80: 10-12ПМ | D80: 7-9 | E80: 1 | I80: {=MROUND(F80/INDEX($AD$80:$AM$87,MATCH(H80,$AC$80:$AC$87,0),MATCH(G80,$AD$79:$AM$79, 0))*0.72,$E$80)} -> #N/A | J80: 8 | L80: {=MROUND(I80/INDEX($AD$80:$AM$87,MATCH(K80,$AC$80:$AC$87,0),MATCH(J80,$AD$79:$AM$79, 0))*0.72,$E$80)} -> #N/A | M80: 8 | O80: {=MROUND(F80/INDEX($AD$80:$AM$87,MATCH(H80,$AC$80:$AC$87,0),MATCH(G80,$AD$79:$AM$79, 0))*0.72,$E$80)} -> #N/A | P80: 6 | R80: {=MROUND(O80/INDEX($AD$80:$AM$87,MATCH(Q80,$AC$80:$AC$87,0),MATCH(P80,$AD$79:$AM$79, 0))*0.72,$E$80)} -> #N/A | S80: 8 | U80: {=MROUND(R80/INDEX($AD$80:$AM$87,MATCH(T80,$AC$80:$AC$87,0),MATCH(S80,$AD$79:$AM$79, 0))*0.69,$E$80)} -> #N/A | V80: 10 | AC80: 10 | AD80: 1 | AE80: 0.96 | AF80: 0.92 | AG80: 0.89 | AH80: 0.86 | AI80: 0.84 | AJ80: 0.81 | AK80: 0.79 | AL80: 0.76 | AM80: 0.74
B81: + | C81: =IF(B81='Формулы'!L39, "", "собственный") | D81: =IF(B81='Формулы'!L39, "", "7-9") | F81: =IF(B81="+", "", "собств.") | I81: =IF(B81="+", "", "собств.") | J81: =IF(B81="+", "", MROUND(G81+(10-H81-3),1)) | L81: =IF(B81="+", "", "собств.") | M81: =IF(B81="+","", MROUND(J81+(10-K81-2),1)) | O81: =IF(B81="+", "", "собств.") | P81: =IF(B81="+", "", MROUND(M81+(10-N81-2),1)) | R81: =IF(B81="+", "", "собств.") | S81: =IF(B81="+", "", MROUND(P81+(10-Q81-1),1)) | U81: =IF(B81="+", "", "собств.") | V81: =IF(B81="+", "", MROUND(S81+(10-T81-1),1)) | AC81: 9.5 | AD81: 0.98 | AE81: 0.94 | AF81: 0.91 | AG81: 0.88 | AH81: 0.85 | AI81: 0.82 | AJ81: 0.8 | AK81: 0.77 | AL81: 0.75 | AM81: 0.72
AC82: 9 | AD82: 0.96 | AE82: 0.92 | AF82: 0.89 | AG82: 0.86 | AH82: 0.84 | AI82: 0.81 | AJ82: 0.79 | AK82: 0.76 | AL82: 0.74 | AM82: 0.71
C83: УСЛОВИЯ 1 ПОДХОДА | F83: 1 подход | I83: 2 подход | L83: 3 подход | O83: 1 подход | R83: 2 подход | U83: 3 подход | AC83: 8.5 | AD83: 0.94 | AE83: 0.91 | AF83: 0.88 | AG83: 0.85 | AH83: 0.82 | AI83: 0.8 | AJ83: 0.77 | AK83: 0.75 | AL83: 0.72 | AM83: 0.69
B84: День 2: | C84: ПМ | D84: RPE | E84: Округл | F84: Вес | G84: Повт | H84: RPE | I84: Вес | J84: Повт | K84: RPE | L84: Вес | M84: Повт | N84: RPE | O84: Вес | P84: Повт | Q84: RPE | R84: Вес | S84: Повт | T84: RPE | U84: Вес | V84: Повт | W84: RPE | AC84: 8 | AD84: 0.92 | AE84: 0.89 | AF84: 0.86 | AG84: 0.84 | AH84: 0.81 | AI84: 0.79 | AJ84: 0.76 | AK84: 0.74 | AL84: 0.71 | AM84: 0.68
B85: Ягодичный мост | C85: 6-8ПМ | D85: 7-9 | E85: 2.5 | I85: {=MROUND(F85/INDEX($AD$80:$AM$87,MATCH(H85,$AC$80:$AC$87,0),MATCH(G85,$AD$79:$AM$79, 0))*0.8,$E$85)} -> #N/A | J85: 5 | L85: {=MROUND(I85/INDEX($AD$80:$AM$87,MATCH(K85,$AC$80:$AC$87,0),MATCH(J85,$AD$79:$AM$79, 0))*0.8,$E$85)} -> #N/A | M85: 5 | O85: =MROUND(F85/INDEX($AD$80:$AM$87,MATCH(H85,$AC$80:$AC$87,0),MATCH(G85,$AD$79:$AM$79, 0))*0.82,E85) -> #N/A | P85: 4 | R85: {=MROUND(O85/INDEX($AD$80:$AM$87,MATCH(Q85,$AC$80:$AC$87,0),MATCH(P85,$AD$79:$AM$79, 0))*0.8,$E$85)} -> #N/A | S85: 5 | U85: {=MROUND(R85/INDEX($AD$80:$AM$87,MATCH(T85,$AC$80:$AC$87,0),MATCH(S85,$AD$79:$AM$79, 0))*0.78,$E$85)} -> #N/A | V85: 6 | AC85: 7.5 | AD85: 0.91 | AE85: 0.88 | AF85: 0.85 | AG85: 0.82 | AH85: 0.8 | AI85: 0.77 | AJ85: 0.75 | AK85: 0.72 | AL85: 0.69 | AM85: 0.67
B86: Подъём штанги на бицепс | C86: 6-8ПМ | D86: 7-9 | E86: 2.5 | I86: {=MROUND(F86/INDEX($AD$80:$AM$87,MATCH(H86,$AC$80:$AC$87,0),MATCH(G86,$AD$79:$AM$79, 0))*0.8,$E$86)} -> #N/A | J86: 5 | L86: {=MROUND(I86/INDEX($AD$80:$AM$87,MATCH(K86,$AC$80:$AC$87,0),MATCH(J86,$AD$79:$AM$79, 0))*0.8,$E$86)} -> #N/A | M86: 5 | O86: =MROUND(F86/INDEX($AD$80:$AM$87,MATCH(H86,$AC$80:$AC$87,0),MATCH(G86,$AD$79:$AM$79, 0))*0.82,E86) -> #N/A | P86: 4 | R86: {=MROUND(O86/INDEX($AD$80:$AM$87,MATCH(Q86,$AC$80:$AC$87,0),MATCH(P86,$AD$79:$AM$79, 0))*0.8,$E$86)} -> #N/A | S86: 5 | U86: {=MROUND(R86/INDEX($AD$80:$AM$87,MATCH(T86,$AC$80:$AC$87,0),MATCH(S86,$AD$79:$AM$79, 0))*0.78,$E$86)} -> #N/A | V86: 6 | AC86: 7 | AD86: 0.89 | AE86: 0.86 | AF86: 0.84 | AG86: 0.81 | AH86: 0.79 | AI86: 0.76 | AJ86: 0.74 | AK86: 0.71 | AL86: 0.68 | AM86: 0.65
B87: Жим штанги лёжа | C87: 8-10ПМ | D87: 7-9 | E87: 2.5 | I87: {=MROUND(F87/INDEX($AD$80:$AM$87,MATCH(H87,$AC$80:$AC$87,0),MATCH(G87,$AD$79:$AM$79, 0))*0.8,$E$87)} -> #N/A | J87: 5 | L87: {=MROUND(I87/INDEX($AD$80:$AM$87,MATCH(K87,$AC$80:$AC$87,0),MATCH(J87,$AD$79:$AM$79, 0))*0.8,$E$87)} -> #N/A | M87: 5 | O87: =MROUND(F87/INDEX($AD$80:$AM$87,MATCH(H87,$AC$80:$AC$87,0),MATCH(G87,$AD$79:$AM$79, 0))*0.82,E87) -> #N/A | P87: 4 | R87: {=MROUND(O87/INDEX($AD$80:$AM$87,MATCH(Q87,$AC$80:$AC$87,0),MATCH(P87,$AD$79:$AM$79, 0))*0.8,$E$87)} -> #N/A | S87: 5 | U87: {=MROUND(R87/INDEX($AD$80:$AM$87,MATCH(T87,$AC$80:$AC$87,0),MATCH(S87,$AD$79:$AM$79, 0))*0.78,$E$87)} -> #N/A | V87: 6 | AC87: 6.5 | AD87: 0.88 | AE87: 0.85 | AF87: 0.82 | AG87: 0.8 | AH87: 0.77 | AI87: 0.75 | AJ87: 0.72 | AK87: 0.69 | AL87: 0.67 | AM87: 0.64
B88: Разгибания рук на блоке | C88: 10-12ПМ | D88: 7-9 | E88: 3 | I88: {=MROUND(F88/INDEX($AD$80:$AM$87,MATCH(H88,$AC$80:$AC$87,0),MATCH(G88,$AD$79:$AM$79, 0))*0.72,$E$88)} -> #N/A | J88: 8 | L88: {=MROUND(I88/INDEX($AD$80:$AM$87,MATCH(K88,$AC$80:$AC$87,0),MATCH(J88,$AD$79:$AM$79, 0))*0.72,$E$88)} -> #N/A | M88: 8 | O88: {=MROUND(F88/INDEX($AD$80:$AM$87,MATCH(H88,$AC$80:$AC$87,0),MATCH(G88,$AD$79:$AM$79, 0))*0.72,E88)} -> #N/A | P88: 6 | R88: {=MROUND(O88/INDEX($AD$80:$AM$87,MATCH(Q88,$AC$80:$AC$87,0),MATCH(P88,$AD$79:$AM$79, 0))*0.72,$E$88)} -> #N/A | S88: 8 | U88: {=MROUND(R88/INDEX($AD$80:$AM$87,MATCH(T88,$AC$80:$AC$87,0),MATCH(S88,$AD$79:$AM$79, 0))*0.69,$E$88)} -> #N/A | V88: 10
B89: + | C89: =IF(B89='Формулы'!L47, "", "собственный") -> собственный | D89: =IF(B89='Формулы'!L47, "", "7-9") -> 7-9 | I89: {=IF(B89="+", "", MROUND(F89/INDEX($AD$80:$AM$87,MATCH(H89,$AC$80:$AC$87,0),MATCH(G89,$AD$79:$AM$79, 0))*0.72,$E$89))} | J89: =IF(B89="+", "", "8") | L89: {=IF(B89="+", "", MROUND(I89/INDEX($AD$80:$AM$87,MATCH(K89,$AC$80:$AC$87,0),MATCH(J89,$AD$79:$AM$79, 0))*0.72,$E$89))} | M89: =IF(B89="+", "", "8") | O89: {=IF(B89="+", "", MROUND(F89/INDEX($AD$80:$AM$87,MATCH(H89,$AC$80:$AC$87,0),MATCH(G89,$AD$79:$AM$79, 0))*0.72,$E$89))} | P89: =IF(B89="+", "", "6") | R89: {=IF($B$89="+", "", MROUND(O89/INDEX($AD$80:$AM$87,MATCH(Q89,$AC$80:$AC$87,0),MATCH(P89,$AD$79:$AM$79, 0))*0.72,$E$89))} | S89: =IF(B89="+", "", "8") | U89: {=IF(B89="+", "", MROUND(R89/INDEX($AD$80:$AM$87,MATCH(T89,$AC$80:$AC$87,0),MATCH(S89,$AD$79:$AM$79, 0))*0.69,$E$89))} | V89: =IF(B89="+", "", "10")
...

Sheet Калькулятор подходов
C4: ПРОХОДКА (ВЫХОД НА 1ПМ) В ЖИМЕ ЛЁЖА ДЛЯ ЖИМА ДО 100 КГ | K4: ПРОХОДКА (ВЫХОД НА 1ПМ) В СТАНОВОЙ ТЯГЕ ДО 200 КГ
C6: Ваш ПМ: | D6: 95 | K6: Ваш ПМ: | L6: 150
D8: Вес | E8: Повт | F8: Время отдыха | L8: Вес | M8: Повт | N8: Время отдыха
C9: 1 подход | D9: 20 | E9: 10 | F9: 1 мин | K9: 1 подход | L9: 60 | M9: 6 | N9: 1-2 мин
C10: 2 подход | D10: =CEILING(D6*0.5,5) -> 50 | E10: 4 | F10: 1 мин | K10: 2 подход | L10: =CEILING(L6*0.5,5) -> 75 | M10: 4 | N10: 1-2 мин
C11: 3 подход | D11: =CEILING(D6*0.65,5) -> 65 | E11: 3 | F11: 2 мин | K11: 3 подход | L11: =CEILING(L6*0.65,5) -> 100 | M11: 3 | N11: 2-3 мин
C12: 4 подход | D12: =CEILING(D6*0.75,5) -> 75 | E12: 2 | F12: 2 мин | K12: 4 подход | L12: =CEILING(L6*0.75,5) -> 115 | M12: 2 | N12: 2-3 мин
C13: 5 подход | D13: =CEILING(D6*0.825,2.5) -> 80 | E13: 1 | F13: 3 мин | K13: 5 подход | L13: =CEILING(L6*0.825,2.5) -> 125 | M13: 1 | N13: 3 мин
C14: 6 подход | D14: =CEILING(D6*0.875,2.5) -> 85 | E14: 1 | F14: 4 мин | K14: 6 подход | L14: =CEILING(L6*0.875,2.5) -> 132.5 | M14: 1 | N14: 4 мин
C15: 7 подход | D15: =CEILING(D6*0.925,2.5) -> 90 | E15: 1 | F15: 5 мин | K15: 7 подход | L15: =CEILING(L6*0.925,2.5) -> 140 | M15: 1 | N15: 5 мин
C16: 8 подход | D16: =FLOOR(D6*0.975,2.5) -> 92.5 | E16: 1 | F16: 5 мин | K16: 8 подход | L16: =FLOOR(L6*0.975,2.5) -> 145 | M16: 1 | N16: 5 мин
C17: 9 подход | D17: =CEILING(D6*1,2.5) -> 95 | E17: 1 | F17: 6 мин | K17: 9 подход | L17: =CEILING(L6*1,2.5) -> 150 | M17: 1 | N17: 6 мин
C21: ПРОХОДКА (ВЫХОД НА 1ПМ) В ЖИМЕ ЛЁЖА ДЛЯ ЖИМА 100-150 кг | K21: ПРОХОДКА (ВЫХОД НА 1ПМ) В СТАНОВОЙ ТЯГЕ 200-250 КГ
C23: Ваш ПМ: | D23: 140 | K23: Ваш ПМ: | L23: 220
D25: Вес | E25: Повт | F25: Время отдыха | L25: Вес | M25: Повт | N25: Время отдыха
C26: 1 подход | D26: 20 | E26: 10 | F26: 1 мин | K26: 1 подход | L26: 70 | M26: 10 | N26: 1-2 мин
C27: 2 подход | D27: =CEILING(D23*0.4,5) -> 60 | E27: 6 | F27: 1 мин | K27: 2 подход | L27: =CEILING(L23*0.4,5) -> 90 | M27: 6 | N27: 1-2 мин
C28: 3 подход | D28: =CEILING(D23*0.55,5) -> 80 | E28: 4 | F28: 2 мин | K28: 3 подход | L28: =CEILING(L23*0.55,5) -> 125 | M28: 4 | N28: 2-3 мин
C29: 4 подход | D29: =CEILING(D23*0.7,5) -> 100 | E29: 2 | F29: 2 мин | K29: 4 подход | L29: =CEILING(L23*0.7,5) -> 155 | M29: 2 | N29: 2-3 мин
C30: 5 подход | D30: =CEILING(D23*0.775,2.5) -> 110 | E30: 1 | F30: 3 мин | K30: 5 подход | L30: =CEILING(L23*0.775,2.5) -> 172.5 | M30: 1 | N30: 3 мин
C31: 6 подход | D31: =CEILING(D23*0.825,2.5) -> 117.5 | E31: 1 | F31: 4 мин | K31: 6 подход | L31: =CEILING(L23*0.825,2.5) -> 182.5 | M31: 1 | N31: 4 мин
C32: 7 подход | D32: =CEILING(D23*0.875,2.5) -> 122.5 | E32: 1 | F32: 5 мин | K32: 7 подход | L32: =CEILING(L23*0.875,2.5) -> 192.5 | M32: 1 | N32: 5 мин
C33: 8 подход | D33: =FLOOR(D23*0.925,2.5) -> 127.5 | E33: 1 | F33: 5 мин | K33: 8 подход | L33: =FLOOR(L23*0.925,2.5) -> 202.5 | M33: 1 | N33: 5 мин
C34: 9 подход | D34: =CEILING(D23*0.95,2.5) -> 135 | E34: 1 | F34: 6 мин | K34: 9 подход | L34: =CEILING(L23*0.95,2.5) -> 210 | M34: 1 | N34: 6 мин
C35: 10 подход | D35: =CEILING(D23*1,2.5) -> 140 | E35: 1 | F35: 6 мин | K35: 10 подход | L35: =CEILING(L23*1,2.5) -> 220 | M35: 1 | N35: 6 мин
C40: ПРОХОДКА (ВЫХОД НА 1ПМ) В ЖИМЕ ЛЁЖА ДЛЯ ЖИМА БОЛЕЕ 150 КГ | K40: ПРОХОДКА (ВЫХОД НА 1ПМ) В СТАНОВОЙ СВЫШЕ 300 КГ
C42: Ваш ПМ: | D42: 150 | K42: Ваш ПМ: | L42: 310
D44: Вес | E44: Повт | F44: Время отдыха | L44: Вес | M44: Повт | N44: Время отдыха
C45: 1 подход | D45: 20 | E45: 10 | F45: 1 мин | K45: 1 подход | L45: 20 | M45: 10 | N45: 1-2 мин
C46: 2 подход | D46: =CEILING(D42*0.4,5) -> 60 | E46: 6 | F46: 1 мин | K46: 2 подход | L46: =CEILING(L42*0.4,5) -> 125 | M46: 6 | N46: 1-2 мин
C47: 3 подход | D47: =CEILING(D42*0.55,5) -> 85 | E47: 4 | F47: 2 мин | K47: 3 подход | L47: =CEILING(L42*0.55,5) -> 175 | M47: 4 | N47: 2-3 мин
C48: 4 подход | D48: =CEILING(D42*0.65,5) -> 100 | E48: 3 | F48: 2 мин | K48: 4 подход | L48: =CEILING(L42*0.65,5) -> 205 | M48: 3 | N48: 2-3 мин
C49: 5 подход | D49: =CEILING(D42*0.75,2.5) -> 112.5 | E49: 2 | F49: 3 мин | K49: 5 подход | L49: =CEILING(L42*0.75,2.5) -> 232.5 | M49: 2 | N49: 3 мин
C50: 6 подход | D50: =CEILING(D42*0.8,2.5) -> 120 | E50: 1 | F50: 4 мин | K50: 6 подход | L50: =CEILING(L42*0.8,2.5) -> 250 | M50: 1 | N50: 4 мин
C51: 7 подход | D51: =CEILING(D42*0.85,2.5) -> 127.5 | E51: 1 | F51: 5 мин | K51: 7 подход | L51: =CEILING(L42*0.85,2.5) -> 265 | M51: 1 | N51: 5 мин
C52: 8 подход | D52: =FLOOR(D42*0.9,2.5) -> 135 | E52: 1 | F52: 5 мин | K52: 8 подход | L52: =FLOOR(L42*0.9,2.5) -> 277.5 | M52: 1 | N52: 5 мин
C53: 9 подход | D53: =CEILING(D42*0.925,2.5) -> 140 | E53: 1 | F53: 6 мин | K53: 9 подход | L53: =CEILING(L42*0.925,2.5) -> 287.5 | M53: 1 | N53: 6 мин
C54: 10 подход | D54: =CEILING(D42*0.95,2.5) -> 142.5 | E54: 1 | F54: 6 мин | K54: 10 подход | L54: =CEILING(L42*0.95,2.5) -> 295 | M54: 1 | N54: 6 мин
C55: 11 подход | D55: =CEILING(D42*0.975,2.5) -> 147.5 | E55: 1 | F55: 6 мин | K55: 11 подход | L55: =CEILING(L42*0.975,2.5) -> 302.5 | M55: 1 | N55: 6 мин
C56: 12 подход | D56: =CEILING(D42*1,2.5) -> 150 | E56: 1 | F56: 6 мин | K56: 12 подход | L56: =CEILING(L42*1,2.5) -> 310 | M56: 1 | N56: 6 мин

Sheet Формулы
M3: 100
N7: Введите свой 4-7ПМ в ячейки: | Q7: Неделя 1 | X7: Неделя 2 | AE7: Неделя 3 | AL7: Неделя 4 | AS7: Неделя 5 | AZ7: Неделя 6 | BG7: Неделя 7 | BN7: Неделя 8 | BU7: Неделя 9
N8: вес (кг) ↓ | O8: ПМ (повт до отказа)↓ | P8: Округл ↓: | Q8: Вес | R8: Подх | S8: Повт | T8: RPE | U8: Вес | V8: Подх | W8: Повт | X8: Вес | Y8: Подх | Z8: Повт | AA8: RPE | AB8: Вес | AC8: Подх | AD8: Повт | AE8: Вес | AF8: Подх | AG8: Повт | AH8: RPE | AI8: Вес | AJ8: Подх | AK8: Повт | AL8: Вес | AM8: Подх | AN8: Повт | AO8: RPE | AP8: Вес | AQ8: Подх | AR8: Повт | AS8: Вес | AT8: Подх | AU8: Повт | AV8: RPE | AW8: Вес | AX8: Подх | AY8: Повт | AZ8: Вес | BA8: Подх | BB8: Повт | BC8: RPE | BD8: Вес | BE8: Подх | BF8: Повт | BG8: Вес | BH8: Подх | BI8: Повт | BJ8: RPE | BK8: Вес | BL8: Подх | BM8: Повт | BN8: Вес | BO8: Подх | BP8: Повт | BQ8: RPE | BR8: Вес | BS8: Подх | BT8: Повт | BU8: Вес | BV8: Подх | BW8: Повт | BX8: RPE | BY8: Вес | BZ8: Подх | CA8: Повт
L9: Жим штанги лёжа | N9: ='Программа тренировок '!C111 | O9: ='Программа тренировок '!D111 | P9: ='Формулы'!I11 -> 2.5 | Q9: =MROUND(N9/INDEX($O$93:$X$100,MATCH(10,$N$93:$N$100,0),MATCH(O9,$O$92:$X$92,0))*0.83,P9) -> #N/A | R9: =IF('Программа тренировок '!B111='Программа тренировок '!B121, 1, 3) -> 1 | S9: 3 | T9: ='Программа тренировок '!F154 | U9: =MROUND(Q9/INDEX($O$93:$X$100,MATCH(T9,$N$93:$N$100,0),MATCH(S9,$O$92:$X$92,0))*0.75,P9) -> #N/A | V9: 3 | W9: 6 | X9: =MROUND(Q9/INDEX($O$93:$X$100,MATCH(T9,$N$93:$N$100,0),MATCH(S9,$O$92:$X$92,0))*0.86,P9) -> #N/A | Y9: =IF('Программа тренировок '!B111='Программа тренировок '!B121, 1, 3) -> 1 | Z9: 3 | AA9: ='Программа тренировок '!M154 | AB9: =MROUND(X9/INDEX($O$93:$X$100,MATCH(AA9,$N$93:$N$100,0),MATCH(Z9,$O$92:$X$92,0))*0.8,P9) -> #N/A | AC9: 3 | AD9: 5 | AE9: =MROUND(X9/INDEX($O$93:$X$100,MATCH(AA9,$N$93:$N$100,0),MATCH(Z9,$O$92:$X$92,0))*0.9,P9) -> #N/A | AF9: =IF('Программа тренировок '!B111='Программа тренировок '!B121, 1, 3) -> 1 | AG9: 3 | AH9: ='Программа тренировок '!T154 | AI9: {=MROUND(AE9/INDEX($O$93:$X$100,MATCH(AH9,$N$93:$N$100,0),MATCH(AG9,$O$92:$X$92,0))*0.84,P9)} -> #N/A | AJ9: 3 | AK9: 4 | AL9: =MROUND(AE9/INDEX($O$93:$X$100,MATCH(AH9,$N$93:$N$100,0),MATCH(AG9,$O$92:$X$92,0))*0.86,P9) -> #N/A | AM9: =IF('Программа тренировок '!B111='Программа тренировок '!B121, 1, 3) -> 1 | AN9: 2 | AO9: ='Программа тренировок '!F181 | AP9: =MROUND(AL9/INDEX($O$93:$X$100,MATCH(AO9,$N$93:$N$100,0),MATCH(AN9,$O$92:$X$92,0))*0.79,P9) -> #N/A | AQ9: 3 | AR9: 5 | AS9: =MROUND(AL9/INDEX($O$93:$X$100,MATCH(AO9,$N$93:$N$100,0),MATCH(AN9,$O$92:$X$92,0))*0.89,P9) -> #N/A | AT9: =IF('Программа тренировок '!B111='Программа тренировок '!B121, 1, 3) -> 1 | AU9: 2 | AV9: ='Программа тренировок '!M181 | AW9: =MROUND(AS9/INDEX($O$93:$X$100,MATCH(AV9,$N$93:$N$100,0),MATCH(AU9,$O$92:$X$92,0))*0.82,P9) -> #N/A | AX9: 3 | AY9: 4 | AZ9: =MROUND(AS9/INDEX($O$93:$X$100,MATCH(AV9,$N$93:$N$100,0),MATCH(AU9,$O$92:$X$92,0))*0.92,P9) -> #N/A | BA9: =IF('Программа тренировок '!B111='Программа тренировок '!B121, 1, 3) -> 1 | BB9: 2 | BC9: ='Программа тренировок '!T181 | BD9: =MROUND(AZ9/INDEX($O$93:$X$100,MATCH(BC9,$N$93:$N$100,0),MATCH(BB9,$O$92:$X$92,0))*0.86,P9) -> #N/A | BE9: 3 | BF9: 3 | BG9: =MROUND(AZ9/INDEX($O$93:$X$100,MATCH(BC9,$N$93:$N$100,0),MATCH(BB9,$O$92:$X$92,0))*0.91,P9) -> #N/A | BH9: =IF('Программа тренировок '!B111='Программа тренировок '!B121, 1, 3) -> 1 | BI9: 1 | BJ9: ='Программа тренировок '!F208 | BK9: =MROUND(BG9/INDEX($O$93:$X$100,MATCH(BJ9,$N$93:$N$100,0),MATCH(BI9,$O$92:$X$92,0))*0.81,P9) -> #N/A | BL9: 3 | BM9: 4 | BN9: =MROUND(BG9/INDEX($O$93:$X$100,MATCH(BJ9,$N$93:$N$100,0),MATCH(BI9,$O$92:$X$92,0))*0.94,P9) -> #N/A | BO9: =IF('Программа тренировок '!B111='Программа тренировок '!B121, 1, 3) -> 1 | BP9: 1 | BQ9: ='Программа тренировок '!M208 | BR9: =MROUND(BN9/INDEX($O$93:$X$100,MATCH(BQ9,$N$93:$N$100,0),MATCH(BP9,$O$92:$X$92,0))*0.84,P9) -> #N/A | BS9: 3 | BT9: 3 | BU9: =MROUND(BN9/INDEX($O$93:$X$100,MATCH(BQ9,$N$93:$N$100,0),MATCH(BP9,$O$92:$X$92,0))*0.97,P9) -> #N/A | BV9: =IF('Программа тренировок '!B111='Программа тренировок '!B121, 1, 3) -> 1 | BW9: 1 | BX9: ='Программа тренировок '!T208 | BY9: =MROUND(BU9/INDEX($O$93:$X$100,MATCH(BX9,$N$93:$N$100,0),MATCH(BW9,$O$92:$X$92,0))*0.89,P9) -> #N/A | BZ9: 3 | CA9: 2
I10: Округлить до↓ | L10: Отжимания на брусьях (с доп весом) | N10: ='Программа тренировок '!C111 | O10: ='Программа тренировок '!D111 | P10: ='Формулы'!I11 -> 2.5 | Q10: =MROUND(N10/INDEX($O$93:$X$100,MATCH(10,$N$93:$N$100,0),MATCH(O10,$O$92:$X$92,0))*0.83,P10) -> #N/A | R10: 3 | S10: 3 | T10: ='Программа тренировок '!F154 | U10: =MROUND(Q10/INDEX($O$93:$X$100,MATCH(T10,$N$93:$N$100,0),MATCH(S10,$O$92:$X$92,0))*0.75,P10) -> #N/A | V10: 3 | W10: 6 | X10: =MROUND(Q10/INDEX($O$93:$X$100,MATCH(T10,$N$93:$N$100,0),MATCH(S10,$O$92:$X$92,0))*0.86,P10) -> #N/A | Y10: 3 | Z10: 3 | AA10: ='Программа тренировок '!M154 | AB10: =MROUND(X10/INDEX($O$93:$X$100,MATCH(AA10,$N$93:$N$100,0),MATCH(Z10,$O$92:$X$92,0))*0.8,P10) -> #N/A | AC10: 3 | AD10: 5 | AE10: =MROUND(X10/INDEX($O$93:$X$100,MATCH(AA10,$N$93:$N$100,0),MATCH(Z10,$O$92:$X$92,0))*0.9,P10) -> #N/A | AF10: 3 | AG10: 3 | AH10: ='Программа тренировок '!T154 | AI10: =MROUND(AE10/INDEX($O$93:$X$100,MATCH(AH10,$N$93:$N$100,0),MATCH(AG10,$O$92:$X$92,0))*0.85,P10) -> #N/A | AJ10: 3 | AK10: 4 | AL10: =MROUND(AE10/INDEX($O$93:$X$100,MATCH(AH10,$N$93:$N$100,0),MATCH(AG10,$O$92:$X$92,0))*0.86,P10) -> #N/A | AM10: 3 | AN10: 2 | AO10: ='Программа тренировок '!F181 | AP10: =MROUND(AL10/INDEX($O$93:$X$100,MATCH(AO10,$N$93:$N$100,0),MATCH(AN10,$O$92:$X$92,0))*0.79,P10) -> #N/A | AQ10: 3 | AR10: 5 | AS10: =MROUND(AL10/INDEX($O$93:$X$100,MATCH(AO10,$N$93:$N$100,0),MATCH(AN10,$O$92:$X$92,0))*0.89,P10) -> #N/A | AT10: 3 | AU10: 2 | AV10: ='Программа тренировок '!M181 | AW10: =MROUND(AS10/INDEX($O$93:$X$100,MATCH(AV10,$N$93:$N$100,0),MATCH(AU10,$O$92:$X$92,0))*0.82,P10) -> #N/A | AX10: 3 | AY10: 4 | AZ10: =MROUND(AS10/INDEX($O$93:$X$100,MATCH(AV10,$N$93:$N$100,0),MATCH(AU10,$O$92:$X$92,0))*0.92,P10) -> #N/A | BA10: 3 | BB10: 2 | BC10: ='Программа тренировок '!T181 | BD10: =MROUND(AZ10/INDEX($O$93:$X$100,MATCH(BC10,$N$93:$N$100,0),MATCH(BB10,$O$92:$X$92,0))*0.86,P10) -> #N/A | BE10: 3 | BF10: 3 | BG10: =MROUND(AZ10/INDEX($O$93:$X$100,MATCH(BC10,$N$93:$N$100,0),MATCH(BB10,$O$92:$X$92,0))*0.91,P10) -> #N/A | BH10: 3 | BI10: 1 | BJ10: ='Программа тренировок '!F208 | BK10: =MROUND(BG10/INDEX($O$93:$X$100,MATCH(BJ10,$N$93:$N$100,0),MATCH(BI10,$O$92:$X$92,0))*0.81,P10) -> #N/A | BL10: 3 | BM10: 4 | BN10: =MROUND(BG10/INDEX($O$93:$X$100,MATCH(BJ10,$N$93:$N$100,0),MATCH(BI10,$O$92:$X$92,0))*0.94,P10) -> #N/A | BO10: 3 | BP10: 1 | BQ10: ='Программа тренировок '!M208 | BR10: =MROUND(BN10/INDEX($O$93:$X$100,MATCH(BQ10,$N$93:$N$100,0),MATCH(BP10,$O$92:$X$92,0))*0.84,P10) -> #N/A | BS10: 3 | BT10: 3 | BU10: =MROUND(BN10/INDEX($O$93:$X$100,MATCH(BQ10,$N$93:$N$100,0),MATCH(BP10,$O$92:$X$92,0))*0.97,P10) -> #N/A | BV10: 3 | BW10: 1 | BX10: ='Программа тренировок '!T208 | BY10: =MROUND(BU10/INDEX($O$93:$X$100,MATCH(BX10,$N$93:$N$100,0),MATCH(BW10,$O$92:$X$92,0))*0.89,P10) -> #N/A | BZ10: 3 | CA10: 2
I11: ='Программа тренировок '!E77 -> 2.5 | L11: Жим штанги лёжа на наклонной скамье | N11: ='Программа тренировок '!C111 | O11: ='Программа тренировок '!D111 | P11: ='Формулы'!I11 -> 2.5 | Q11: {=MROUND(N11/INDEX($O$93:$X$100,MATCH(10,$N$93:$N$100,0),MATCH(O11,$O$92:$X$92,0))*0.8,P11)} -> #N/A | R11: =IF('Программа тренировок '!B111='Программа тренировок '!B121, 1, 3) -> 1 | S11: 5 | T11: ='Программа тренировок '!F154 | U11: =MROUND(Q11/INDEX($O$93:$X$100,MATCH(T11,$N$93:$N$100,0),MATCH(S11,$O$92:$X$92,0))*0.75,P11) -> #N/A | V11: 3 | W11: 6 | X11: {=MROUND(Q11/INDEX($O$93:$X$100,MATCH(T11,$N$93:$N$100,0),MATCH(S11,$O$92:$X$92,0))*0.84,P11)} -> #N/A | Y11: =IF('Программа тренировок '!B111='Программа тренировок '!B121, 1, 3) -> 1 | Z11: 4 | AA11: ='Программа тренировок '!M154 | AB11: =MROUND(X11/INDEX($O$93:$X$100,MATCH(AA11,$N$93:$N$100,0),MATCH(Z11,$O$92:$X$92,0))*0.8,P11) -> #N/A | AC11: 3 | AD11: 5 | AE11: {=MROUND(X11/INDEX($O$93:$X$100,MATCH(AA11,$N$93:$N$100,0),MATCH(Z11,$O$92:$X$92,0))*0.88,P11)} -> #N/A | AF11: =IF('Программа тренировок '!B111='Программа тренировок '!B121, 1, 3) -> 1 | AG11: 3 | AH11: ='Программа тренировок '!T154 | AI11: =MROUND(AE11/INDEX($O$93:$X$100,MATCH(AH11,$N$93:$N$100,0),MATCH(AG11,$O$92:$X$92,0))*0.85,P11) -> #N/A | AJ11: 3 | AK11: 4 | AL11: {=MROUND(AE11/INDEX($O$93:$X$100,MATCH(AH11,$N$93:$N$100,0),MATCH(AG11,$O$92:$X$92,0))*0.82,P11)} -> #N/A | AM11: =IF('Программа тренировок '!B111='Программа тренировок '!B121, 1, 3) -> 1 | AN11: 4 | AO11: ='Программа тренировок '!F181 | AP11: =MROUND(AL11/INDEX($O$93:$X$100,MATCH(AO11,$N$93:$N$100,0),MATCH(AN11,$O$92:$X$92,0))*0.79,P11) -> #N/A | AQ11: 3 | AR11: 5 | AS11: {=MROUND(AL11/INDEX($O$93:$X$100,MATCH(AO11,$N$93:$N$100,0),MATCH(AN11,$O$92:$X$92,0))*0.86,P11)} -> #N/A | AT11: =IF('Программа тренировок '!B111='Программа тренировок '!B121, 1, 3) -> 1 | AU11: 3 | AV11: ='Программа тренировок '!M181 | AW11: =MROUND(AS11/INDEX($O$93:$X$100,MATCH(AV11,$N$93:$N$100,0),MATCH(AU11,$O$92:$X$92,0))*0.82,P11) -> #N/A | AX11: 3 | AY11: 4 | AZ11: =MROUND(AS11/INDEX($O$93:$X$100,MATCH(AV11,$N$93:$N$100,0),MATCH(AU11,$O$92:$X$92,0))*0.92,P11) -> #N/A | BA11: =IF('Программа тренировок '!B111='Программа тренировок '!B121, 1, 3) -> 1 | BB11: 2 | BC11: ='Программа тренировок '!T181 | BD11: =MROUND(AZ11/INDEX($O$93:$X$100,MATCH(BC11,$N$93:$N$100,0),MATCH(BB11,$O$92:$X$92,0))*0.86,P11) -> #N/A | BE11: 3 | BF11: 3 | BG11: {=MROUND(AZ11/INDEX($O$93:$X$100,MATCH(BC11,$N$93:$N$100,0),MATCH(BB11,$O$92:$X$92,0))*0.81,P11)} -> #N/A | BH11: =IF('Программа тренировок '!B111='Программа тренировок '!B121, 1, 3) -> 1 | BI11: 3 | BJ11: ='Программа тренировок '!F208 | BK11: =MROUND(BG11/INDEX($O$93:$X$100,MATCH(BJ11,$N$93:$N$100,0),MATCH(BI11,$O$92:$X$92,0))*0.81,P11) -> #N/A | BL11: 3 | BM11: 4 | BN11: {=MROUND(BG11/INDEX($O$93:$X$100,MATCH(BJ11,$N$93:$N$100,0),MATCH(BI11,$O$92:$X$92,0))*0.89,P11)} -> #N/A | BO11: =IF('Программа тренировок '!B111='Программа тренировок '!B121, 1, 3) -> 1 | BP11: 2 | BQ11: ='Программа тренировок '!M208 | BR11: =MROUND(BN11/INDEX($O$93:$X$100,MATCH(BQ11,$N$93:$N$100,0),MATCH(BP11,$O$92:$X$92,0))*0.84,P11) -> #N/A | BS11: 3 | BT11: 3 | BU11: =MROUND(BN11/INDEX($O$93:$X$100,MATCH(BQ11,$N$93:$N$100,0),MATCH(BP11,$O$92:$X$92,0))*0.97,P11) -> #N/A | BV11: =IF('Программа тренировок '!B111='Программа тренировок '!B121, 1, 3) -> 1 | BW11: 1 | BX11: ='Программа тренировок '!T208 | BY11: =MROUND(BU11/INDEX($O$93:$X$100,MATCH(BX11,$N$93:$N$100,0),MATCH(BW11,$O$92:$X$92,0))*0.89,P11) -> #N/A | BZ11: 3 | CA11: 2
I12: ='Программа тренировок '!E78 -> 2.5
I13: ='Программа тренировок '!E79 -> 5 | L13: Подтягивания (с отягощением) | N13: ='Программа тренировок '!C112 | O13: ='Программа тренировок '!D112 | P13: ='Формулы'!I12 -> 2.5 | Q13: {=MROUND(N13/INDEX($O$93:$X$100,MATCH(10,$N$93:$N$100,0),MATCH(O13,$O$92:$X$92,0))*0.83,P13)} -> #N/A | R13: 3 | S13: 3 | T13: ='Программа тренировок '!F155 | U13: {=MROUND(Q13/INDEX($O$93:$X$100,MATCH(T13,$N$93:$N$100,0),MATCH(S13,$O$92:$X$92,0))*0.75,P13)} -> #N/A | V13: 3 | W13: 6 | X13: {=MROUND(Q13/INDEX($O$93:$X$100,MATCH(T13,$N$93:$N$100,0),MATCH(S13,$O$92:$X$92,0))*0.86,P13)} -> #N/A | Y13: 3 | Z13: 3 | AA13: ='Программа тренировок '!M155 | AB13: {=MROUND(X13/INDEX($O$93:$X$100,MATCH(AA13,$N$93:$N$100,0),MATCH(Z13,$O$92:$X$92,0))*0.8,P13)} -> #N/A | AC13: 3 | AD13: 5 | AE13: {=MROUND(X13/INDEX($O$93:$X$100,MATCH(AA13,$N$93:$N$100,0),MATCH(Z13,$O$92:$X$92,0))*0.9,P13)} -> #N/A | AF13: 3 | AG13: 3 | AH13: ='Программа тренировок '!T155 | AI13: {=MROUND(AE13/INDEX($O$93:$X$100,MATCH(AH13,$N$93:$N$100,0),MATCH(AG13,$O$92:$X$92,0))*0.85,P13)} -> #N/A | AJ13: 3 | AK13: 4 | AL13: {=MROUND(AE13/INDEX($O$93:$X$100,MATCH(AH13,$N$93:$N$100,0),MATCH(AG13,$O$92:$X$92,0))*0.86,P13)} -> #N/A | AM13: 3 | AN13: 2 | AO13: ='Программа тренировок '!F182 | AP13: {=MROUND(AL13/INDEX($O$93:$X$100,MATCH(AO13,$N$93:$N$100,0),MATCH(AN13,$O$92:$X$92,0))*0.79,P13)} -> #N/A | AQ13: 3 | AR13: 5 | AS13: {=MROUND(AL13/INDEX($O$93:$X$100,MATCH(AO13,$N$93:$N$100,0),MATCH(AN13,$O$92:$X$92,0))*0.89,P13)} -> #N/A | AT13: 3 | AU13: 2 | AV13: ='Программа тренировок '!M182 | AW13: {=MROUND(AS13/INDEX($O$93:$X$100,MATCH(AV13,$N$93:$N$100,0),MATCH(AU13,$O$92:$X$92,0))*0.82,P13)} -> #N/A | AX13: 3 | AY13: 4 | AZ13: {=MROUND(AS13/INDEX($O$93:$X$100,MATCH(AV13,$N$93:$N$100,0),MATCH(AU13,$O$92:$X$92,0))*0.92,P13)} -> #N/A | BA13: 3 | BB13: 2 | BC13: ='Программа тренировок '!T182 | BD13: {=MROUND(AZ13/INDEX($O$93:$X$100,MATCH(BC13,$N$93:$N$100,0),MATCH(BB13,$O$92:$X$92,0))*0.86,P13)} -> #N/A | BE13: 3 | BF13: 3 | BG13: {=MROUND(AZ13/INDEX($O$93:$X$100,MATCH(BC13,$N$93:$N$100,0),MATCH(BB13,$O$92:$X$92,0))*0.91,P13)} -> #N/A | BH13: 3 | BI13: 1 | BJ13: ='Программа тренировок '!F209 | BK13: {=MROUND(BG13/INDEX($O$93:$X$100,MATCH(BJ13,$N$93:$N$100,0),MATCH(BI13,$O$92:$X$92,0))*0.81,P13)} -> #N/A | BL13: 3 | BM13: 4 | BN13: {=MROUND(BG13/INDEX($O$93:$X$100,MATCH(BJ13,$N$93:$N$100,0),MATCH(BI13,$O$92:$X$92,0))*0.94,P13)} -> #N/A | BO13: 3 | BP13: 1 | BQ13: ='Программа тренировок '!M209 | BR13: {=MROUND(BN13/INDEX($O$93:$X$100,MATCH(BQ13,$N$93:$N$100,0),MATCH(BP13,$O$92:$X$92,0))*0.84,P13)} -> #N/A | BS13: 3 | BT13: 3 | BU13: {=MROUND(BN13/INDEX($O$93:$X$100,MATCH(BQ13,$N$93:$N$100,0),MATCH(BP13,$O$92:$X$92,0))*0.97,P13)} -> #N/A | BV13: 3 | BW13: 1 | BX13: ='Программа тренировок '!T209 | BY13: {=MROUND(BU13/INDEX($O$93:$X$100,MATCH(BX13,$N$93:$N$100,0),MATCH(BW13,$O$92:$X$92,0))*0.89,P13)} -> #N/A | BZ13: 3 | CA13: 2
I14: ='Программа тренировок '!E80 -> 1 | L14: Подтягивания (собственный вес) | N14: ='Программа тренировок '!C112 | O14: 8 | P14: ='Формулы'!I12 -> 2.5 | Q14: собств. | R14: 1 | S14: =O14-2 -> 6 | T14: ='Программа тренировок '!F155 | U14: собств. | V14: 4 | W14: =FLOOR((10-T14+S14)-3,1) -> 13 | X14: собств. | Y14: 1 | Z14: =FLOOR((10-T14+S14)-1,1) -> 15 | AA14: ='Программа тренировок '!M155 | AB14: собств. | AC14: 4 | AD14: =FLOOR((10-AA14+Z14)-2,1) -> 23 | AE14: собств. | AF14: 1 | AG14: =FLOOR((10-AA14+Z14),1) -> 25 | AH14: ='Программа тренировок '!T155 | AI14: собств. | AJ14: 3 | AK14: =FLOOR((10-AH14+AG14)-2,1) -> 33 | AL14: собств. | AM14: 1 | AN14: =FLOOR((10-AH14+AG14)-2,1) -> 33 | AO14: ='Программа тренировок '!F182 | AP14: собств. | AQ14: 4 | AR14: =FLOOR((10-AO14+AN14)-3,1) -> 40 | AS14: собств. | AT14: 1 | AU14: =FLOOR((10-AO14+AN14)-1,1) -> 42 | AV14: ='Программа тренировок '!M182 | AW14: собств. | AX14: 4 | AY14: =FLOOR((10-AV14+AU14)-2,1) -> 50 | AZ14: собств. | BA14: 1 | BB14: =FLOOR((10-AV14+AU14),1) -> 52 | BC14: ='Программа тренировок '!T182 | BD14: собств. | BE14: 3 | BF14: =FLOOR((10-BC14+BB14)-2,1) -> 60 | BG14: собств. | BH14: 1 | BI14: =FLOOR((10-BC14+BB14)-2,1) -> 60 | BJ14: ='Программа тренировок '!F209 | BK14: собств. | BL14: 4 | BM14: =FLOOR((10-BJ14+BI14)-3,1) -> 67 | BN14: собств. | BO14: 1 | BP14: =FLOOR((10-BJ14+BI14)-1,1) -> 69 | BQ14: ='Программа тренировок '!M209 | BR14: собств. | BS14: 3 | BT14: =FLOOR((10-BQ14+BP14)-2,1) -> 77 | BU14: собств. | BV14: 1 | BW14: =FLOOR((10-BQ14+BP14),1) -> 79 | BX14: ='Программа тренировок '!T209 | BY14: собств. | BZ14: 3 | CA14: =FLOOR((10-BQ14+BP14)-2,1) -> 77
L15: Тяга вертикального блока | N15: ='Программа тренировок '!C112 | O15: ='Программа тренировок '!D112 | P15: ='Формулы'!I12 -> 2.5 | Q15: {=MROUND(N15/INDEX($O$93:$X$100,MATCH(10,$N$93:$N$100,0),MATCH(O15,$O$92:$X$92,0))*0.8,P15)} -> #N/A | R15: 3 | S15: 5 | T15: ='Программа тренировок '!F155 | U15: {=MROUND(Q15/INDEX($O$93:$X$100,MATCH(T15,$N$93:$N$100,0),MATCH(S15,$O$92:$X$92,0))*0.75,P15)} -> #N/A | V15: 3 | W15: 6 | X15: {=MROUND(Q15/INDEX($O$93:$X$100,MATCH(T15,$N$93:$N$100,0),MATCH(S15,$O$92:$X$92,0))*0.82,P15)} -> #N/A | Y15: 3 | Z15: 5 | AA15: ='Программа тренировок '!M155 | AB15: {=MROUND(X15/INDEX($O$93:$X$100,MATCH(AA15,$N$93:$N$100,0),MATCH(Z15,$O$92:$X$92,0))*0.77,P15)} -> #N/A | AC15: 3 | AD15: 6 | AE15: {=MROUND(X15/INDEX($O$93:$X$100,MATCH(AA15,$N$93:$N$100,0),MATCH(Z15,$O$92:$X$92,0))*0.85,P15)} -> #N/A | AF15: 3 | AG15: 5 | AH15: ='Программа тренировок '!T155 | AI15: {=MROUND(AE15/INDEX($O$93:$X$100,MATCH(AH15,$N$93:$N$100,0),MATCH(AG15,$O$92:$X$92,0))*0.79,P15)} -> #N/A | AJ15: 3 | AK15: 6 | AL15: {=MROUND(AE15/INDEX($O$93:$X$100,MATCH(AH15,$N$93:$N$100,0),MATCH(AG15,$O$92:$X$92,0))*0.82,P15)} -> #N/A | AM15: 3 | AN15: 4 | AO15: ='Программа тренировок '!F182 | AP15: {=MROUND(AL15/INDEX($O$93:$X$100,MATCH(AO15,$N$93:$N$100,0),MATCH(AN15,$O$92:$X$92,0))*0.79,P15)} -> #N/A | AQ15: 3 | AR15: 5 | AS15: {=MROUND(AL15/INDEX($O$93:$X$100,MATCH(AO15,$N$93:$N$100,0),MATCH(AN15,$O$92:$X$92,0))*0.85,P15)} -> #N/A | AT15: 3 | AU15: 4 | AV15: ='Программа тренировок '!M182 | AW15: {=MROUND(AS15/INDEX($O$93:$X$100,MATCH(AV15,$N$93:$N$100,0),MATCH(AU15,$O$92:$X$92,0))*0.8,P15)} -> #N/A | AX15: 3 | AY15: 5 | AZ15: {=MROUND(AS15/INDEX($O$93:$X$100,MATCH(AV15,$N$93:$N$100,0),MATCH(AU15,$O$92:$X$92,0))*0.88,P15)} -> #N/A | BA15: 3 | BB15: 4 | BC15: ='Программа тренировок '!T182 | BD15: {=MROUND(AZ15/INDEX($O$93:$X$100,MATCH(BC15,$N$93:$N$100,0),MATCH(BB15,$O$92:$X$92,0))*0.81,P15)} -> #N/A | BE15: 3 | BF15: 5 | BG15: {=MROUND(AZ15/INDEX($O$93:$X$100,MATCH(BC15,$N$93:$N$100,0),MATCH(BB15,$O$92:$X$92,0))*0.83,P15)} -> #N/A | BH15: 3 | BI15: 3 | BJ15: ='Программа тренировок '!F209 | BK15: {=MROUND(BG15/INDEX($O$93:$X$100,MATCH(BJ15,$N$93:$N$100,0),MATCH(BI15,$O$92:$X$92,0))*0.81,P15)} -> #N/A | BL15: 3 | BM15: 4 | BN15: {=MROUND(BG15/INDEX($O$93:$X$100,MATCH(BJ15,$N$93:$N$100,0),MATCH(BI15,$O$92:$X$92,0))*0.86,P15)} -> #N/A | BO15: 3 | BP15: 3 | BQ15: ='Программа тренировок '!M209 | BR15: {=MROUND(BN15/INDEX($O$93:$X$100,MATCH(BQ15,$N$93:$N$100,0),MATCH(BP15,$O$92:$X$92,0))*0.82,P15)} -> #N/A | BS15: 3 | BT15: 4 | BU15: {=MROUND(BN15/INDEX($O$93:$X$100,MATCH(BQ15,$N$93:$N$100,0),MATCH(BP15,$O$92:$X$92,0))*0.91,P15)} -> #N/A | BV15: 3 | BW15: 3 | BX15: ='Программа тренировок '!T209 | BY15: {=MROUND(BU15/INDEX($O$93:$X$100,MATCH(BX15,$N$93:$N$100,0),MATCH(BW15,$O$92:$X$92,0))*0.84,P15)} -> #N/A | BZ15: 3 | CA15: 4
L17: Приседания со штангой | N17: =IF('Программа тренировок '!B127='Программа тренировок '!B113,'Программа тренировок '!C113,'Программа тренировок '!C127) | O17: =IF('Программа тренировок '!B127='Программа тренировок '!B113,O54,'Программа тренировок '!D127) | P17: =IF('Программа тренировок '!B132='Программа тренировок '!B118,P54,'Формулы'!I27) -> 2.5 | Q17: {=MROUND(N17/INDEX($O$93:$X$100,MATCH(10,$N$93:$N$100,0),MATCH(O17,$O$92:$X$92,0))*0.83,P17)} -> #N/A | R17: =IF('Программа тренировок '!B93='Программа тренировок '!B79, 1, 3) -> 3 | S17: 3 | T17: ='Программа тренировок '!F170 | U17: =MROUND(Q17/INDEX($O$93:$X$100,MATCH(T17,$N$93:$N$100,0),MATCH(S17,$O$92:$X$92,0))*0.75,P17) -> #N/A | V17: 3 | W17: 6 | X17: {=MROUND(Q17/INDEX($O$93:$X$100,MATCH(T17,$N$93:$N$100,0),MATCH(S17,$O$92:$X$92,0))*0.86,P17)} -> #N/A | Y17: =IF('Программа тренировок '!B93='Программа тренировок '!B79, 1, 3) -> 3 | Z17: 3 | AA17: ='Программа тренировок '!M170 | AB17: {=MROUND(X17/INDEX($O$93:$X$100,MATCH(AA17,$N$93:$N$100,0),MATCH(Z17,$O$92:$X$92,0))*0.8,P17)} -> #N/A | AC17: 3 | AD17: 5 | AE17: {=MROUND(X17/INDEX($O$93:$X$100,MATCH(AA17,$N$93:$N$100,0),MATCH(Z17,$O$92:$X$92,0))*0.9,P17)} -> #N/A | AF17: =IF('Программа тренировок '!B93='Программа тренировок '!B79, 1, 3) -> 3 | AG17: 3 | AH17: ='Программа тренировок '!T170 | AI17: {=MROUND(AE17/INDEX($O$93:$X$100,MATCH(AH17,$N$93:$N$100,0),MATCH(AG17,$O$92:$X$92,0))*0.85,P17)} -> #N/A | AJ17: 3 | AK17: 4 | AL17: {=MROUND(AE17/INDEX($O$93:$X$100,MATCH(AH17,$N$93:$N$100,0),MATCH(AG17,$O$92:$X$92,0))*0.86,P17)} -> #N/A | AM17: =IF('Программа тренировок '!B93='Программа тренировок '!B79, 1, 3) -> 3 | AN17: 2 | AO17: ='Программа тренировок '!F197 | AP17: =MROUND(AL17/INDEX($O$93:$X$100,MATCH(AO17,$N$93:$N$100,0),MATCH(AN17,$O$92:$X$92,0))*0.79,P17) -> #N/A | AQ17: 3 | AR17: 5 | AS17: {=MROUND(AL17/INDEX($O$93:$X$100,MATCH(AO17,$N$93:$N$100,0),MATCH(AN17,$O$92:$X$92,0))*0.89,P17)} -> #N/A | AT17: =IF('Программа тренировок '!B93='Программа тренировок '!B79, 1, 3) -> 3 | AU17: 2 | AV17: ='Программа тренировок '!M197 | AW17: {=MROUND(AS17/INDEX($O$93:$X$100,MATCH(AV17,$N$93:$N$100,0),MATCH(AU17,$O$92:$X$92,0))*0.82,P17)} -> #N/A | AX17: 3 | AY17: 4 | AZ17: {=MROUND(AS17/INDEX($O$93:$X$100,MATCH(AV17,$N$93:$N$100,0),MATCH(AU17,$O$92:$X$92,0))*0.92,P17)} -> #N/A | BA17: =IF('Программа тренировок '!B93='Программа тренировок '!B79, 1, 3) -> 3 | BB17: 2 | BC17: ='Программа тренировок '!T197 | BD17: {=MROUND(AZ17/INDEX($O$93:$X$100,MATCH(BC17,$N$93:$N$100,0),MATCH(BB17,$O$92:$X$92,0))*0.86,P17)} -> #N/A | BE17: 3 | BF17: 3 | BG17: {=MROUND(AZ17/INDEX($O$93:$X$100,MATCH(BC17,$N$93:$N$100,0),MATCH(BB17,$O$92:$X$92,0))*0.91,P17)} -> #N/A | BH17: =IF('Программа тренировок '!B93='Программа тренировок '!B79, 1, 3) -> 3 | BI17: 1 | BJ17: ='Программа тренировок '!F224 | BK17: =MROUND(BG17/INDEX($O$93:$X$100,MATCH(BJ17,$N$93:$N$100,0),MATCH(BI17,$O$92:$X$92,0))*0.81,P17) -> #N/A | BL17: 3 | BM17: 4 | BN17: {=MROUND(BG17/INDEX($O$93:$X$100,MATCH(BJ17,$N$93:$N$100,0),MATCH(BI17,$O$92:$X$92,0))*0.94,P17)} -> #N/A | BO17: =IF('Программа тренировок '!B93='Программа тренировок '!B79, 1, 3) -> 3 | BP17: 1 | BQ17: ='Программа тренировок '!M224 | BR17: {=MROUND(BN17/INDEX($O$93:$X$100,MATCH(BQ17,$N$93:$N$100,0),MATCH(BP17,$O$92:$X$92,0))*0.84,P17)} -> #N/A | BS17: 3 | BT17: 3 | BU17: {=MROUND(BN17/INDEX($O$93:$X$100,MATCH(BQ17,$N$93:$N$100,0),MATCH(BP17,$O$92:$X$92,0))*0.97,P17)} -> #N/A | BV17: =IF('Программа тренировок '!B93='Программа тренировок '!B79, 1, 3) -> 3 | BW17: 1 | BX17: ='Программа тренировок '!T224 | BY17: {=MROUND(BU17/INDEX($O$93:$X$100,MATCH(BX17,$N$93:$N$100,0),MATCH(BW17,$O$92:$X$92,0))*0.89,P17)} -> #N/A | BZ17: 3 | CA17: 2
I18: Округлить до↓ | L18: Приседания в колодец | N18: ='Программа тренировок '!C127 | O18: ='Программа тренировок '!D127 | P18: ='Формулы'!I27 -> 2.5 | Q18: =MROUND(N18/INDEX($O$93:$X$100,MATCH(10,$N$93:$N$100,0),MATCH(O18,$O$92:$X$92,0))*0.8,P18) -> #N/A | R18: 3 | S18: 5 | T18: ='Программа тренировок '!F170 | U18: =MROUND(Q18/INDEX($O$93:$X$100,MATCH(T18,$N$93:$N$100,0),MATCH(S18,$O$92:$X$92,0))*0.75,P18) -> #N/A | V18: 3 | W18: 6 | X18: =MROUND(Q18/INDEX($O$93:$X$100,MATCH(T18,$N$93:$N$100,0),MATCH(S18,$O$92:$X$92,0))*0.82,P18) -> #N/A | Y18: 3 | Z18: 5 | AA18: ='Программа тренировок '!M170 | AB18: =MROUND(X18/INDEX($O$93:$X$100,MATCH(AA18,$N$93:$N$100,0),MATCH(Z18,$O$92:$X$92,0))*0.77,P18) -> #N/A | AC18: 3 | AD18: 6 | AE18: =MROUND(X18/INDEX($O$93:$X$100,MATCH(AA18,$N$93:$N$100,0),MATCH(Z18,$O$92:$X$92,0))*0.85,P18) -> #N/A | AF18: 3 | AG18: 5 | AH18: ='Программа тренировок '!T170 | AI18: =MROUND(AE18/INDEX($O$93:$X$100,MATCH(AH18,$N$93:$N$100,0),MATCH(AG18,$O$92:$X$92,0))*0.79,P18) -> #N/A | AJ18: 3 | AK18: 6 | AL18: =MROUND(AE18/INDEX($O$93:$X$100,MATCH(AH18,$N$93:$N$100,0),MATCH(AG18,$O$92:$X$92,0))*0.82,P18) -> #N/A | AM18: 3 | AN18: 4 | AO18: ='Программа тренировок '!F197 | AP18: =MROUND(AL18/INDEX($O$93:$X$100,MATCH(AO18,$N$93:$N$100,0),MATCH(AN18,$O$92:$X$92,0))*0.79,P18) -> #N/A | AQ18: 3 | AR18: 5 | AS18: =MROUND(AL18/INDEX($O$93:$X$100,MATCH(AO18,$N$93:$N$100,0),MATCH(AN18,$O$92:$X$92,0))*0.85,P18) -> #N/A | AT18: 3 | AU18: 4 | AV18: ='Программа тренировок '!M197 | AW18: =MROUND(AS18/INDEX($O$93:$X$100,MATCH(AV18,$N$93:$N$100,0),MATCH(AU18,$O$92:$X$92,0))*0.8,P18) -> #N/A | AX18: 3 | AY18: 5 | AZ18: =MROUND(AS18/INDEX($O$93:$X$100,MATCH(AV18,$N$93:$N$100,0),MATCH(AU18,$O$92:$X$92,0))*0.88,P18) -> #N/A | BA18: 3 | BB18: 4 | BC18: ='Программа тренировок '!T197 | BD18: =MROUND(AZ18/INDEX($O$93:$X$100,MATCH(BC18,$N$93:$N$100,0),MATCH(BB18,$O$92:$X$92,0))*0.81,P18) -> #N/A | BE18: 3 | BF18: 5 | BG18: =MROUND(AZ18/INDEX($O$93:$X$100,MATCH(BC18,$N$93:$N$100,0),MATCH(BB18,$O$92:$X$92,0))*0.83,P18) -> #N/A | BH18: 3 | BI18: 3 | BJ18: ='Программа тренировок '!F224 | BK18: =MROUND(BG18/INDEX($O$93:$X$100,MATCH(BJ18,$N$93:$N$100,0),MATCH(BI18,$O$92:$X$92,0))*0.81,P18) -> #N/A | BL18: 3 | BM18: 4 | BN18: =MROUND(BG18/INDEX($O$93:$X$100,MATCH(BJ18,$N$93:$N$100,0),MATCH(BI18,$O$92:$X$92,0))*0.86,P18) -> #N/A | BO18: 3 | BP18: 3 | BQ18: ='Программа тренировок '!M224 | BR18: =MROUND(BN18/INDEX($O$93:$X$100,MATCH(BQ18,$N$93:$N$100,0),MATCH(BP18,$O$92:$X$92,0))*0.82,P18) -> #N/A | BS18: 3 | BT18: 4 | BU18: =MROUND(BN18/INDEX($O$93:$X$100,MATCH(BQ18,$N$93:$N$100,0),MATCH(BP18,$O$92:$X$92,0))*0.91,P18) -> #N/A | BV18: 3 | BW18: 3 | BX18: ='Программа тренировок '!T224 | BY18: =MROUND(BU18/INDEX($O$93:$X$100,MATCH(BX18,$N$93:$N$100,0),MATCH(BW18,$O$92:$X$92,0))*0.84,P18) -> #N/A | BZ18: 3 | CA18: 4
I19: ='Программа тренировок '!E85 -> 2.5 | L19: Ягодичный мост | N19: =IF('Программа тренировок '!B119='Программа тренировок '!B127,'Программа тренировок '!C119,'Программа тренировок '!C127) | O19: =IF('Программа тренировок '!B119='Программа тренировок '!B127,'Программа тренировок '!D119,'Программа тренировок '!D127) | P19: =IF('Программа тренировок '!B124='Программа тренировок '!B132,'Формулы'!I19,'Формулы'!I27) -> 2.5 | Q19: =MROUND(N19/INDEX($O$93:$X$100,MATCH(10,$N$93:$N$100,0),MATCH(O19,$O$92:$X$92,0))*0.8,P19) -> #N/A | R19: =IF('Программа тренировок '!B127='Программа тренировок '!B119, 1, 3) -> 3 | S19: 5 | T19: ='Программа тренировок '!F170 | U19: =MROUND(Q19/INDEX($O$93:$X$100,MATCH(T19,$N$93:$N$100,0),MATCH(S19,$O$92:$X$92,0))*0.75,P19) -> #N/A | V19: 3 | W19: 6 | X19: =MROUND(Q19/INDEX($O$93:$X$100,MATCH(T19,$N$93:$N$100,0),MATCH(S19,$O$92:$X$92,0))*0.82,P19) -> #N/A | Y19: =IF('Программа тренировок '!B127='Программа тренировок '!B119, 1, 3) -> 3 | Z19: 5 | AA19: ='Программа тренировок '!M170 | AB19: =MROUND(X19/INDEX($O$93:$X$100,MATCH(AA19,$N$93:$N$100,0),MATCH(Z19,$O$92:$X$92,0))*0.77,P19) -> #N/A | AC19: 3 | AD19: 6 | AE19: =MROUND(X19/INDEX($O$93:$X$100,MATCH(AA19,$N$93:$N$100,0),MATCH(Z19,$O$92:$X$92,0))*0.85,P19) -> #N/A | AF19: =IF('Программа тренировок '!B127='Программа тренировок '!B119, 1, 3) -> 3 | AG19: 5 | AH19: ='Программа тренировок '!T170 | AI19: =MROUND(AE19/INDEX($O$93:$X$100,MATCH(AH19,$N$93:$N$100,0),MATCH(AG19,$O$92:$X$92,0))*0.79,P19) -> #N/A | AJ19: 3 | AK19: 6 | AL19: =MROUND(AE19/INDEX($O$93:$X$100,MATCH(AH19,$N$93:$N$100,0),MATCH(AG19,$O$92:$X$92,0))*0.82,P19) -> #N/A | AM19: =IF('Программа тренировок '!B127='Программа тренировок '!B119, 1, 3) -> 3 | AN19: 4 | AO19: ='Программа тренировок '!F197 | AP19: =MROUND(AL19/INDEX($O$93:$X$100,MATCH(AO19,$N$93:$N$100,0),MATCH(AN19,$O$92:$X$92,0))*0.79,P19) -> #N/A | AQ19: 3 | AR19: 5 | AS19: =MROUND(AL19/INDEX($O$93:$X$100,MATCH(AO19,$N$93:$N$100,0),MATCH(AN19,$O$92:$X$92,0))*0.85,P19) -> #N/A | AT19: =IF('Программа тренировок '!B127='Программа тренировок '!B119, 1, 3) -> 3 | AU19: 4 | AV19: ='Программа тренировок '!M197 | AW19: =MROUND(AS19/INDEX($O$93:$X$100,MATCH(AV19,$N$93:$N$100,0),MATCH(AU19,$O$92:$X$92,0))*0.8,P19) -> #N/A | AX19: 3 | AY19: 5 | AZ19: =MROUND(AS19/INDEX($O$93:$X$100,MATCH(AV19,$N$93:$N$100,0),MATCH(AU19,$O$92:$X$92,0))*0.88,P19) -> #N/A | BA19: =IF('Программа тренировок '!B127='Программа тренировок '!B119, 1, 3) -> 3 | BB19: 4 | BC19: ='Программа тренировок '!T197 | BD19: =MROUND(AZ19/INDEX($O$93:$X$100,MATCH(BC19,$N$93:$N$100,0),MATCH(BB19,$O$92:$X$92,0))*0.81,P19) -> #N/A | BE19: 3 | BF19: 5 | BG19: =MROUND(AZ19/INDEX($O$93:$X$100,MATCH(BC19,$N$93:$N$100,0),MATCH(BB19,$O$92:$X$92,0))*0.83,P19) -> #N/A | BH19: =IF('Программа тренировок '!B127='Программа тренировок '!B119, 1, 3) -> 3 | BI19: 3 | BJ19: ='Программа тренировок '!F224 | BK19: =MROUND(BG19/INDEX($O$93:$X$100,MATCH(BJ19,$N$93:$N$100,0),MATCH(BI19,$O$92:$X$92,0))*0.81,P19) -> #N/A | BL19: 3 | BM19: 4 | BN19: =MROUND(BG19/INDEX($O$93:$X$100,MATCH(BJ19,$N$93:$N$100,0),MATCH(BI19,$O$92:$X$92,0))*0.86,P19) -> #N/A | BO19: =IF('Программа тренировок '!B127='Программа тренировок '!B119, 1, 3) -> 3 | BP19: 3 | BQ19: ='Программа тренировок '!M224 | BR19: =MROUND(BN19/INDEX($O$93:$X$100,MATCH(BQ19,$N$93:$N$100,0),MATCH(BP19,$O$92:$X$92,0))*0.82,P19) -> #N/A | BS19: 3 | BT19: 4 | BU19: =MROUND(BN19/INDEX($O$93:$X$100,MATCH(BQ19,$N$93:$N$100,0),MATCH(BP19,$O$92:$X$92,0))*0.91,P19) -> #N/A | BV19: =IF('Программа тренировок '!B127='Программа тренировок '!B119, 1, 3) -> 3 | BW19: 3 | BX19: ='Программа тренировок '!T224 | BY19: =MROUND(BU19/INDEX($O$93:$X$100,MATCH(BX19,$N$93:$N$100,0),MATCH(BW19,$O$92:$X$92,0))*0.84,P19) -> #N/A | BZ19: 3 | CA19: 4
I20: ='Программа тренировок '!E86 -> 2.5
I21: ='Программа тренировок '!E87 -> 2.5 | L21: Махи с гантелями в стороны | N21: ='Программа тренировок '!C114 | O21: ='Программа тренировок '!D114 | P21: ='Формулы'!I14 -> 1 | Q21: {=MROUND(N21/INDEX($O$93:$X$100,MATCH(10,$N$93:$N$100,0),MATCH(O21,$O$92:$X$92,0))*0.65,P21)} -> #N/A | R21: 3 | S21: 10 | T21: ='Программа тренировок '!F157 | U21: {=MROUND(Q21/INDEX($O$93:$X$100,MATCH(T21,$N$93:$N$100,0),MATCH(S21,$O$92:$X$92,0))*0.62,P21)} -> #N/A | V21: 1 | W21: до отказа | X21: {=MROUND(Q21/INDEX($O$93:$X$100,MATCH(T21,$N$93:$N$100,0),MATCH(S21,$O$92:$X$92,0))*0.67,P21)} -> #N/A | Y21: 3 | Z21: 10 | AA21: ='Программа тренировок '!M157 | AB21: {=MROUND(X21/INDEX($O$93:$X$100,MATCH(AA21,$N$93:$N$100,0),MATCH(Z21,$O$92:$X$92,0))*0.64,P21)} -> #N/A | AC21: 1 | AD21: до отказа | AE21: {=MROUND(X21/INDEX($O$93:$X$100,MATCH(AA21,$N$93:$N$100,0),MATCH(Z21,$O$92:$X$92,0))*0.69,P21)} -> #N/A | AF21: 3 | AG21: 10 | AH21: ='Программа тренировок '!T157 | AI21: {=MROUND(AE21/INDEX($O$93:$X$100,MATCH(AH21,$N$93:$N$100,0),MATCH(AG21,$O$92:$X$92,0))*0.67,P21)} -> #N/A | AJ21: 1 | AK21: до отказа | AL21: {=MROUND(AE21/INDEX($O$93:$X$100,MATCH(AH21,$N$93:$N$100,0),MATCH(AG21,$O$92:$X$92,0))*0.68,P21)} -> #N/A | AM21: 3 | AN21: 9 | AO21: ='Программа тренировок '!F184 | AP21: {=MROUND(AL21/INDEX($O$93:$X$100,MATCH(AO21,$N$93:$N$100,0),MATCH(AN21,$O$92:$X$92,0))*0.65,P21)} -> #N/A | AQ21: 1 | AR21: до отказа | AS21: {=MROUND(AL21/INDEX($O$93:$X$100,MATCH(AO21,$N$93:$N$100,0),MATCH(AN21,$O$92:$X$92,0))*0.69,P21)} -> #N/A | AT21: 3 | AU21: 9 | AV21: ='Программа тренировок '!M184 | AW21: {=MROUND(AS21/INDEX($O$93:$X$100,MATCH(AV21,$N$93:$N$100,0),MATCH(AU21,$O$92:$X$92,0))*0.66,P21)} -> #N/A | AX21: 1 | AY21: до отказа | AZ21: {=MROUND(AS21/INDEX($O$93:$X$100,MATCH(AV21,$N$93:$N$100,0),MATCH(AU21,$O$92:$X$92,0))*0.71,P21)} -> #N/A | BA21: 3 | BB21: 9 | BC21: ='Программа тренировок '!T184 | BD21: {=MROUND(AZ21/INDEX($O$93:$X$100,MATCH(BC21,$N$93:$N$100,0),MATCH(BB21,$O$92:$X$92,0))*0.68,P21)} -> #N/A | BE21: 1 | BF21: до отказа | BG21: {=MROUND(AZ21/INDEX($O$93:$X$100,MATCH(BC21,$N$93:$N$100,0),MATCH(BB21,$O$92:$X$92,0))*0.71,P21)} -> #N/A | BH21: 3 | BI21: 8 | BJ21: ='Программа тренировок '!F211 | BK21: {=MROUND(BG21/INDEX($O$93:$X$100,MATCH(BJ21,$N$93:$N$100,0),MATCH(BI21,$O$92:$X$92,0))*0.68,P21)} -> #N/A | BL21: 1 | BM21: до отказа | BN21: {=MROUND(BG21/INDEX($O$93:$X$100,MATCH(BJ21,$N$93:$N$100,0),MATCH(BI21,$O$92:$X$92,0))*0.72,P21)} -> #N/A | BO21: 3 | BP21: 8 | BQ21: ='Программа тренировок '!M211 | BR21: {=MROUND(BN21/INDEX($O$93:$X$100,MATCH(BQ21,$N$93:$N$100,0),MATCH(BP21,$O$92:$X$92,0))*0.69,P21)} -> #N/A | BS21: 1 | BT21: до отказа | BU21: {=MROUND(BN21/INDEX($O$93:$X$100,MATCH(BQ21,$N$93:$N$100,0),MATCH(BP21,$O$92:$X$92,0))*0.74,P21)} -> #N/A | BV21: 3 | BW21: 8 | BX21: ='Программа тренировок '!T211 | BY21: {=MROUND(BU21/INDEX($O$93:$X$100,MATCH(BX21,$N$93:$N$100,0),MATCH(BW21,$O$92:$X$92,0))*0.71,P21)} -> #N/A | BZ21: 1 | CA21: до отказа
I22: ='Программа тренировок '!E88 -> 3 | L22: Тяга к подбородку | N22: ='Программа тренировок '!C114 | O22: ='Программа тренировок '!D114 | P22: ='Формулы'!I14 -> 1 | Q22: {=MROUND(N22/INDEX($O$93:$X$100,MATCH(10,$N$93:$N$100,0),MATCH(O22,$O$92:$X$92,0))*0.76,P22)} -> #N/A | R22: 3 | S22: 6 | T22: ='Программа тренировок '!F157 | U22: {=MROUND(Q22/INDEX($O$93:$X$100,MATCH(T22,$N$93:$N$100,0),MATCH(S22,$O$92:$X$92,0))*0.72,P22)} -> #N/A | V22: 1 | W22: до отказа | X22: {=MROUND(Q22/INDEX($O$93:$X$100,MATCH(T22,$N$93:$N$100,0),MATCH(S22,$O$92:$X$92,0))*0.79,P22)} -> #N/A | Y22: 3 | Z22: 6 | AA22: ='Программа тренировок '!M157 | AB22: {=MROUND(X22/INDEX($O$93:$X$100,MATCH(AA22,$N$93:$N$100,0),MATCH(Z22,$O$92:$X$92,0))*0.76,P22)} -> #N/A | AC22: 1 | AD22: до отказа | AE22: {=MROUND(X22/INDEX($O$93:$X$100,MATCH(AA22,$N$93:$N$100,0),MATCH(Z22,$O$92:$X$92,0))*0.81,P22)} -> #N/A | AF22: 3 | AG22: 6 | AH22: ='Программа тренировок '!T157 | AI22: {=MROUND(AE22/INDEX($O$93:$X$100,MATCH(AH22,$N$93:$N$100,0),MATCH(AG22,$O$92:$X$92,0))*0.79,P22)} -> #N/A | AJ22: 1 | AK22: до отказа | AL22: {=MROUND(AE22/INDEX($O$93:$X$100,MATCH(AH22,$N$93:$N$100,0),MATCH(AG22,$O$92:$X$92,0))*0.79,P22)} -> #N/A | AM22: 3 | AN22: 5 | AO22: ='Программа тренировок '!F184 | AP22: {=MROUND(AL22/INDEX($O$93:$X$100,MATCH(AO22,$N$93:$N$100,0),MATCH(AN22,$O$92:$X$92,0))*0.76,P22)} -> #N/A | AQ22: 1 | AR22: до отказа | AS22: {=MROUND(AL22/INDEX($O$93:$X$100,MATCH(AO22,$N$93:$N$100,0),MATCH(AN22,$O$92:$X$92,0))*0.82,P22)} -> #N/A | AT22: 3 | AU22: 5 | AV22: ='Программа тренировок '!M184 | AW22: {=MROUND(AS22/INDEX($O$93:$X$100,MATCH(AV22,$N$93:$N$100,0),MATCH(AU22,$O$92:$X$92,0))*0.79,P22)} -> #N/A | AX22: 1 | AY22: до отказа | AZ22: {=MROUND(AS22/INDEX($O$93:$X$100,MATCH(AV22,$N$93:$N$100,0),MATCH(AU22,$O$92:$X$92,0))*0.84,P22)} -> #N/A | BA22: 3 | BB22: 5 | BC22: ='Программа тренировок '!T184 | BD22: {=MROUND(AZ22/INDEX($O$93:$X$100,MATCH(BC22,$N$93:$N$100,0),MATCH(BB22,$O$92:$X$92,0))*0.81,P22)} -> #N/A | BE22: 1 | BF22: до отказа | BG22: {=MROUND(AZ22/INDEX($O$93:$X$100,MATCH(BC22,$N$93:$N$100,0),MATCH(BB22,$O$92:$X$92,0))*0.81,P22)} -> #N/A | BH22: 3 | BI22: 4 | BJ22: ='Программа тренировок '!F211 | BK22: {=MROUND(BG22/INDEX($O$93:$X$100,MATCH(BJ22,$N$93:$N$100,0),MATCH(BI22,$O$92:$X$92,0))*0.78,P22)} -> #N/A | BL22: 1 | BM22: до отказа | BN22: {=MROUND(BG22/INDEX($O$93:$X$100,MATCH(BJ22,$N$93:$N$100,0),MATCH(BI22,$O$92:$X$92,0))*0.83,P22)} -> #N/A | BO22: 3 | BP22: 4 | BQ22: ='Программа тренировок '!M211 | BR22: {=MROUND(BN22/INDEX($O$93:$X$100,MATCH(BQ22,$N$93:$N$100,0),MATCH(BP22,$O$92:$X$92,0))*0.8,P22)} -> #N/A | BS22: 1 | BT22: до отказа | BU22: {=MROUND(BN22/INDEX($O$93:$X$100,MATCH(BQ22,$N$93:$N$100,0),MATCH(BP22,$O$92:$X$92,0))*0.85,P22)} -> #N/A | BV22: 3 | BW22: 4 | BX22: ='Программа тренировок '!T211 | BY22: {=MROUND(BU22/INDEX($O$93:$X$100,MATCH(BX22,$N$93:$N$100,0),MATCH(BW22,$O$92:$X$92,0))*0.81,P22)} -> #N/A | BZ22: 1 | CA22: до отказа
I23: 2.5
L24: Становая тяга | N24: ='Программа тренировок '!C119 | O24: ='Программа тренировок '!D119 | P24: ='Формулы'!I19 -> 2.5 | Q24: {=MROUND(N24/INDEX($O$93:$X$100,MATCH(10,$N$93:$N$100,0),MATCH(O24,$O$92:$X$92,0))*0.83,P24)} -> #N/A | R24: 2 | S24: 3 | T24: ='Программа тренировок '!F162 | U24: =MROUND(Q24/INDEX($O$93:$X$100,MATCH(T24,$N$93:$N$100,0),MATCH(S24,$O$92:$X$92,0))*0.75,P24) -> #N/A | V24: 3 | W24: 6 | X24: {=MROUND(Q24/INDEX($O$93:$X$100,MATCH(T24,$N$93:$N$100,0),MATCH(S24,$O$92:$X$92,0))*0.86,P24)} -> #N/A | Y24: 2 | Z24: 3 | AA24: ='Программа тренировок '!M162 | AB24: {=MROUND(X24/INDEX($O$93:$X$100,MATCH(AA24,$N$93:$N$100,0),MATCH(Z24,$O$92:$X$92,0))*0.8,P24)} -> #N/A | AC24: 3 | AD24: 5 | AE24: {=MROUND(X24/INDEX($O$93:$X$100,MATCH(AA24,$N$93:$N$100,0),MATCH(Z24,$O$92:$X$92,0))*0.9,P24)} -> #N/A | AF24: 2 | AG24: 3 | AH24: ='Программа тренировок '!T162 | AI24: {=MROUND(AE24/INDEX($O$93:$X$100,MATCH(AH24,$N$93:$N$100,0),MATCH(AG24,$O$92:$X$92,0))*0.85,P24)} -> #N/A | AJ24: 3 | AK24: 4 | AL24: {=MROUND(AE24/INDEX($O$93:$X$100,MATCH(AH24,$N$93:$N$100,0),MATCH(AG24,$O$92:$X$92,0))*0.86,P24)} -> #N/A | AM24: 2 | AN24: 2 | AO24: ='Программа тренировок '!F189 | AP24: =MROUND(AL24/INDEX($O$93:$X$100,MATCH(AO24,$N$93:$N$100,0),MATCH(AN24,$O$92:$X$92,0))*0.79,P24) -> #N/A | AQ24: 3 | AR24: 5 | AS24: {=MROUND(AL24/INDEX($O$93:$X$100,MATCH(AO24,$N$93:$N$100,0),MATCH(AN24,$O$92:$X$92,0))*0.89,P24)} -> #N/A | AT24: 2 | AU24: 2 | AV24: ='Программа тренировок '!M189 | AW24: {=MROUND(AS24/INDEX($O$93:$X$100,MATCH(AV24,$N$93:$N$100,0),MATCH(AU24,$O$92:$X$92,0))*0.82,P24)} -> #N/A | AX24: 3 | AY24: 4 | AZ24: {=MROUND(AS24/INDEX($O$93:$X$100,MATCH(AV24,$N$93:$N$100,0),MATCH(AU24,$O$92:$X$92,0))*0.92,P24)} -> #N/A | BA24: 2 | BB24: 2 | BC24: ='Программа тренировок '!T189 | BD24: {=MROUND(AZ24/INDEX($O$93:$X$100,MATCH(BC24,$N$93:$N$100,0),MATCH(BB24,$O$92:$X$92,0))*0.86,P24)} -> #N/A | BE24: 3 | BF24: 3 | BG24: {=MROUND(AZ24/INDEX($O$93:$X$100,MATCH(BC24,$N$93:$N$100,0),MATCH(BB24,$O$92:$X$92,0))*0.91,P24)} -> #N/A | BH24: 2 | BI24: 1 | BJ24: ='Программа тренировок '!F216 | BK24: =MROUND(BG24/INDEX($O$93:$X$100,MATCH(BJ24,$N$93:$N$100,0),MATCH(BI24,$O$92:$X$92,0))*0.81,P24) -> #N/A | BL24: 3 | BM24: 4 | BN24: {=MROUND(BG24/INDEX($O$93:$X$100,MATCH(BJ24,$N$93:$N$100,0),MATCH(BI24,$O$92:$X$92,0))*0.94,P24)} -> #N/A | BO24: 2 | BP24: 1 | BQ24: ='Программа тренировок '!M216 | BR24: {=MROUND(BN24/INDEX($O$93:$X$100,MATCH(BQ24,$N$93:$N$100,0),MATCH(BP24,$O$92:$X$92,0))*0.84,P24)} -> #N/A | BS24: 3 | BT24: 3 | BU24: {=MROUND(BN24/INDEX($O$93:$X$100,MATCH(BQ24,$N$93:$N$100,0),MATCH(BP24,$O$92:$X$92,0))*0.97,P24)} -> #N/A | BV24: 1 | BW24: 1 | BX24: ='Программа тренировок '!T216 | BY24: {=MROUND(BU24/INDEX($O$93:$X$100,MATCH(BX24,$N$93:$N$100,0),MATCH(BW24,$O$92:$X$92,0))*0.89,P24)} -> #N/A | BZ24: 3 | CA24: 2
L25: Мёртвая тяга | N25: ='Программа тренировок '!C119 | O25: ='Программа тренировок '!D119 | P25: ='Формулы'!I19 -> 2.5 | Q25: =MROUND(N25/INDEX($O$93:$X$100,MATCH(10,$N$93:$N$100,0),MATCH(O25,$O$92:$X$92,0))*0.8,P25) -> #N/A | R25: 1 | S25: 5 | T25: ='Программа тренировок '!F162 | U25: =MROUND(Q25/INDEX($O$93:$X$100,MATCH(T25,$N$93:$N$100,0),MATCH(S25,$O$92:$X$92,0))*0.75,P25) -> #N/A | V25: 3 | W25: 6 | X25: {=MROUND(Q25/INDEX($O$93:$X$100,MATCH(T25,$N$93:$N$100,0),MATCH(S25,$O$92:$X$92,0))*0.82,P25)} -> #N/A | Y25: 1 | Z25: 5 | AA25: ='Программа тренировок '!M162 | AB25: {=MROUND(X25/INDEX($O$93:$X$100,MATCH(AA25,$N$93:$N$100,0),MATCH(Z25,$O$92:$X$92,0))*0.77,P25)} -> #N/A | AC25: 3 | AD25: 6 | AE25: {=MROUND(X25/INDEX($O$93:$X$100,MATCH(AA25,$N$93:$N$100,0),MATCH(Z25,$O$92:$X$92,0))*0.85,P25)} -> #N/A | AF25: 1 | AG25: 5 | AH25: ='Программа тренировок '!T162 | AI25: {=MROUND(AE25/INDEX($O$93:$X$100,MATCH(AH25,$N$93:$N$100,0),MATCH(AG25,$O$92:$X$92,0))*0.79,P25)} -> #N/A | AJ25: 3 | AK25: 6 | AL25: =MROUND(AE25/INDEX($O$93:$X$100,MATCH(AH25,$N$93:$N$100,0),MATCH(AG25,$O$92:$X$92,0))*0.82,P25) -> #N/A | AM25: 1 | AN25: 4 | AO25: ='Программа тренировок '!F189 | AP25: =MROUND(AL25/INDEX($O$93:$X$100,MATCH(AO25,$N$93:$N$100,0),MATCH(AN25,$O$92:$X$92,0))*0.79,P25) -> #N/A | AQ25: 3 | AR25: 5 | AS25: {=MROUND(AL25/INDEX($O$93:$X$100,MATCH(AO25,$N$93:$N$100,0),MATCH(AN25,$O$92:$X$92,0))*0.85,P25)} -> #N/A | AT25: 1 | AU25: 4 | AV25: ='Программа тренировок '!M189 | AW25: {=MROUND(AS25/INDEX($O$93:$X$100,MATCH(AV25,$N$93:$N$100,0),MATCH(AU25,$O$92:$X$92,0))*0.8,P25)} -> #N/A | AX25: 3 | AY25: 5 | AZ25: {=MROUND(AS25/INDEX($O$93:$X$100,MATCH(AV25,$N$93:$N$100,0),MATCH(AU25,$O$92:$X$92,0))*0.88,P25)} -> #N/A | BA25: 1 | BB25: 4 | BC25: ='Программа тренировок '!T189 | BD25: {=MROUND(AZ25/INDEX($O$93:$X$100,MATCH(BC25,$N$93:$N$100,0),MATCH(BB25,$O$92:$X$92,0))*0.81,P25)} -> #N/A | BE25: 3 | BF25: 5 | BG25: {=MROUND(AZ25/INDEX($O$93:$X$100,MATCH(BC25,$N$93:$N$100,0),MATCH(BB25,$O$92:$X$92,0))*0.83,P25)} -> #N/A | BH25: 1 | BI25: 3 | BJ25: ='Программа тренировок '!F216 | BK25: =MROUND(BG25/INDEX($O$93:$X$100,MATCH(BJ25,$N$93:$N$100,0),MATCH(BI25,$O$92:$X$92,0))*0.81,P25) -> #N/A | BL25: 3 | BM25: 4 | BN25: {=MROUND(BG25/INDEX($O$93:$X$100,MATCH(BJ25,$N$93:$N$100,0),MATCH(BI25,$O$92:$X$92,0))*0.86,P25)} -> #N/A | BO25: 1 | BP25: 3 | BQ25: ='Программа тренировок '!M216 | BR25: {=MROUND(BN25/INDEX($O$93:$X$100,MATCH(BQ25,$N$93:$N$100,0),MATCH(BP25,$O$92:$X$92,0))*0.82,P25)} -> #N/A | BS25: 3 | BT25: 4 | BU25: {=MROUND(BN25/INDEX($O$93:$X$100,MATCH(BQ25,$N$93:$N$100,0),MATCH(BP25,$O$92:$X$92,0))*0.91,P25)} -> #N/A | BV25: 1 | BW25: 3 | BX25: ='Программа тренировок '!T216 | BY25: {=MROUND(BU25/INDEX($O$93:$X$100,MATCH(BX25,$N$93:$N$100,0),MATCH(BW25,$O$92:$X$92,0))*0.84,P25)} -> #N/A | BZ25: 3 | CA25: 4
